Workbook

Sheet Cover
B2: PT Metro Healthcare Indonesia Tbk (CARE) - Model data fundamental 6 tahun & proyeksi ilustratif
B3: Historis FY2020-FY2025 (laporan keuangan konsolidasian audited) | proyeksi ilustratif FY2026-FY2030 | Format: PRO
B5: Penting - sifat dokumen
B6: Bukan rekomendasi | C6: Dokumen ini hanya ringkasan informasi dan analisis data fundamental yang bersumber dari laporan keuangan publik (audited) PT Metro Healthcare Indonesia Tbk. Dokumen ini BUKAN saran atau rekomendasi investasi, bukan ajakan membeli, menjual, atau menahan efek apa pun, dan tidak memuat target atau penilaian nilai wajar. Proyeksi bersifat ilustratif dan dapat berbeda jauh dari realisasi. Data dapat mengandung kesalahan ekstraksi; selalu cek ke laporan asli. Dokumen ini disusun dengan bantuan kecerdasan buatan (AI) dari laporan keuangan publik; kemungkinan kesalahan tetap ada, harap verifikasi ke sumber.
B7: Proyeksi | C7: Angka FY..E adalah proyeksi ILUSTRATIF berbasis asumsi transparan di sheet Asumsi (Base/Bull/Bear), dikalibrasi dari tren FY2022-2025. Tidak ada target, nilai wajar, atau kesimpulan nilai per saham.
B8: Sumber data | C8: Laporan keuangan konsolidasian audited PT Metro Healthcare Indonesia Tbk FY2021-FY2025. Kolom 2021 dari komparatif LK FY2022 (disilangkan ke LK FY2021); kolom 2020 dari komparatif LK FY2021 (ringkasan XBRL IDX tidak dapat diunduh, HTTP 403), tanpa CALK. Lihat Data_Log & Temuan.
B10: Hak cipta & lisensi
B11: Hak cipta | C11: © 2026 Ryant Gabein Pasaribu. Kompilasi, struktur, metodologi, kode akun standar, dan analisis dalam file ini adalah ciptaan Ryant Gabein Pasaribu. Dilisensikan di bawah Creative Commons Atribusi 4.0 Internasional (CC BY 4.0): bebas digunakan dan dibagikan dengan wajib mencantumkan atribusi "Ryant Gabein Pasaribu" dan menyertakan tautan lisensi https://creativecommons.org/licenses/by/4.0/deed.id. Data laporan keuangan bersumber dari laporan publik emiten.
B12: Versi | C12: v1.0
B13: Tanggal terbit | C13: 2026-10-25
B14: ID file | C14: CARE-FY2025-v1.0-21844D70
B16: Format
B17: Data terbuka | C17: Data dan model ini terbuka dan gratis untuk semua orang.
B18: Format output | C18: Tiga format (bukan tingkatan akses, semuanya gratis): Ritel (PDF ringkasan 4 halaman), Akademik (Excel data historis, rasio, rekonsiliasi), Pro (Excel model penuh dengan proyeksi ilustratif & template DCF kosong).
B20: Informasi model
B21: Emiten | C21: PT Metro Healthcare Indonesia Tbk dan Entitas Anaknya (kode CARE) - rumah sakit swasta
B22: Satuan | C22: Rupiah penuh (Ringkasan/Dashboard: Rp miliar); beban & arus kas keluar negatif (kurung)
B23: Tahun historis | C23: FY2020, FY2021, FY2022, FY2023, FY2024, FY2025
B24: Status rekonsiliasi | C24: =Rekonsiliasi!$C$3 -> SEMUA 354 CEK SESUAI EKSPEKTASI
B25: Skenario aktif | C25: =Asumsi!C4 -> Base
B26: Dibangun | C26: 25-10-2026 oleh /workspace/emiten/common/build_model.py --ticker CARE
B28: Daftar sheet
B29: Cover | C29: Sifat dokumen, lisensi, keterangan warna
B30: Panduan | C30: Cara memakai model ini
B31: Ringkasan | C31: Ringkasan siap cetak/PDF (A4): highlights, indikator utama, grafik, tanda perhatian
B32: Dashboard | C32: Indikator & grafik historis + proyeksi ilustratif
B33: Asumsi | C33: Selektor skenario Base/Bull/Bear & driver per tahun, dengan dasar kalibrasi FY2022-2025
B34: IS_Proj | C34: Proyeksi laba rugi (pendapatan per layanan, EBITDA, laba)
B35: BS_Proj | C35: Proyeksi neraca agregat; kas = penyeimbang; cek balance
B36: CF_Proj | C36: Proyeksi arus kas tidak langsung; FCF
B37: Schedules_Proj | C37: Aset tetap, aset takberwujud, sewa, utang, modal kerja
B38: DCF_Template | C38: Kalkulator DCF opsional dengan input KOSONG (tanpa kesimpulan)
B39: Peer | C39: Tabel pembanding fundamental (input kosong, tanpa kelipatan pasar)
B40: IS | C40: Laba rugi & OCI FY2020-2025
... B48: Data_Log | C48: Sumber per tahun, pemetaan akun, override

Sheet Panduan
A1: Panduan pemakaian
A2: Format PRO (model penuh) - gratis & terbuka; bukan rekomendasi investasi
B4: Langkah
B5: 1. Mulai | C5: Baca Cover (sifat dokumen) lalu Ringkasan (siap cetak A4: File > Print/Export PDF untuk sheet Ringkasan).
B6: 2. Data historis | C6: IS, BS, CF berisi angka laporan (biru) dan subtotal rumus (hitam). Baris 3 menyebut sumber tiap kolom; kolom FY2020 berlatar oranye = kolom pertama, dari komparatif LK FY2021 (Temuan C2); FY2021 dari komparatif LK FY2022 (C1).
B7: 3. Rincian & rasio | C7: Schedules memuat rincian catatan (CALK) FY2021-2025; bagian A merangkum angka yang dipakai Rasio. Rasio memakai rumus hidup dan kolom rata-rata FY2022-25.
B8: 4. Cek kualitas | C8: Rekonsiliasi: kolom "Sesuai ekspektasi?" harus ✔ untuk semua baris. ❌ yang diharapkan adalah selisih di laporan sumber dan dijelaskan di kolom Penjelasan / sheet Temuan.
B9: 5. Proyeksi ilustratif | C9: Pilih skenario di Asumsi!C4 (Base/Bull/Bear). Ubah sel biru di blok skenario untuk mencoba asumsi sendiri; IS_Proj, BS_Proj, CF_Proj ikut berubah. Cek BS_Proj baris "Cek" harus 0.
B10: 6. Template DCF (opsional) | C10: Isi sendiri sel kuning (Rf, ERP, beta, Kd, pajak, bobot utang, g / kelipatan). Tanpa input, template tidak menghitung apa pun. Hasil adalah keluaran rumus atas input Anda, bukan nilai wajar atau rekomendasi.
B11: 7. Peer | C11: Isi data fundamental pembanding dari laporan publik masing-masing emiten beserta sumbernya. Tidak ada angka pembanding yang dikarang di file ini.
B13: Keterangan warna
B14: Biru | C14: Input / angka dari laporan (bisa diubah)
B15: Hitam | C15: Rumus di sheet yang sama
B16: Hijau | C16: Rumus yang merujuk sheet lain
B17: Kuning | C17: Sel yang perlu diisi/diverifikasi pengguna atau angka yang dikoreksi (ada komentar sel)
B18: Oranye | C18: Kolom FY2020 (kolom pertama) dari komparatif LK FY2021
B19: Biru muda | C19: Kolom tahun proyeksi (E) - ilustratif
B21: Definisi penting
B22: EBITDA | C22: Laba (rugi) usaha (laba bruto + beban usaha; pendapatan/beban lain disajikan di bawahnya) + penyusutan aset tetap (Cat 21).
B23: Utang | C23: Utang berbunga: pinjaman bank jangka pendek & panjang, pinjaman lembaga keuangan, wesel bayar/sukuk. Utang neto = utang - kas. CARE tidak memiliki liabilitas sewa.
B24: EPS | C24: EPS tercetak memakai saham rata-rata tertimbang (CALK); Rasio juga menyajikan laba induk / saham tercatat (Temuan C3).
B25: Satuan | C25: Rupiah penuh kecuali disebut (Ringkasan/Dashboard: Rp miliar). Beban & arus kas keluar bertanda negatif.
B27: Daftar sheet (format ini)
B28: Cover | C28: Sifat dokumen, lisensi, keterangan warna
B29: Panduan | C29: Cara memakai model ini
B30: Ringkasan | C30: Ringkasan siap cetak/PDF (A4): highlights, indikator utama, grafik, tanda perhatian
B31: Dashboard | C31: Indikator & grafik historis + proyeksi ilustratif
B32: Asumsi | C32: Selektor skenario Base/Bull/Bear & driver per tahun, dengan dasar kalibrasi FY2022-2025
B33: IS_Proj | C33: Proyeksi laba rugi (pendapatan per layanan, EBITDA, laba)
B34: BS_Proj | C34: Proyeksi neraca agregat; kas = penyeimbang; cek balance
B35: CF_Proj | C35: Proyeksi arus kas tidak langsung; FCF
B36: Schedules_Proj | C36: Aset tetap, aset takberwujud, sewa, utang, modal kerja
B37: DCF_Template | C37: Kalkulator DCF opsional dengan input KOSONG (tanpa kesimpulan)
B38: Peer | C38: Tabel pembanding fundamental (input kosong, tanpa kelipatan pasar)
B39: IS | C39: Laba rugi & OCI FY2020-2025
... B47: Data_Log | C47: Sumber per tahun, pemetaan akun, override
B49: Batasan
B50: Data | C50: Angka diekstrak dari PDF dan dapat mengandung kesalahan; cek ke laporan asli sebelum dipakai.
B51: Proyeksi | C51: Asumsi sederhana: pos neraca lain konstan (termasuk investasi jk pendek), utang konstan, beban keuangan = suku bunga x utang, tanpa OCI baru, tanpa pendanaan baru. Hasil sangat sensitif terhadap asumsi.
B52: Bukan saran | C52: Dokumen ini hanya ringkasan informasi dan analisis data fundamental yang bersumber dari laporan keuangan publik (audited) PT Metro Healthcare Indonesia Tbk. Dokumen ini BUKAN saran atau rekomendasi investasi, bukan ajakan membeli, menjual, atau menahan efek apa pun, dan tidak memuat target atau penilaian nilai wajar. Proyeksi bersifat ilustratif dan dapat berbeda jauh dari realisasi. Data dapat mengandung kesalahan ekstraksi; selalu cek ke laporan asli. Dokumen ini disusun dengan bantuan kecerdasan buatan (AI) dari laporan keuangan publik; kemungkinan kesalahan tetap ada, harap verifikasi ke sumber.

Sheet Ringkasan
B1: Metro Healthcare Indonesia (CARE) | Ringkasan FY2020-FY2025
B2: Rumah sakit swasta (Cinere, Ciputat, Cibitung & lainnya) | sumber: laporan keuangan konsolidasian audited | gratis & terbuka | BUKAN rekomendasi investasi
B4: Penting: Dokumen ini hanya ringkasan informasi dan analisis data fundamental yang bersumber dari laporan keuangan publik (audited) PT Metro Healthcare Indonesia Tbk. Dokumen ini BUKAN saran atau rekomendasi investasi, bukan ajakan membeli, menjual, atau menahan efek apa pun, dan tidak memuat target atau penilaian nilai wajar. Proyeksi bersifat ilustratif dan dapat berbeda jauh dari realisasi. Data dapat mengandung kesalahan ekstraksi; selalu cek ke laporan asli. Dokumen ini disusun dengan bantuan kecerdasan buatan (AI) dari laporan keuangan publik; kemungkinan kesalahan tetap ada, harap verifikasi ke sumber.
B6: Ringkasan Eksekutif / Highlights
B7: • Pendapatan neto FY2025 Rp440 miliar (+37,8% vs FY2024), termasuk pendapatan investasi Rp97,8 miliar; pendapatan rumah sakit (rawat inap + rawat jalan) Rp342 miliar.
B8: • Rawat inap tumbuh 16,2% per tahun dan rawat jalan 25,1% per tahun FY2023-2025; porsi rawat jalan 30,2% pendapatan RS FY2025.
B9: • Laba pemilik induk FY2025 Rp5,0 miliar (EPS Rp0,15) setelah rugi tiga tahun (FY2022-2024 total Rp-285 miliar).
B10: • Utang berbunga Rp1.084 miliar vs kas Rp420 miliar (FY2025); beban keuangan Rp80 miliar melebihi EBITDA rumah sakit. Tidak ada dividen FY2020-FY2025.
B11: • Data 6 tahun direkonsiliasi dengan 354 cek; 3 selisih di laporan sumber sudah diperkirakan dan dijelaskan (lihat tanda perhatian & sheet Temuan).
B13: Indikator utama (Rp miliar, kecuali disebut lain) - rumus hidup dari sheet IS/BS/CF/Rasio
B14: Indikator | C14: FY2020A | D14: FY2021A | E14: FY2022A | F14: FY2023A | G14: FY2024A | H14: FY2025A
B15: Pendapatan neto | C15: =IS!C6/1000000000 -> 216.2961 | D15: =IS!D6/1000000000 -> 290.93436 | E15: =IS!E6/1000000000 -> 233.97072 | F15: =IS!F6/1000000000 -> 242.6808 | G15: =IS!G6/1000000000 -> 319.02241 | H15: =IS!H6/1000000000 -> 439.75161
B16: Pertumbuhan | D16: =Rasio!D6 -> 0.34507447 | E16: =Rasio!E6 -> -0.19579548 | F16: =Rasio!F6 -> 0.037227198 | G16: =Rasio!G6 -> 0.31457623 | H16: =Rasio!H6 -> 0.37843484
B17: Porsi rawat jalan | C17: n/a | D17: =Rasio!D25 -> 0.30082755 | E17: =Rasio!E25 -> 0.33346319 | F17: =Rasio!F25 -> 0.27231421 | G17: =Rasio!G25 -> 0.27701089 | H17: =Rasio!H25 -> 0.30223216
B18: EBITDA | C18: n/a | D18: =Rasio!D15/1000000000 -> 31.395271 | E18: =Rasio!E15/1000000000 -> -37.713752 | F18: =Rasio!F15/1000000000 -> -14.553809 | G18: =Rasio!G15/1000000000 -> -4.4118705 | H18: =Rasio!H15/1000000000 -> 96.341924
B19: Margin EBITDA | C19: n/a | D19: =Rasio!D16 -> 0.10791187 | E19: =Rasio!E16 -> -0.16119005 | F19: =Rasio!F16 -> -0.059970996 | G19: =Rasio!G16 -> -0.013829344 | H19: =Rasio!H16 -> 0.2190826
B20: Laba tahun berjalan | C20: =IS!C17/1000000000 -> 14.167951 | D20: =IS!D17/1000000000 -> 6.1736248 | E20: =IS!E17/1000000000 -> -93.604422 | F20: =IS!F17/1000000000 -> -110.68886 | G20: =IS!G17/1000000000 -> -79.91722 | H20: =IS!H17/1000000000 -> 5.1455661
B21: Laba pemilik entitas induk | C21: =IS!C24/1000000000 -> 14.312843 | D21: =IS!D24/1000000000 -> 6.0991939 | E21: =IS!E24/1000000000 -> -93.543897 | F21: =IS!F24/1000000000 -> -110.91979 | G21: =IS!G24/1000000000 -> -80.309181 | H21: =IS!H24/1000000000 -> 4.9527183
B22: Porsi laba ke NCI | C22: =Rasio!C22 -> -0.010226703 | D22: =Rasio!D22 -> 0.012056273 | E22: =Rasio!E22 -> 0.00064660741 | F22: =Rasio!F22 -> -0.0020862705 | G22: =Rasio!G22 -> -0.0049045902 | H22: =Rasio!H22 -> 0.037478444
B23: ROE (rata-rata ekuitas induk) | D23: =Rasio!D19 -> 0.0018518641 | E23: =Rasio!E19 -> -0.028768755 | F23: =Rasio!F19 -> -0.03519918 | G23: =Rasio!G19 -> -0.026273737 | H23: =Rasio!H19 -> 0.001640296
B24: Arus kas operasi | C24: =CF!C14/1000000000 -> 50.302794 | D24: =CF!D14/1000000000 -> 47.12909 | E24: =CF!E14/1000000000 -> -48.836369 | F24: =CF!F14/1000000000 -> -83.033264 | G24: =CF!G14/1000000000 -> -113.01118 | H24: =CF!H14/1000000000 -> 45.886905
B25: Capex | C25: =Rasio!C39/1000000000 -> 522.26812 | D25: =Rasio!D39/1000000000 -> 310.40494 | E25: =Rasio!E39/1000000000 -> 290.45364 | F25: =Rasio!F39/1000000000 -> 12.562011 | G25: =Rasio!G39/1000000000 -> 226.92998 | H25: =Rasio!H39/1000000000 -> 210.75646
B26: Utang neto (utang berbunga - kas) | C26: =Rasio!C34/1000000000 -> -409.31695 | D26: =Rasio!D34/1000000000 -> 301.66334 | E26: =Rasio!E34/1000000000 -> 423.82926 | F26: =Rasio!F34/1000000000 -> 428.75124 | G26: =Rasio!G34/1000000000 -> 495.39694 | H26: =Rasio!H34/1000000000 -> 663.43093
B27: Utang neto / EBITDA (x) | C27: n/a | D27: =Rasio!D36 -> 9.6085597 | E27: =Rasio!E36 -> -11.238056 | F27: =Rasio!F36 -> -29.459727 | G27: =Rasio!G36 -> -112.28728 | H27: =Rasio!H36 -> 6.8862123
B28: DSO piutang (hari) | C28: =Rasio!C27 -> 78.157702 | D28: =Rasio!D27 -> 54.471996 | E28: =Rasio!E27 -> 30.410991 | F28: =Rasio!F27 -> 44.764498 | G28: =Rasio!G27 -> 44.949167 | H28: =Rasio!H27 -> 26.904669
B29: Tarif pajak efektif | C29: =Rasio!C21 -> -0.027198489 | D29: =Rasio!D21 -> 0.051166078 | E29: =Rasio!E21 -> -0.0030912546 | F29: =Rasio!F21 -> -0.043025819 | G29: =Rasio!G21 -> -0.054817048 | H29: =Rasio!H21 -> 0.36248885
B30: Catatan: kolom FY2021 dari komparatif LK FY2022, FY2020 dari komparatif LK FY2021 (EBITDA 2020 tidak dihitung: CALK 2020 tidak dimuat). EBITDA = laba (rugi) usaha + penyusutan aset tetap. Utang = bank + lembaga keuangan + wesel/sukuk.
B32: Tren 6 tahun
B50: Batang = pendapatan RS per layanan (Cat 20, tanpa pendapatan investasi 2025 & diskon); garis putus-putus = porsi rawat jalan (sumbu kanan).
B68: Kiri: margin terhadap pendapatan neto. Kanan: arus kas operasi (abu-abu), capex (arsir), dan sisanya (garis).
B86: Tanda perhatian dari laporan keuangan (bahasa sederhana)
B87: 1. Beban bunga besar - Utang bank, pinjaman lembaga keuangan dan sukuk sekitar Rp1 triliun; bunganya lebih besar dari EBITDA rumah sakit, sehingga laba sangat bergantung pada pendapatan nonoperasi. (Temuan C6)
B88: 2. Pendapatan 2025 termasuk pendapatan investasi - Laba 2025 kembali positif terutama karena pendapatan investasi dicatat di dalam pendapatan; pos ini tidak diasumsikan berulang. (Temuan C5)
B89: 3. Penyajian ulang 2022 - LK 2023 mengubah pendapatan & beban pokok 2022 menjadi bruto (diskon dipindah ke beban pokok); model memakai angka asli, sehingga 2021-2022 vs 2023+ tidak sebanding penuh. (Temuan C4)
B90: 4. Sumber 2020-2021 - Angka 2021 dari kolom pembanding LK 2022 (dicocokkan ke LK 2021); angka 2020 dari kolom pembanding LK 2021 karena ringkasan XBRL BEI tidak dapat diunduh. (Temuan C1, C2)
B91: 5. Kas proyeksi - Pada skenario Base kas dapat menipis/negatif karena rugi dan capex; artinya butuh pendanaan tambahan, yang tidak dimodelkan. (Temuan C7)
B92: Detail lengkap ada di sheet Temuan dan Rekonsiliasi. Tanda perhatian bukan tuduhan kecurangan; ini daftar hal yang perlu dicek ulang ke laporan asli.
B94: Lisensi & format
... B102: Dokumen ini hanya ringkasan informasi dan analisis data fundamental yang bersumber dari laporan keuangan publik (audited) PT Metro Healthcare Indonesia Tbk. Dokumen ini BUKAN saran atau rekomendasi investasi, bukan ajakan membeli, menjual, atau menahan efek apa pun, dan tidak memuat target atau penilaian nilai wajar. Proyeksi bersifat ilustratif dan dapat berbeda jauh dari realisasi. Data dapat mengandung kesalahan ekstraksi; selalu cek ke laporan asli. Dokumen ini disusun dengan bantuan kecerdasan buatan (AI) dari laporan keuangan publik; kemungkinan kesalahan tetap ada, harap verifikasi ke sumber. Penyusun tidak bertanggung jawab atas keputusan apa pun yang diambil berdasarkan dokumen ini. Dokumen ini disusun pada 25-10-2026.

Sheet Dashboard
A1: Dashboard - historis FY2020-FY2025 & proyeksi ilustratif FY2026-FY2030 (skenario aktif)
A2: Rp miliar. Kolom E = Proyeksi ILUSTRATIF berbasis asumsi transparan - bukan rekomendasi investasi, bukan target, bukan nilai wajar. Tidak ada nilai per saham/target di sheet ini.
B3: Skenario aktif: | C3: =Asumsi!C4 -> Base
B4: Indikator | C4: FY2020A | D4: FY2021A | E4: FY2022A | F4: FY2023A | G4: FY2024A | H4: FY2025A | I4: FY2026E | J4: FY2027E | K4: FY2028E | L4: FY2029E | M4: FY2030E | N4: Catatan
B5: Pendapatan neto | C5: =IS_Proj!C9/1000000000 -> 216.2961 | D5: =IS_Proj!D9/1000000000 -> 290.93436 | E5: =IS_Proj!E9/1000000000 -> 233.97072 | F5: =IS_Proj!F9/1000000000 -> 242.6808 | G5: =IS_Proj!G9/1000000000 -> 319.02241 | H5: =IS_Proj!H9/1000000000 -> 439.75161 | I5: =IS_Proj!I9/1000000000 -> 386.08626 | J5: =IS_Proj!J9/1000000000 -> 435.98215 | ... M5: =IS_Proj!M9/1000000000 -> 628.37101
B6: Pertumbuhan pendapatan | D6: =IS_Proj!D10 -> 0.34507447 | E6: =IS_Proj!E10 -> -0.19579548 | F6: =IS_Proj!F10 -> 0.037227198 | G6: =IS_Proj!G10 -> 0.31457623 | H6: =IS_Proj!H10 -> 0.37843484 | I6: =IS_Proj!I10 -> -0.12203558 | J6: =IS_Proj!J10 -> 0.12923507 | K6: =IS_Proj!K10 -> 0.12940489 | ... M6: =IS_Proj!M10 -> 0.12974954
B7: EBITDA | D7: =IS_Proj!D15/1000000000 -> 31.395271 | E7: =IS_Proj!E15/1000000000 -> -37.713752 | F7: =IS_Proj!F15/1000000000 -> -14.553809 | G7: =IS_Proj!G15/1000000000 -> -4.4118705 | H7: =IS_Proj!H15/1000000000 -> 96.341924 | I7: =IS_Proj!I15/1000000000 -> 19.304313 | J7: =IS_Proj!J15/1000000000 -> 21.799107 | K7: =IS_Proj!K15/1000000000 -> 24.620018 | ... M7: =IS_Proj!M15/1000000000 -> 31.418551
B8: Margin EBITDA | D8: =IS_Proj!D29 -> 0.10791187 | E8: =IS_Proj!E29 -> -0.16119005 | F8: =IS_Proj!F29 -> -0.059970996 | G8: =IS_Proj!G29 -> -0.013829344 | H8: =IS_Proj!H29 -> 0.2190826 | I8: =IS_Proj!I29 -> 0.05 | J8: =IS_Proj!J29 -> 0.05 | K8: =IS_Proj!K29 -> 0.05 | ... M8: =IS_Proj!M29 -> 0.05
B9: Laba tahun berjalan | C9: =IS_Proj!C23/1000000000 -> 14.167951 | D9: =IS_Proj!D23/1000000000 -> 6.1736248 | E9: =IS_Proj!E23/1000000000 -> -93.604422 | F9: =IS_Proj!F23/1000000000 -> -110.68886 | G9: =IS_Proj!G23/1000000000 -> -79.91722 | H9: =IS_Proj!H23/1000000000 -> 5.1455661 | I9: =IS_Proj!I23/1000000000 -> -81.870694 | J9: =IS_Proj!J23/1000000000 -> -81.013145 | ... M9: =IS_Proj!M23/1000000000 -> -76.542648
B10: Laba pemilik entitas induk | C10: =IS_Proj!C25/1000000000 -> 14.312843 | D10: =IS_Proj!D25/1000000000 -> 6.0991939 | E10: =IS_Proj!E25/1000000000 -> -93.543897 | F10: =IS_Proj!F25/1000000000 -> -110.91979 | G10: =IS_Proj!G25/1000000000 -> -80.309181 | H10: =IS_Proj!H25/1000000000 -> 4.9527183 | I10: =IS_Proj!I25/1000000000 -> -78.841479 | J10: =IS_Proj!J25/1000000000 -> -78.015659 | ... M10: =IS_Proj!M25/1000000000 -> -73.71057
B11: Arus kas operasi | C11: =CF_Proj!C11/1000000000 -> 50.302794 | D11: =CF_Proj!D11/1000000000 -> 47.12909 | E11: =CF_Proj!E11/1000000000 -> -48.836369 | F11: =CF_Proj!F11/1000000000 -> -83.033264 | G11: =CF_Proj!G11/1000000000 -> -113.01118 | H11: =CF_Proj!H11/1000000000 -> 45.886905 | I11: =CF_Proj!I11/1000000000 -> -62.856401 | J11: =CF_Proj!J11/1000000000 -> -59.565383 | ... M11: =CF_Proj!M11/1000000000 -> -56.01489
B12: Capex | C12: =CF_Proj!C13/1000000000 -> -522.26812 | D12: =CF_Proj!D13/1000000000 -> -310.40494 | E12: =CF_Proj!E13/1000000000 -> -290.45364 | F12: =CF_Proj!F13/1000000000 -> -12.562011 | G12: =CF_Proj!G13/1000000000 -> -226.92998 | H12: =CF_Proj!H13/1000000000 -> -210.75646 | I12: =CF_Proj!I13/1000000000 -> -30.886901 | J12: =CF_Proj!J13/1000000000 -> -34.878572 | ... M12: =CF_Proj!M13/1000000000 -> -50.269681
B13: FCF setelah sewa | C13: =CF_Proj!C27/1000000000 -> -471.96533 | D13: =CF_Proj!D27/1000000000 -> -263.27585 | E13: =CF_Proj!E27/1000000000 -> -339.29001 | F13: =CF_Proj!F27/1000000000 -> -95.595275 | G13: =CF_Proj!G27/1000000000 -> -339.94117 | H13: =CF_Proj!H27/1000000000 -> -164.86956 | I13: =CF_Proj!I27/1000000000 -> -93.743302 | J13: =CF_Proj!J27/1000000000 -> -94.443954 | ... M13: =CF_Proj!M27/1000000000 -> -106.28457
B14: Kas akhir | C14: =BS_Proj!C6/1000000000 -> 525.47969 | D14: =BS_Proj!D6/1000000000 -> 542.40048 | E14: =BS_Proj!E6/1000000000 -> 533.20803 | F14: =BS_Proj!F6/1000000000 -> 525.76295 | G14: =BS_Proj!G6/1000000000 -> 449.06966 | H14: =BS_Proj!H6/1000000000 -> 420.20409 | I14: =BS_Proj!I6/1000000000 -> 326.46079 | J14: =BS_Proj!J6/1000000000 -> 232.01684 | ... M14: =BS_Proj!M6/1000000000 -> -74.350241
B15: Utang neto (utang + sewa - kas) | C15: =BS_Proj!C31/1000000000 -> -409.31695 | D15: =BS_Proj!D31/1000000000 -> 301.66334 | E15: =BS_Proj!E31/1000000000 -> 423.82926 | F15: =BS_Proj!F31/1000000000 -> 428.75124 | G15: =BS_Proj!G31/1000000000 -> 495.39694 | H15: =BS_Proj!H31/1000000000 -> 663.43093 | I15: =BS_Proj!I31/1000000000 -> 757.17424 | J15: =BS_Proj!J31/1000000000 -> 851.61819 | ... M15: =BS_Proj!M31/1000000000 -> 1157.9853
B16: Utang neto / EBITDA | D16: =BS_Proj!D33 -> 9.6085597 | E16: =BS_Proj!E33 -> -11.238056 | F16: =BS_Proj!F33 -> -29.459727 | G16: =BS_Proj!G33 -> -112.28728 | H16: =BS_Proj!H33 -> 6.8862123 | I16: =BS_Proj!I33 -> 39.22306 | J16: =BS_Proj!J33 -> 39.066654 | K16: =BS_Proj!K33 -> 38.573983 | ... M16: =BS_Proj!M33 -> 36.856737
B17: ROE | D17: =BS_Proj!D32 -> 0.0018518641 | E17: =BS_Proj!E32 -> -0.028768755 | F17: =BS_Proj!F32 -> -0.03519918 | G17: =BS_Proj!G32 -> -0.026273737 | H17: =BS_Proj!H32 -> 0.001640296 | I17: =BS_Proj!I32 -> -0.026433611 | J17: =BS_Proj!J32 -> -0.026863104 | K17: =BS_Proj!K32 -> -0.027199395 | ... M17: =BS_Proj!M32 -> -0.027545259
B18: Cek balance BS_Proj (harus 0) | C18: =BS_Proj!C30 -> 0 | D18: =BS_Proj!D30 -> 0 | E18: =BS_Proj!E30 -> 0 | F18: =BS_Proj!F30 -> 0 | G18: =BS_Proj!G30 -> 0 | H18: =BS_Proj!H30 -> 0 | I18: =BS_Proj!I30 -> 0 | J18: =BS_Proj!J30 -> 0 | ... M18: =BS_Proj!M30 -> 0
B19: Status rekonsiliasi | C19: =Rekonsiliasi!$C$3 -> SEMUA 354 CEK SESUAI EKSPEKTASI

Sheet Asumsi
A1: Asumsi proyeksi ilustratif FY2026E-FY2030E (Base / Bull / Bear)
A2: Proyeksi ILUSTRATIF berbasis asumsi transparan - bukan rekomendasi investasi, bukan target, bukan nilai wajar.
A4: Skenario aktif | C4: Base | D4: =IF(C4="Bull",2,IF(C4="Bear",3,1)) -> 1 | E4: <- pilih Base / Bull / Bear. Kolom historis = aktual (rumus dari IS/BS/CF/Schedules); kolom E = asumsi skenario aktif.
A5: Kalibrasi | C5: Asumsi dikalibrasi dari FY2023-FY2025 (RS mulai beroperasi penuh). FY2020-2022 (masa IPO/COVID, basis pendapatan berbeda) tidak dipakai sebagai patokan.
A7: Kunci | B7: Driver | C7: FY2020A | D7: FY2021A | E7: FY2022A | F7: FY2023A | G7: FY2024A | H7: FY2025A | I7: FY2026E | J7: FY2027E | K7: FY2028E | L7: FY2029E | M7: FY2030E | N7: Dasar asumsi (kalibrasi FY2022-FY2025)
B8: ASUMSI AKTIF - kolom historis = aktual (rumus), kolom E = skenario terpilih
B9: PENDAPATAN (per jenis layanan, Cat 20)
A10: g_inpat | B10: Pertumbuhan pendapatan rawat inap | D10: =IFERROR(Schedules!D6/Schedules!C6-1,"") | E10: =IFERROR(Schedules!E6/Schedules!D6-1,"") -> -0.23780263 | F10: =IFERROR(Schedules!F6/Schedules!E6-1,"") -> 0.017350281 | G10: =IFERROR(Schedules!G6/Schedules!F6-1,"") -> 0.3060916 | H10: =IFERROR(Schedules!H6/Schedules!G6-1,"") -> 0.034481309 | I10: =CHOOSE(Asumsi!$D$4,I36,I61,I86) -> 0.12 | J10: =CHOOSE(Asumsi!$D$4,J36,J61,J86) -> 0.12 | K10: =CHOOSE(Asumsi!$D$4,K36,K61,K86) -> 0.12 | L10: =CHOOSE(Asumsi!$D$4,L36,L61,L86) -> 0.12 | M10: =CHOOSE(Asumsi!$D$4,M36,M61,M86) -> 0.12 | N10: Pendapatan: 2022 174 M, 2023 177 M, 2024 231 M, 2025 239 M. CAGR 2023-25 16,2% (fase ramp-up RS baru). Base 12%; Bull 16%; Bear 7%.
A11: g_outpat | B11: Pertumbuhan pendapatan rawat jalan | D11: =IFERROR(Schedules!D7/Schedules!C7-1,"") | E11: =IFERROR(Schedules!E7/Schedules!D7-1,"") -> -0.11374661 | F11: =IFERROR(Schedules!F7/Schedules!E7-1,"") -> -0.23902013 | G11: =IFERROR(Schedules!G7/Schedules!F7-1,"") -> 0.3372491 | H11: =IFERROR(Schedules!H7/Schedules!G7-1,"") -> 0.16946515 | I11: =CHOOSE(Asumsi!$D$4,I37,I62,I87) -> 0.15 | J11: =CHOOSE(Asumsi!$D$4,J37,J62,J87) -> 0.15 | K11: =CHOOSE(Asumsi!$D$4,K37,K62,K87) -> 0.15 | L11: =CHOOSE(Asumsi!$D$4,L37,L62,L87) -> 0.15 | M11: =CHOOSE(Asumsi!$D$4,M37,M62,M87) -> 0.15 | N11: Pendapatan: 2022 87 M, 2023 66 M, 2024 88 M, 2025 103 M. CAGR 2023-25 25,1%. Base 15%; Bull 20%; Bear 9%.
B12: MARGIN & BIAYA (% pendapatan neto)
A13: cogs | B13: Beban pokok di luar penyusutan | C13: =IFERROR(-(IS!C7+Schedules!C12)/IS!C6,"") -> 0.52430277 | D13: =IFERROR(-(IS!D7+Schedules!D12)/IS!D6,"") -> 0.43894136 | E13: =IFERROR(-(IS!E7+Schedules!E12)/IS!E6,"") -> 0.49091966 | F13: =IFERROR(-(IS!F7+Schedules!F12)/IS!F6,"") -> 0.54162322 | G13: =IFERROR(-(IS!G7+Schedules!G12)/IS!G6,"") -> 0.59218078 | H13: =IFERROR(-(IS!H7+Schedules!H12)/IS!H6,"") -> 0.45086354 | I13: =CHOOSE(Asumsi!$D$4,I39,I64,I89) -> 0.57 | J13: =CHOOSE(Asumsi!$D$4,J39,J64,J89) -> 0.57 | K13: =CHOOSE(Asumsi!$D$4,K39,K64,K89) -> 0.57 | L13: =CHOOSE(Asumsi!$D$4,L39,L64,L89) -> 0.57 | M13: =CHOOSE(Asumsi!$D$4,M39,M64,M89) -> 0.57 | N13: Historis: 2022 49,1%, 2023 54,2%, 2024 59,2%, 2025 45,1% (2025 diturunkan oleh pendapatan investasi 97,8 M di pendapatan; Temuan C5). Atas pendapatan RS saja 2025 ±57%. Base 57%; Bull 55%; Bear 60%.
A14: opex | B14: Beban usaha di luar penyusutan | C14: =IFERROR(-(IS!C9+Schedules!C13+Schedules!C16+Schedules!C17)/IS!C6,"") -> 0.54743769 | D14: =IFERROR(-(IS!D9+Schedules!D13+Schedules!D16+Schedules!D17)/IS!D6,"") -> 0.45314676 | E14: =IFERROR(-(IS!E9+Schedules!E13+Schedules!E16+Schedules!E17)/IS!E6,"") -> 0.67027038 | F14: =IFERROR(-(IS!F9+Schedules!F13+Schedules!F16+Schedules!F17)/IS!F6,"") -> 0.51834778 | G14: =IFERROR(-(IS!G9+Schedules!G13+Schedules!G16+Schedules!G17)/IS!G6,"") -> 0.42164856 | H14: =IFERROR(-(IS!H9+Schedules!H13+Schedules!H16+Schedules!H17)/IS!H6,"") -> 0.33005387 | I14: =CHOOSE(Asumsi!$D$4,I40,I65,I90) -> 0.38 | J14: =CHOOSE(Asumsi!$D$4,J40,J65,J90) -> 0.38 | K14: =CHOOSE(Asumsi!$D$4,K40,K65,K90) -> 0.38 | L14: =CHOOSE(Asumsi!$D$4,L40,L65,L90) -> 0.38 | M14: =CHOOSE(Asumsi!$D$4,M40,M65,M90) -> 0.38 | N14: Historis: 2022 67,0%, 2023 51,8%, 2024 42,2%, 2025 33,0%. Atas pendapatan RS saja 2025 ±42%; skala operasi menurunkan rasio. Base 38%; Bull 35%; Bear 42%.
A15: other_op | B15: Pendapatan (beban) lain neto (di bawah laba usaha) | C15: =IFERROR(IS!C12/IS!C6,"") -> 0.0024631428 | D15: =IFERROR(IS!D12/IS!D6,"") -> 0.0084739653 | E15: =IFERROR(IS!E12/IS!E6,"") -> 0.10957279 | F15: =IFERROR(IS!F12/IS!F6,"") -> 0.0010315002 | G15: =IFERROR(IS!G12/IS!G6,"") -> 0.079103768 | H15: =IFERROR(IS!H12/IS!H6,"") -> 0.0064969318 | I15: =CHOOSE(Asumsi!$D$4,I41,I66,I91) -> 0.005 | J15: =CHOOSE(Asumsi!$D$4,J41,J66,J91) -> 0.005 | K15: =CHOOSE(Asumsi!$D$4,K41,K66,K91) -> 0.005 | L15: =CHOOSE(Asumsi!$D$4,L41,L66,L91) -> 0.005 | M15: =CHOOSE(Asumsi!$D$4,M41,M66,M91) -> 0.005 | N15: Historis: 2022 0,0%, 2023 0,0%, 2024 0,0%, 2025 0,0% (2022 & 2024 memuat pos tidak berulang). Base 0,5%; Bull 0,8%; Bear 0,3%.
B16: INVESTASI & ASET
A17: capex | B17: Capex aset tetap + uang muka aset tetap (% pendapatan) | C17: =IFERROR(-(CF!C22+CF!C21)/IS!C6,"") -> 2.414598 | D17: =IFERROR(-(CF!D22+CF!D21)/IS!D6,"") -> 1.0669243 | E17: =IFERROR(-(CF!E22+CF!E21)/IS!E6,"") -> 1.2414102 | F17: =IFERROR(-(CF!F22+CF!F21)/IS!F6,"") -> 0.051763514 | G17: =IFERROR(-(CF!G22+CF!G21)/IS!G6,"") -> 0.71132929 | H17: =IFERROR(-(CF!H22+CF!H21)/IS!H6,"") -> 0.47926252 | I17: =CHOOSE(Asumsi!$D$4,I43,I68,I93) -> 0.08 | J17: =CHOOSE(Asumsi!$D$4,J43,J68,J93) -> 0.08 | K17: =CHOOSE(Asumsi!$D$4,K43,K68,K93) -> 0.08 | L17: =CHOOSE(Asumsi!$D$4,L43,L68,L93) -> 0.08 | M17: =CHOOSE(Asumsi!$D$4,M43,M68,M93) -> 0.08 | N17: Historis kas: 2022 124,1%, 2023 5,2%, 2024 71,1%, 2025 47,9% (pembangunan RS selesai). Base 8%; Bull 6%; Bear 12%.
A18: lease_pd | B18: Penambahan sewa dikapitalisasi (% pendapatan; CARE: tidak ada) | C18: =0 -> 0 | D18: =0 -> 0 | E18: =0 -> 0 | F18: =0 -> 0 | G18: =0 -> 0 | H18: =0 -> 0 | I18: =CHOOSE(Asumsi!$D$4,I44,I69,I94) -> 0 | J18: =CHOOSE(Asumsi!$D$4,J44,J69,J94) -> 0 | K18: =CHOOSE(Asumsi!$D$4,K44,K69,K94) -> 0 | L18: =CHOOSE(Asumsi!$D$4,L44,L69,L94) -> 0 | M18: =CHOOSE(Asumsi!$D$4,M44,M69,M94) -> 0 | N18: CARE tidak memiliki liabilitas sewa; 0 di semua skenario.
A19: dep | B19: Penyusutan aset tetap (% aset tetap neto awal) | D19: =IFERROR(Schedules!D14/BS!C16,"") -> 0.0079516282 | E19: =IFERROR(Schedules!E14/BS!D16,"") -> 0.0078461143 | F19: =IFERROR(Schedules!F14/BS!E16,"") -> 0.0064676906 | G19: =IFERROR(Schedules!G14/BS!F16,"") -> 0.0076614698 | H19: =IFERROR(Schedules!H14/BS!G16,"") -> 0.0080818592 | I19: =CHOOSE(Asumsi!$D$4,I45,I70,I95) -> 0.0074 | J19: =CHOOSE(Asumsi!$D$4,J45,J70,J95) -> 0.0074 | K19: =CHOOSE(Asumsi!$D$4,K45,K70,K95) -> 0.0074 | L19: =CHOOSE(Asumsi!$D$4,L45,L70,L95) -> 0.0074 | M19: =CHOOSE(Asumsi!$D$4,M45,M70,M95) -> 0.0074 | N19: Historis: 2022 0,8%, 2023 0,6%, 2024 0,8%, 2025 0,8% (porsi besar aset tetap = tanah & bangunan dalam penyelesaian). Base/Bull/Bear = rata-rata 2023-25.
A20: sw | B20: Amortisasi aset takberwujud (CARE: goodwill, tidak diamortisasi) | C20: =0 -> 0 | D20: =0 -> 0 | E20: =0 -> 0 | F20: =0 -> 0 | G20: =0 -> 0 | H20: =0 -> 0 | I20: =CHOOSE(Asumsi!$D$4,I46,I71,I96) -> 0 | J20: =CHOOSE(Asumsi!$D$4,J46,J71,J96) -> 0 | K20: =CHOOSE(Asumsi!$D$4,K46,K71,K96) -> 0 | L20: =CHOOSE(Asumsi!$D$4,L46,L71,L96) -> 0 | M20: =CHOOSE(Asumsi!$D$4,M46,M71,M96) -> 0 | N20: Goodwill tidak diamortisasi; 0.
B21: MODAL KERJA (hari, saldo akhir, basis 365)
A22: dso | B22: DSO piutang usaha / pendapatan | C22: =IFERROR(BS!C8/IS!C6*365,"") -> 78.157702 | D22: =IFERROR(BS!D8/IS!D6*365,"") -> 54.471996 | E22: =IFERROR(BS!E8/IS!E6*365,"") -> 30.410991 | F22: =IFERROR(BS!F8/IS!F6*365,"") -> 44.764498 | G22: =IFERROR(BS!G8/IS!G6*365,"") -> 44.949167 | H22: =IFERROR(BS!H8/IS!H6*365,"") -> 26.904669 | I22: =CHOOSE(Asumsi!$D$4,I48,I73,I98) -> 40 | J22: =CHOOSE(Asumsi!$D$4,J48,J73,J98) -> 40 | K22: =CHOOSE(Asumsi!$D$4,K48,K73,K98) -> 40 | L22: =CHOOSE(Asumsi!$D$4,L48,L73,L98) -> 40 | M22: =CHOOSE(Asumsi!$D$4,M48,M73,M98) -> 40 | N22: Historis: 2022 30,4, 2023 44,8, 2024 44,9, 2025 26,9. Base 40; Bull 35; Bear 45.
A23: dio | B23: DIO persediaan / beban pokok di luar penyusutan | C23: =IFERROR(BS!C10/-(IS!C7+Schedules!C12)*365,"") -> 22.105991 | D23: =IFERROR(BS!D10/-(IS!D7+Schedules!D12)*365,"") -> 17.517856 | E23: =IFERROR(BS!E10/-(IS!E7+Schedules!E12)*365,"") -> 12.107786 | F23: =IFERROR(BS!F10/-(IS!F7+Schedules!F12)*365,"") -> 13.269195 | G23: =IFERROR(BS!G10/-(IS!G7+Schedules!G12)*365,"") -> 12.110239 | H23: =IFERROR(BS!H10/-(IS!H7+Schedules!H12)*365,"") -> 9.8392559 | I23: =CHOOSE(Asumsi!$D$4,I49,I74,I99) -> 11 | J23: =CHOOSE(Asumsi!$D$4,J49,J74,J99) -> 11 | K23: =CHOOSE(Asumsi!$D$4,K49,K74,K99) -> 11 | L23: =CHOOSE(Asumsi!$D$4,L49,L74,L99) -> 11 | M23: =CHOOSE(Asumsi!$D$4,M49,M74,M99) -> 11 | N23: Historis: 2022 12,1, 2023 13,3, 2024 12,1, 2025 9,8. Base 11; Bull 10; Bear 12.
A24: dpo | B24: DPO utang usaha / beban pokok di luar penyusutan | C24: =IFERROR(BS!C24/-(IS!C7+Schedules!C12)*365,"") -> 34.831007 | D24: =IFERROR(BS!D24/-(IS!D7+Schedules!D12)*365,"") -> 41.891802 | E24: =IFERROR(BS!E24/-(IS!E7+Schedules!E12)*365,"") -> 85.404129 | F24: =IFERROR(BS!F24/-(IS!F7+Schedules!F12)*365,"") -> 118.10956 | G24: =IFERROR(BS!G24/-(IS!G7+Schedules!G12)*365,"") -> 48.535333 | H24: =IFERROR(BS!H24/-(IS!H7+Schedules!H12)*365,"") -> 38.937891 | I24: =CHOOSE(Asumsi!$D$4,I50,I75,I100) -> 45 | J24: =CHOOSE(Asumsi!$D$4,J50,J75,J100) -> 45 | K24: =CHOOSE(Asumsi!$D$4,K50,K75,K100) -> 45 | L24: =CHOOSE(Asumsi!$D$4,L50,L75,L100) -> 45 | M24: =CHOOSE(Asumsi!$D$4,M50,M75,M100) -> 45 | N24: Historis: 2022 85,4, 2023 118,1, 2024 48,5, 2025 38,9. Base 45; Bull 50; Bear 40.
B25: PAJAK, PENDANAAN, DISTRIBUSI
A26: tax | B26: Tarif pajak (% laba sebelum pajak positif; rugi = 0) | C26: =IFERROR(-IS!C16/IS!C15,"") -> -0.027198489 | D26: =IFERROR(-IS!D16/IS!D15,"") -> 0.051166078 | E26: =IFERROR(-IS!E16/IS!E15,"") -> -0.0030912546 | F26: =IFERROR(-IS!F16/IS!F15,"") -> -0.043025819 | G26: =IFERROR(-IS!G16/IS!G15,"") -> -0.054817048 | H26: =IFERROR(-IS!H16/IS!H15,"") -> 0.36248885 | I26: =CHOOSE(Asumsi!$D$4,I52,I77,I102) -> 0.22 | J26: =CHOOSE(Asumsi!$D$4,J52,J77,J102) -> 0.22 | K26: =CHOOSE(Asumsi!$D$4,K52,K77,K102) -> 0.22 | L26: =CHOOSE(Asumsi!$D$4,L52,L77,L102) -> 0.22 | M26: =CHOOSE(Asumsi!$D$4,M52,M77,M102) -> 0.22 | N26: Historis tarif efektif: 2022 -0,3%, 2023 -4,3%, 2024 -5,5%, 2025 36,2% (tidak bermakna saat rugi; pajak tangguhan). Tarif badan 22% hanya pada laba positif.
A27: fin_cost | B27: Suku bunga efektif (beban keuangan / rata-rata utang berbunga) | D27: =IFERROR(-IS!D14/AVERAGE((BS!D23+BS!D30+BS!D34+BS!D31+BS!D35+BS!D32+BS!D36),(BS!C23+BS!C30+BS!C34+BS!C31+BS!C35+BS!C32+BS!C36)),"") -> 0.053817975 | E27: =IFERROR(-IS!E14/AVERAGE((BS!E23+BS!E30+BS!E34+BS!E31+BS!E35+BS!E32+BS!E36),(BS!D23+BS!D30+BS!D34+BS!D31+BS!D35+BS!D32+BS!D36)),"") -> 0.10010136 | F27: =IFERROR(-IS!F14/AVERAGE((BS!F23+BS!F30+BS!F34+BS!F31+BS!F35+BS!F32+BS!F36),(BS!E23+BS!E30+BS!E34+BS!E31+BS!E35+BS!E32+BS!E36)),"") -> 0.080413901 | G27: =IFERROR(-IS!G14/AVERAGE((BS!G23+BS!G30+BS!G34+BS!G31+BS!G35+BS!G32+BS!G36),(BS!F23+BS!F30+BS!F34+BS!F31+BS!F35+BS!F32+BS!F36)),"") -> 0.081427908 | H27: =IFERROR(-IS!H14/AVERAGE((BS!H23+BS!H30+BS!H34+BS!H31+BS!H35+BS!H32+BS!H36),(BS!G23+BS!G30+BS!G34+BS!G31+BS!G35+BS!G32+BS!G36)),"") -> 0.079243528 | I27: =CHOOSE(Asumsi!$D$4,I53,I78,I103) -> 0.0804 | J27: =CHOOSE(Asumsi!$D$4,J53,J78,J103) -> 0.0804 | K27: =CHOOSE(Asumsi!$D$4,K53,K78,K103) -> 0.0804 | L27: =CHOOSE(Asumsi!$D$4,L53,L78,L103) -> 0.0804 | M27: =CHOOSE(Asumsi!$D$4,M53,M78,M103) -> 0.0804 | N27: Historis: 2023 8,04%, 2024 8,14%, 2025 7,92%. Base = rata-rata 2023-25; Bull x0,9; Bear x1,1. Beban = suku bunga x rata-rata utang (Temuan C6).
A28: yld | B28: Imbal hasil kas (penghasilan keuangan / kas awal) | D28: =IFERROR(IS!D13/BS!C6,"") -> 0.030033394 | E28: =IFERROR(IS!E13/BS!D6,"") -> 0.058600482 | F28: =IFERROR(IS!F13/BS!E6,"") -> 0.012421559 | G28: =IFERROR(IS!G13/BS!F6,"") -> 0.011873623 | H28: =IFERROR(IS!H13/BS!G6,"") -> 0.03463915 | I28: =CHOOSE(Asumsi!$D$4,I54,I79,I104) -> 0.0196 | J28: =CHOOSE(Asumsi!$D$4,J54,J79,J104) -> 0.0196 | K28: =CHOOSE(Asumsi!$D$4,K54,K79,K104) -> 0.0196 | L28: =CHOOSE(Asumsi!$D$4,L54,L79,L104) -> 0.0196 | M28: =CHOOSE(Asumsi!$D$4,M54,M79,M104) -> 0.0196 | N28: Historis: 2022 5,86%, 2023 1,24%, 2024 1,19%, 2025 3,46%. Base = rata-rata 2023-25; Bear x0,8; tanpa circular reference.
A29: debt_chg | B29: Perubahan neto utang (Rp; + = tambah) | D29: =(BS!D23+BS!D30+BS!D34+BS!D31+BS!D35+BS!D32+BS!D36)-(BS!C23+BS!C30+BS!C34+BS!C31+BS!C35+BS!C32+BS!C36) -> 727901075220 | E29: =(BS!E23+BS!E30+BS!E34+BS!E31+BS!E35+BS!E32+BS!E36)-(BS!D23+BS!D30+BS!D34+BS!D31+BS!D35+BS!D32+BS!D36) -> 112973480557 | F29: =(BS!F23+BS!F30+BS!F34+BS!F31+BS!F35+BS!F32+BS!F36)-(BS!E23+BS!E30+BS!E34+BS!E31+BS!E35+BS!E32+BS!E36) -> -2523103518 | G29: =(BS!G23+BS!G30+BS!G34+BS!G31+BS!G35+BS!G32+BS!G36)-(BS!F23+BS!F30+BS!F34+BS!F31+BS!F35+BS!F32+BS!F36) -> -10047593917 | H29: =(BS!H23+BS!H30+BS!H34+BS!H31+BS!H35+BS!H32+BS!H36)-(BS!G23+BS!G30+BS!G34+BS!G31+BS!G35+BS!G32+BS!G36) -> 139168430360 | I29: =CHOOSE(Asumsi!$D$4,I55,I80,I105) -> 0 | J29: =CHOOSE(Asumsi!$D$4,J55,J80,J105) -> 0 | K29: =CHOOSE(Asumsi!$D$4,K55,K80,K105) -> 0 | L29: =CHOOSE(Asumsi!$D$4,L55,L80,L105) -> 0 | M29: =CHOOSE(Asumsi!$D$4,M55,M80,M105) -> 0 | N29: Historis utang berbunga: 2022 957 M, 2023 955 M, 2024 944 M, 2025 1.084 M. Semua skenario 0 (kas = penyeimbang; refinancing tidak dimodelkan).
A30: payout | B30: Payout dividen (% laba induk tahun lalu) | C30: =0 -> 0 | D30: =0 -> 0 | E30: =0 -> 0 | F30: =0 -> 0 | G30: =0 -> 0 | H30: =0 -> 0 | I30: =CHOOSE(Asumsi!$D$4,I56,I81,I106) -> 0 | J30: =CHOOSE(Asumsi!$D$4,J56,J81,J106) -> 0 | K30: =CHOOSE(Asumsi!$D$4,K56,K81,K106) -> 0 | L30: =CHOOSE(Asumsi!$D$4,L56,L81,L106) -> 0 | M30: =CHOOSE(Asumsi!$D$4,M56,M81,M106) -> 0 | N30: CARE tidak membagi dividen FY2020-2025 dan masih defisit; 0 di semua skenario.
A31: nci_share | B31: Porsi laba ke NCI (% laba tahun berjalan) | C31: =IFERROR(IS!C25/IS!C17,"") -> -0.010226703 | D31: =IFERROR(IS!D25/IS!D17,"") -> 0.012056273 | E31: =IFERROR(IS!E25/IS!E17,"") -> 0.00064660741 | F31: =IFERROR(IS!F25/IS!F17,"") -> -0.0020862705 | G31: =IFERROR(IS!G25/IS!G17,"") -> -0.0049045902 | H31: =IFERROR(IS!H25/IS!H17,"") -> 0.037478444 | I31: =CHOOSE(Asumsi!$D$4,I57,I82,I107) -> 0.037 | J31: =CHOOSE(Asumsi!$D$4,J57,J82,J107) -> 0.037 | K31: =CHOOSE(Asumsi!$D$4,K57,K82,K107) -> 0.037 | L31: =CHOOSE(Asumsi!$D$4,L57,L82,L107) -> 0.037 | M31: =CHOOSE(Asumsi!$D$4,M57,M82,M107) -> 0.037 | N31: Historis: 2022 0,1%, 2023 -0,2%, 2024 -0,5%, 2025 3,7%. 3,7% semua skenario.
B34: SKENARIO BASE - input biru per tahun (boleh diubah pengguna)
B35: PENDAPATAN (per jenis layanan, Cat 20)
A36: Base.g_inpat | B36: Pertumbuhan pendapatan rawat inap | I36: 0.12 | J36: 0.12 | K36: 0.12 | L36: 0.12 | M36: 0.12
A37: Base.g_outpat | B37: Pertumbuhan pendapatan rawat jalan | I37: 0.15 | J37: 0.15 | K37: 0.15 | L37: 0.15 | M37: 0.15
B38: MARGIN & BIAYA (% pendapatan neto)
A39: Base.cogs | B39: Beban pokok di luar penyusutan | I39: 0.57 | J39: 0.57 | K39: 0.57 | L39: 0.57 | M39: 0.57
A40: Base.opex | B40: Beban usaha di luar penyusutan | I40: 0.38 | J40: 0.38 | K40: 0.38 | L40: 0.38 | M40: 0.38
A41: Base.other_op | B41: Pendapatan (beban) lain neto (di bawah laba usaha) | I41: 0.005 | J41: 0.005 | K41: 0.005 | L41: 0.005 | M41: 0.005
B42: INVESTASI & ASET
A43: Base.capex | B43: Capex aset tetap + uang muka aset tetap (% pendapatan) | I43: 0.08 | J43: 0.08 | K43: 0.08 | L43: 0.08 | M43: 0.08
A44: Base.lease_pd | B44: Penambahan sewa dikapitalisasi (% pendapatan; CARE: tidak ada) | I44: 0 | J44: 0 | K44: 0 | L44: 0 | M44: 0
...

Sheet IS_Proj
A1: Proyeksi laba rugi (ilustratif)
A2: Rp penuh | kolom A = aktual (link ke IS/BS/CF/Schedules), kolom E = proyeksi | Proyeksi ILUSTRATIF berbasis asumsi transparan - bukan rekomendasi investasi, bukan target, bukan nilai wajar.
A3: Skenario aktif: | C3: =Asumsi!C4 -> Base | I3: ilustratif | J3: ilustratif | K3: ilustratif | L3: ilustratif | M3: ilustratif
A4: Kode | B4: Akun | C4: FY2020A | D4: FY2021A | E4: FY2022A | F4: FY2023A | G4: FY2024A | H4: FY2025A | I4: FY2026E | J4: FY2027E | K4: FY2028E | L4: FY2029E | M4: FY2030E | N4: Catatan / sumber
B5: PENDAPATAN (per jenis layanan)
A6: P.REV_INPAT | B6: Rawat inap | D6: =Schedules!D6 -> 227741067451 | E6: =Schedules!E6 -> 173583642926 | F6: =Schedules!F6 -> 176595367941 | G6: =Schedules!G6 -> 230649727444 | H6: =Schedules!H6 -> 238602832073 | I6: =H6*(1+Asumsi!I10) -> 2.6723517e+11 | J6: =I6*(1+Asumsi!J10) -> 2.9930339e+11 | K6: =J6*(1+Asumsi!K10) -> 3.352198e+11 | L6: =K6*(1+Asumsi!L10) -> 3.7544618e+11 | M6: =L6*(1+Asumsi!M10) -> 4.2049972e+11
A7: P.REV_OUTPAT | B7: Rawat jalan | D7: =Schedules!D7 -> 97988396120 | E7: =Schedules!E7 -> 86842548252 | F7: =Schedules!F7 -> 66085431242 | G7: =Schedules!G7 -> 88372683358 | H7: =Schedules!H7 -> 103348773155 | I7: =H7*(1+Asumsi!I11) -> 1.1885109e+11 | J7: =I7*(1+Asumsi!J11) -> 1.3667875e+11 | K7: =J7*(1+Asumsi!K11) -> 1.5718057e+11 | L7: =K7*(1+Asumsi!L11) -> 1.8075765e+11 | M7: =L7*(1+Asumsi!M11) -> 2.078713e+11
A8: P.REV_OTHER | B8: Lainnya (pendapatan investasi 2025) & diskon (2021-22) | D8: =Schedules!D8+Schedules!D9 -> -34795107445 | E8: =Schedules!E8+Schedules!E9 -> -26455466569 | F8: =Schedules!F8+Schedules!F9 -> 0 | G8: =Schedules!G8+Schedules!G9 -> 0 | H8: =Schedules!H8+Schedules!H9 -> 97800000000 | I8: =0 -> 0 | J8: =0 -> 0 | K8: =0 -> 0 | L8: =0 -> 0 | M8: =0 -> 0 | N8: E: 0 (tidak berulang; Temuan C4-C5)
A9: P.REVENUE | B9: Pendapatan neto | C9: =IS!C6 -> 216296095571 | D9: =IS!D6 -> 290934356126 | E9: =IS!E6 -> 233970724609 | F9: =IS!F6 -> 242680799183 | G9: =IS!G6 -> 319022410802 | H9: =IS!H6 -> 439751605228 | I9: =I6+I7+I8 -> 3.8608626e+11 | J9: =J6+J7+J8 -> 4.3598215e+11 | K9: =K6+K7+K8 -> 4.9240037e+11 | L9: =L6+L7+L8 -> 5.5620383e+11 | M9: =M6+M7+M8 -> 6.2837101e+11
A10: P.REV_GROWTH | B10: Pertumbuhan pendapatan neto | D10: =D9/C9-1 -> 0.34507447 | E10: =E9/D9-1 -> -0.19579548 | F10: =F9/E9-1 -> 0.037227198 | G10: =G9/F9-1 -> 0.31457623 | H10: =H9/G9-1 -> 0.37843484 | I10: =I9/H9-1 -> -0.12203558 | J10: =J9/I9-1 -> 0.12923507 | K10: =K9/J9-1 -> 0.12940489 | ... M10: =M9/L9-1 -> 0.12974954
B11: BIAYA & EBITDA
A12: P.COGS_X | B12: Beban pokok di luar penyusutan | D12: =IS!D7+Schedules!D12 -> -127703122398 | E12: =IS!E7+Schedules!E12 -> -114860829484 | F12: =IS!F7+Schedules!F12 -> -131441555891 | G12: =IS!G7+Schedules!G12 -> -188918940570 | H12: =IS!H7+Schedules!H12 -> -198267964153 | I12: =-I9*Asumsi!I13 -> -2.2006917e+11 | J12: =-J9*Asumsi!J13 -> -2.4850982e+11 | K12: =-K9*Asumsi!K13 -> -2.8066821e+11 | L12: =-L9*Asumsi!L13 -> -3.1703618e+11 | M12: =-M9*Asumsi!M13 -> -3.5817148e+11
A13: P.GP_X | B13: Laba bruto sebelum penyusutan | D13: =D9+D12 -> 163231233728 | E13: =E9+E12 -> 119109895125 | F13: =F9+F12 -> 111239243292 | G13: =G9+G12 -> 130103470232 | H13: =H9+H12 -> 241483641075 | I13: =I9+I12 -> 1.6601709e+11 | J13: =J9+J12 -> 1.8747232e+11 | K13: =K9+K12 -> 2.1173216e+11 | ... M13: =M9+M12 -> 2.7019954e+11
A14: P.OPEX_X | B14: Beban usaha di luar penyusutan & amortisasi | D14: =IS!D9+Schedules!D13+Schedules!D16+Schedules!D17 -> -131835962281 | E14: =IS!E9+Schedules!E13+Schedules!E16+Schedules!E17 -> -156823647433 | F14: =IS!F9+Schedules!F13+Schedules!F16+Schedules!F17 -> -125793052442 | G14: =IS!G9+Schedules!G13+Schedules!G16+Schedules!G17 -> -134515340769 | H14: =IS!H9+Schedules!H13+Schedules!H16+Schedules!H17 -> -145141717485 | I14: =-I9*Asumsi!I14 -> -1.4671278e+11 | J14: =-J9*Asumsi!J14 -> -1.6567322e+11 | K14: =-K9*Asumsi!K14 -> -1.8711214e+11 | L14: =-L9*Asumsi!L14 -> -2.1135745e+11 | M14: =-M9*Asumsi!M14 -> -2.3878099e+11
A15: P.EBITDA | B15: EBITDA | D15: =D13+D14 -> 31395271447 | E15: =E13+E14 -> -37713752308 | F15: =F13+F14 -> -14553809150 | G15: =G13+G14 -> -4411870537 | H15: =H13+H14 -> 96341923590 | I15: =I13+I14 -> 1.9304313e+10 | J15: =J13+J14 -> 2.1799107e+10 | K15: =K13+K14 -> 2.4620018e+10 | ... M15: =M13+M14 -> 3.1418551e+10 | N15: laba (rugi) usaha + penyusutan aset tetap (FY2020 kosong: Temuan C2)
A16: P.DA | B16: Penyusutan & amortisasi | D16: =-Schedules!D18 -> -17297314280 | E16: =-Schedules!E18 -> -22877629559 | F16: =-Schedules!F18 -> -21584974350 | G16: =-Schedules!G18 -> -25515756073 | H16: =-Schedules!H18 -> -26326052136 | I16: =-(Schedules_Proj!I9+Schedules_Proj!I13) -> -2.4217183e+10 | J16: =-(Schedules_Proj!J9+Schedules_Proj!J13) -> -2.4266539e+10 | K16: =-(Schedules_Proj!K9+Schedules_Proj!K13) -> -2.4345068e+10 | L16: =-(Schedules_Proj!L9+Schedules_Proj!L13) -> -2.4456415e+10 | M16: =-(Schedules_Proj!M9+Schedules_Proj!M13) -> -2.460471e+10
A17: P.EBIT | B17: Laba (rugi) usaha (EBIT) | C17: =IS!C10 -> -15517181073 | D17: =D15+D16 -> 14097957167 | E17: =E15+E16 -> -60591381867 | F17: =F15+F16 -> -36138783500 | G17: =G15+G16 -> -29927626610 | H17: =H15+H16 -> 70015871454 | I17: =I15+I16 -> -4.9128696e+09 | J17: =J15+J16 -> -2.4674313e+09 | K17: =K15+K16 -> 2.7495068e+08 | ... M17: =M15+M16 -> 6.8138404e+09 | N17: historis: = laba usaha IS (cek di Rekonsiliasi)
A18: P.OTHER_OP | B18: Pendapatan (beban) lain neto | C18: =IS!C12 -> 532768164 | D18: =IS!D12 -> 2465367652 | E18: =IS!E12 -> 25636825732 | F18: =IS!F12 -> 250325287 | G18: =IS!G12 -> 25235874672 | H18: =IS!H12 -> 2857036197 | I18: =I9*Asumsi!I15 -> 1.9304313e+09 | J18: =J9*Asumsi!J15 -> 2.1799107e+09 | K18: =K9*Asumsi!K15 -> 2.4620018e+09 | L18: =L9*Asumsi!L15 -> 2.7810191e+09 | M18: =M9*Asumsi!M15 -> 3.1418551e+09
A19: P.FIN_INC | B19: Penghasilan keuangan | C19: =IS!C13 -> 40428301431 | D19: =IS!D13 -> 15781938577 | E19: =IS!E13 -> 31784929332 | F19: =IS!F13 -> 6623274915 | G19: =IS!G13 -> 6242710845 | H19: =IS!H13 -> 15555391585 | I19: =BS_Proj!H6*Asumsi!I28 -> 8.2360003e+09 | J19: =BS_Proj!I6*Asumsi!J28 -> 6.3986315e+09 | K19: =BS_Proj!J6*Asumsi!K28 -> 4.54753e+09 | L19: =BS_Proj!K6*Asumsi!L28 -> 2.6252801e+09 | M19: =BS_Proj!L6*Asumsi!M28 -> 6.2591287e+08 | N19: E: imbal hasil x kas awal
A20: P.FIN_COST | B20: Beban keuangan | C20: =IS!C14 -> -11651080910 | D20: =IS!D14 -> -25838724542 | E20: =IS!E14 -> -90146332117 | F20: =IS!F14 -> -76857656488 | G20: =IS!G14 -> -77315017008 | H20: =IS!H14 -> -80356964083 | I20: =-Schedules_Proj!I24*Asumsi!I27 -> -8.7124256e+10 | J20: =-Schedules_Proj!J24*Asumsi!J27 -> -8.7124256e+10 | K20: =-Schedules_Proj!K24*Asumsi!K27 -> -8.7124256e+10 | L20: =-Schedules_Proj!L24*Asumsi!L27 -> -8.7124256e+10 | M20: =-Schedules_Proj!M24*Asumsi!M27 -> -8.7124256e+10 | N20: E: suku bunga x rata-rata utang (Temuan C6)
A21: P.PBT | B21: Laba sebelum pajak | C21: =C17+C18+C19+C20 -> 13792807612 | D21: =D17+D18+D19+D20 -> 6506538854 | E21: =E17+E18+E19+E20 -> -93315958920 | F21: =F17+F18+F19+F20 -> -106122839786 | G21: =G17+G18+G19+G20 -> -75764058101 | H21: =H17+H18+H19+H20 -> 8071335153 | I21: =I17+I18+I19+I20 -> -8.1870694e+10 | J21: =J17+J18+J19+J20 -> -8.1013145e+10 | ... M21: =M17+M18+M19+M20 -> -7.6542648e+10
A22: P.TAX | B22: Beban pajak | C22: =IS!C16 -> 375143524 | D22: =IS!D16 -> -332914077 | E22: =IS!E16 -> -288463386 | F22: =IS!F16 -> -4566022109 | G22: =IS!G16 -> -4153162003 | H22: =IS!H16 -> -2925769032 | I22: =-MAX(I21,0)*Asumsi!I26 -> 0 | J22: =-MAX(J21,0)*Asumsi!J26 -> 0 | K22: =-MAX(K21,0)*Asumsi!K26 -> 0 | L22: =-MAX(L21,0)*Asumsi!L26 -> 0 | M22: =-MAX(M21,0)*Asumsi!M26 -> 0
A23: P.NI | B23: Laba tahun berjalan | C23: =C21+C22 -> 14167951136 | D23: =D21+D22 -> 6173624777 | E23: =E21+E22 -> -93604422306 | F23: =F21+F22 -> -110688861895 | G23: =G21+G22 -> -79917220104 | H23: =H21+H22 -> 5145566121 | I23: =I21+I22 -> -8.1870694e+10 | J23: =J21+J22 -> -8.1013145e+10 | ... M23: =M21+M22 -> -7.6542648e+10
A24: P.NI_NCI | B24: Diatribusikan ke NCI | C24: =IS!C25 -> -144891428 | D24: =IS!D25 -> 74430906 | E24: =IS!E25 -> -60525313 | F24: =IS!F25 -> 230926912 | G24: =IS!G25 -> 391961217 | H24: =IS!H25 -> 192847813 | I24: =I23*Asumsi!I31 -> -3.0292157e+09 | J24: =J23*Asumsi!J31 -> -2.9974864e+09 | K24: =K23*Asumsi!K31 -> -2.9540716e+09 | L24: =L23*Asumsi!L31 -> -2.8994747e+09 | M24: =M23*Asumsi!M31 -> -2.832078e+09
A25: P.NI_PARENT | B25: Diatribusikan ke pemilik entitas induk | C25: =C23-C24 -> 14312842564 | D25: =D23-D24 -> 6099193871 | E25: =E23-E24 -> -93543896993 | F25: =F23-F24 -> -110919788807 | G25: =G23-G24 -> -80309181321 | H25: =H23-H24 -> 4952718308 | I25: =I23-I24 -> -7.8841479e+10 | J25: =J23-J24 -> -7.8015659e+10 | ... M25: =M23-M24 -> -7.371057e+10
A26: P.EPS | B26: Laba induk per saham (Rp; / 33.250.000.000 saham) | C26: =C25/Asumsi!$C$110 -> 0.43046143 | D26: =D25/Asumsi!$C$110 -> 0.1834344 | E26: =E25/Asumsi!$C$110 -> -2.8133503 | F26: =F25/Asumsi!$C$110 -> -3.3359335 | G26: =G25/Asumsi!$C$110 -> -2.4153137 | H26: =H25/Asumsi!$C$110 -> 0.14895393 | I26: =I25/Asumsi!$C$110 -> -2.3711723 | J26: =J25/Asumsi!$C$110 -> -2.3463356 | ... M26: =M25/Asumsi!$C$110 -> -2.2168592 | N26: saham tetap sejak IPO
B27: MARGIN
A28: P.GM_X | B28: Margin laba bruto sebelum penyusutan | D28: =D13/D9 -> 0.56105864 | E28: =E13/E9 -> 0.50908034 | F28: =F13/F9 -> 0.45837678 | G28: =G13/G9 -> 0.40781922 | H28: =H13/H9 -> 0.54913646 | I28: =I13/I9 -> 0.43 | J28: =J13/J9 -> 0.43 | K28: =K13/K9 -> 0.43 | ... M28: =M13/M9 -> 0.43
A29: P.EBITDA_M | B29: Margin EBITDA | D29: =D15/D9 -> 0.10791187 | E29: =E15/E9 -> -0.16119005 | F29: =F15/F9 -> -0.059970996 | G29: =G15/G9 -> -0.013829344 | H29: =H15/H9 -> 0.2190826 | I29: =I15/I9 -> 0.05 | J29: =J15/J9 -> 0.05 | K29: =K15/K9 -> 0.05 | ... M29: =M15/M9 -> 0.05
A30: P.EBIT_M | B30: Margin EBIT | C30: =C17/C9 -> -0.071740459 | D30: =D17/D9 -> 0.048457519 | E30: =E17/E9 -> -0.25896993 | F30: =F17/F9 -> -0.14891489 | G30: =G17/G9 -> -0.093810421 | H30: =H17/H9 -> 0.15921686 | I30: =I17/I9 -> -0.012724798 | J30: =J17/J9 -> -0.0056594778 | ... M30: =M17/M9 -> 0.010843658
A31: P.NI_M | B31: Margin laba bersih | C31: =C23/C9 -> 0.065502575 | D31: =D23/D9 -> 0.021219992 | E31: =E23/E9 -> -0.40006895 | F31: =F23/F9 -> -0.45610886 | G31: =G23/G9 -> -0.2505066 | H31: =H23/H9 -> 0.011701074 | I31: =I23/I9 -> -0.21205286 | J31: =J23/J9 -> -0.18581758 | ... M31: =M23/M9 -> -0.12181123

Sheet BS_Proj
A1: Proyeksi posisi keuangan agregat (ilustratif)
A2: Rp penuh | kolom A = aktual (link ke IS/BS/CF/Schedules), kolom E = proyeksi | Proyeksi ILUSTRATIF berbasis asumsi transparan - bukan rekomendasi investasi, bukan target, bukan nilai wajar.
A3: Skenario aktif: | C3: =Asumsi!C4 -> Base | I3: ilustratif | J3: ilustratif | K3: ilustratif | L3: ilustratif | M3: ilustratif
A4: Kode | B4: Akun | C4: FY2020A | D4: FY2021A | E4: FY2022A | F4: FY2023A | G4: FY2024A | H4: FY2025A | I4: FY2026E | J4: FY2027E | K4: FY2028E | L4: FY2029E | M4: FY2030E | N4: Catatan / sumber
B5: ASET
A6: PB.CASH | B6: Kas dan setara kas | C6: =BS!C6 -> 525479693804 | D6: =BS!D6 -> 542400475238 | E6: =BS!E6 -> 533208033479 | F6: =BS!F6 -> 525762948837 | G6: =BS!G6 -> 449069663731 | H6: =BS!H6 -> 420204094763 | I6: =CF_Proj!I24 -> 3.2646079e+11 | J6: =CF_Proj!J24 -> 2.3201684e+11 | K6: =CF_Proj!K24 -> 1.3394286e+11 | L6: =CF_Proj!L24 -> 3.193433e+10 | M6: =CF_Proj!M24 -> -7.4350241e+10 | N6: E: penyeimbang dari CF_Proj
A7: PB.AR | B7: Piutang usaha | C7: =BS!C8 -> 46315632063 | D7: =BS!D8 -> 43418562083 | E7: =BS!E8 -> 19493922195 | F7: =BS!F8 -> 29762970115 | G7: =BS!G8 -> 39287099946 | H7: =BS!H8 -> 32414715751 | I7: =Schedules_Proj!I26 -> 4.2310823e+10 | J7: =Schedules_Proj!J26 -> 4.7778865e+10 | K7: =Schedules_Proj!K26 -> 5.3961684e+10 | L7: =Schedules_Proj!L26 -> 6.0953844e+10 | M7: =Schedules_Proj!M26 -> 6.8862577e+10
A8: PB.INV | B8: Persediaan | C8: =BS!C10 -> 6868279382 | D8: =BS!D10 -> 6128999612 | E8: =BS!E10 -> 3810165323 | F8: =BS!F10 -> 4778420963 | G8: =BS!G10 -> 6268091785 | H8: =BS!H10 -> 5344682837 | I8: =Schedules_Proj!I27 -> 6.6322215e+09 | J8: =Schedules_Proj!J27 -> 7.4893371e+09 | K8: =Schedules_Proj!K27 -> 8.4584939e+09 | L8: =Schedules_Proj!L27 -> 9.554515e+09 | M8: =Schedules_Proj!M27 -> 1.0794209e+10
A9: PB.OCA | B9: Aset lancar lainnya | C9: =BS!C15-BS!C6-BS!C8-BS!C10 -> 203189597426 | D9: =BS!D15-BS!D6-BS!D8-BS!D10 -> 662313009876 | E9: =BS!E15-BS!E6-BS!E8-BS!E10 -> 325110362505 | F9: =BS!F15-BS!F6-BS!F8-BS!F10 -> 234215132667 | G9: =BS!G15-BS!G6-BS!G8-BS!G10 -> 48691384911 | H9: =BS!H15-BS!H6-BS!H8-BS!H10 -> 55953490668 | I9: =H9 -> 55953490668 | J9: =I9 -> 55953490668 | K9: =J9 -> 55953490668 | L9: =K9 -> 55953490668 | M9: =L9 -> 55953490668 | N9: termasuk investasi jk pendek; E: konstan
A10: PB.TCA | B10: Jumlah aset lancar | C10: =C6+C7+C8+C9 -> 781853202675 | D10: =D6+D7+D8+D9 -> 1254261046809 | E10: =E6+E7+E8+E9 -> 881622483502 | F10: =F6+F7+F8+F9 -> 794519472582 | G10: =G6+G7+G8+G9 -> 543316240373 | H10: =H6+H7+H8+H9 -> 513916984019 | I10: =I6+I7+I8+I9 -> 4.3135733e+11 | J10: =J6+J7+J8+J9 -> 3.4323853e+11 | ... M10: =M6+M7+M8+M9 -> 6.1260036e+10
A11: PB.PPE | B11: Aset tetap - neto | C11: =BS!C16 -> 2175317280881 | D11: =BS!D16 -> 2915791008035 | E11: =BS!E16 -> 3337354211724 | F11: =BS!F16 -> 3330399614118 | G11: =BS!G16 -> 3257425244004 | H11: =BS!H16 -> 3272592245462 | I11: =Schedules_Proj!I10 -> 3.279262e+12 | J11: =Schedules_Proj!J10 -> 3.289874e+12 | K11: =Schedules_Proj!K10 -> 3.304921e+12 | L11: =Schedules_Proj!L10 -> 3.3249608e+12 | M11: =Schedules_Proj!M10 -> 3.3506258e+12
A12: PB.INTANG | B12: Goodwill | C12: =BS!C17 -> 7024470936 | D12: =BS!D17 -> 6971681464 | E12: =BS!E17 -> 6971681464 | F12: =BS!F17 -> 6971681464 | G12: =BS!G17 -> 0 | H12: =BS!H17 -> 0 | I12: =Schedules_Proj!I15 -> 0 | J12: =Schedules_Proj!J15 -> 0 | K12: =Schedules_Proj!K15 -> 0 | L12: =Schedules_Proj!L15 -> 0 | M12: =Schedules_Proj!M15 -> 0
A13: PB.ONCA | B13: Aset tidak lancar lainnya | C13: =BS!C20-BS!C16-BS!C17 -> 481476309661 | D13: =BS!D20-BS!D16-BS!D17 -> 34188065950 | E13: =BS!E20-BS!E16-BS!E17 -> 8672755722 | F13: =BS!F20-BS!F16-BS!F17 -> 5115489549 | G13: =BS!G20-BS!G16-BS!G17 -> 220363928007 | H13: =BS!H20-BS!H16-BS!H17 -> 389419701284 | I13: =H13 -> 389419701284 | J13: =I13 -> 389419701284 | K13: =J13 -> 389419701284 | L13: =K13 -> 389419701284 | M13: =L13 -> 389419701284 | N13: E: konstan
A14: PB.TNCA | B14: Jumlah aset tidak lancar | C14: =C11+C12+C13 -> 2663818061478 | D14: =D11+D12+D13 -> 2956950755449 | E14: =E11+E12+E13 -> 3352998648910 | F14: =F11+F12+F13 -> 3342486785131 | G14: =G11+G12+G13 -> 3477789172011 | H14: =H11+H12+H13 -> 3662011946746 | I14: =I11+I12+I13 -> 3.6686817e+12 | J14: =J11+J12+J13 -> 3.6792937e+12 | ... M14: =M11+M12+M13 -> 3.7400455e+12
A15: PB.TA | B15: JUMLAH ASET | C15: =C10+C14 -> 3445671264153 | D15: =D10+D14 -> 4211211802258 | E15: =E10+E14 -> 4234621132412 | F15: =F10+F14 -> 4137006257713 | G15: =G10+G14 -> 4021105412384 | H15: =H10+H14 -> 4175928930765 | I15: =I10+I14 -> 4.100039e+12 | J15: =J10+J14 -> 4.0225322e+12 | ... M15: =M10+M14 -> 3.8013056e+12
B16: LIABILITAS
A17: PB.AP | B17: Utang usaha | C17: =BS!C24 -> 10821912088 | D17: =BS!D24 -> 14656750351 | E17: =BS!E24 -> 26875586517 | F17: =BS!F24 -> 42532889111 | G17: =BS!G24 -> 25121215698 | H17: =BS!H24 -> 21151058333 | I17: =Schedules_Proj!I28 -> 2.7131815e+10 | J17: =Schedules_Proj!J28 -> 3.0638197e+10 | K17: =Schedules_Proj!K28 -> 3.460293e+10 | L17: =Schedules_Proj!L28 -> 3.9086652e+10 | M17: =Schedules_Proj!M28 -> 4.4158127e+10
A18: PB.DEBT | B18: Utang berbunga (bank, lembaga keuangan, wesel/sukuk) | C18: =(BS!C23+BS!C30+BS!C34+BS!C31+BS!C35+BS!C32+BS!C36) -> 116162740870 | D18: =(BS!D23+BS!D30+BS!D34+BS!D31+BS!D35+BS!D32+BS!D36) -> 844063816090 | E18: =(BS!E23+BS!E30+BS!E34+BS!E31+BS!E35+BS!E32+BS!E36) -> 957037296647 | F18: =(BS!F23+BS!F30+BS!F34+BS!F31+BS!F35+BS!F32+BS!F36) -> 954514193129 | G18: =(BS!G23+BS!G30+BS!G34+BS!G31+BS!G35+BS!G32+BS!G36) -> 944466599212 | H18: =(BS!H23+BS!H30+BS!H34+BS!H31+BS!H35+BS!H32+BS!H36) -> 1083635029572 | I18: =Schedules_Proj!I23 -> 1083635029572 | J18: =Schedules_Proj!J23 -> 1083635029572 | K18: =Schedules_Proj!K23 -> 1083635029572 | L18: =Schedules_Proj!L23 -> 1083635029572 | M18: =Schedules_Proj!M23 -> 1083635029572
A19: PB.LEASE | B19: Liabilitas sewa (tidak ada) | C19: =0 -> 0 | D19: =0 -> 0 | E19: =0 -> 0 | F19: =0 -> 0 | G19: =0 -> 0 | H19: =0 -> 0 | I19: =Schedules_Proj!I18 -> 0 | J19: =Schedules_Proj!J18 -> 0 | K19: =Schedules_Proj!K18 -> 0 | L19: =Schedules_Proj!L18 -> 0 | M19: =Schedules_Proj!M18 -> 0
A20: PB.OL | B20: Liabilitas lainnya | C20: =BS!C40-BS!C24-(BS!C23+BS!C30+BS!C34+BS!C31+BS!C35+BS!C32+BS!C36) -> 27929171939 | D20: =BS!D40-BS!D24-(BS!D23+BS!D30+BS!D34+BS!D31+BS!D35+BS!D32+BS!D36) -> 54223391980 | E20: =BS!E40-BS!E24-(BS!E23+BS!E30+BS!E34+BS!E31+BS!E35+BS!E32+BS!E36) -> 43816446726 | F20: =BS!F40-BS!F24-(BS!F23+BS!F30+BS!F34+BS!F31+BS!F35+BS!F32+BS!F36) -> 42235167472 | G20: =BS!G40-BS!G24-(BS!G23+BS!G30+BS!G34+BS!G31+BS!G35+BS!G32+BS!G36) -> 33130760746 | H20: =BS!H40-BS!H24-(BS!H23+BS!H30+BS!H34+BS!H31+BS!H35+BS!H32+BS!H36) -> 47287331752 | I20: =H20 -> 47287331752 | J20: =I20 -> 47287331752 | K20: =J20 -> 47287331752 | L20: =K20 -> 47287331752 | M20: =L20 -> 47287331752 | N20: akrual, utang lain, pajak, imbalan kerja, dll; E: konstan
A21: PB.TL | B21: JUMLAH LIABILITAS | C21: =C17+C18+C19+C20 -> 154913824897 | D21: =D17+D18+D19+D20 -> 912943958421 | E21: =E17+E18+E19+E20 -> 1027729329890 | F21: =F17+F18+F19+F20 -> 1039282249712 | G21: =G17+G18+G19+G20 -> 1002718575656 | H21: =H17+H18+H19+H20 -> 1152073419657 | I21: =I17+I18+I19+I20 -> 1.1580542e+12 | J21: =J17+J18+J19+J20 -> 1.1615606e+12 | ... M21: =M17+M18+M19+M20 -> 1.1750805e+12
B22: EKUITAS
A23: PB.EQ_OTHER | B23: Modal & cadangan (selain saldo laba) | C23: =BS!C45-BS!C44 -> 3328284159332 | D23: =BS!D45-BS!D44 -> 3328284159332 | E23: =BS!E45-BS!E44 -> 3328284159332 | F23: =BS!F45-BS!F44 -> 3328284159332 | G23: =BS!G45-BS!G44 -> 3328284159332 | H23: =BS!H45-BS!H44 -> 3328284159332 | I23: =H23 -> 3328284159332 | J23: =I23 -> 3328284159332 | K23: =J23 -> 3328284159332 | L23: =K23 -> 3328284159332 | M23: =L23 -> 3328284159332 | N23: E: konstan
A24: PB.RE | B24: Saldo laba | C24: =BS!C44 -> -38449339396 | D24: =BS!D44 -> -31033031403 | E24: =BS!E44 -> -122376092871 | F24: =BS!F44 -> -231784665472 | G24: =BS!G44 -> -311516892081 | H24: =BS!H44 -> -306241065514 | I24: =H24+IS_Proj!I25+CF_Proj!I19 -> -3.8508254e+11 | J24: =I24+IS_Proj!J25+CF_Proj!J19 -> -4.630982e+11 | K24: =J24+IS_Proj!K25+CF_Proj!K19 -> -5.3998391e+11 | L24: =K24+IS_Proj!L25+CF_Proj!L19 -> -6.1544861e+11 | M24: =L24+IS_Proj!M25+CF_Proj!M19 -> -6.8915918e+11
A25: PB.EQ_PARENT | B25: Ekuitas pemilik entitas induk | C25: =C23+C24 -> 3289834819936 | D25: =D23+D24 -> 3297251127929 | E25: =E23+E24 -> 3205908066461 | F25: =F23+F24 -> 3096499493860 | G25: =G23+G24 -> 3016767267251 | H25: =H23+H24 -> 3022043093818 | I25: =I23+I24 -> 2.9432016e+12 | J25: =J23+J24 -> 2.865186e+12 | ... M25: =M23+M24 -> 2.639125e+12
A26: PB.NCI | B26: Kepentingan nonpengendali | C26: =BS!C46 -> 922619320 | D26: =BS!D46 -> 1016715908 | E26: =BS!E46 -> 983736061 | F26: =BS!F46 -> 1224514141 | G26: =BS!G46 -> 1619569477 | H26: =BS!H46 -> 1812417290 | I26: =H26+IS_Proj!I24 -> -1.2167984e+09 | J26: =I26+IS_Proj!J24 -> -4.2142848e+09 | K26: =J26+IS_Proj!K24 -> -7.1683564e+09 | L26: =K26+IS_Proj!L24 -> -1.0067831e+10 | M26: =L26+IS_Proj!M24 -> -1.2899909e+10 | N26: E: tanpa dividen ke NCI (ilustratif)
A27: PB.TE | B27: JUMLAH EKUITAS | C27: =C25+C26 -> 3290757439256 | D27: =D25+D26 -> 3298267843837 | E27: =E25+E26 -> 3206891802522 | F27: =F25+F26 -> 3097724008001 | G27: =G25+G26 -> 3018386836728 | H27: =H25+H26 -> 3023855511108 | I27: =I25+I26 -> 2.9419848e+12 | J27: =J25+J26 -> 2.8609717e+12 | ... M27: =M25+M26 -> 2.6262251e+12
A28: PB.TLE | B28: JUMLAH LIABILITAS DAN EKUITAS | C28: =C21+C27 -> 3445671264153 | D28: =D21+D27 -> 4211211802258 | E28: =E21+E27 -> 4234621132412 | F28: =F21+F27 -> 4137006257713 | G28: =G21+G27 -> 4021105412384 | H28: =H21+H27 -> 4175928930765 | I28: =I21+I27 -> 4.100039e+12 | J28: =J21+J27 -> 4.0225322e+12 | ... M28: =M21+M27 -> 3.8013056e+12
A30: PB.CHECK | B30: Cek: aset - (liabilitas + ekuitas), harus 0 | C30: =ROUND(C15-C28,0) -> 0 | D30: =ROUND(D15-D28,0) -> 0 | E30: =ROUND(E15-E28,0) -> 0 | F30: =ROUND(F15-F28,0) -> 0 | G30: =ROUND(G15-G28,0) -> 0 | H30: =ROUND(H15-H28,0) -> 0 | I30: =ROUND(I15-I28,0) -> 0 | J30: =ROUND(J15-J28,0) -> 0 | ... M30: =ROUND(M15-M28,0) -> 0
A31: PB.NETDEBT | B31: Memo: utang neto (utang berbunga - kas) | C31: =C18+C19-C6 -> -409316952934 | D31: =D18+D19-D6 -> 301663340852 | E31: =E18+E19-E6 -> 423829263168 | F31: =F18+F19-F6 -> 428751244292 | G31: =G18+G19-G6 -> 495396935481 | H31: =H18+H19-H6 -> 663430934809 | I31: =I18+I19-I6 -> 7.5717424e+11 | J31: =J18+J19-J6 -> 8.5161819e+11 | ... M31: =M18+M19-M6 -> 1.1579853e+12
A32: PB.ROE | B32: Memo: ROE (laba induk / rata-rata ekuitas induk) | D32: =IS_Proj!D25/AVERAGE(C25,D25) -> 0.0018518641 | E32: =IS_Proj!E25/AVERAGE(D25,E25) -> -0.028768755 | F32: =IS_Proj!F25/AVERAGE(E25,F25) -> -0.03519918 | G32: =IS_Proj!G25/AVERAGE(F25,G25) -> -0.026273737 | H32: =IS_Proj!H25/AVERAGE(G25,H25) -> 0.001640296 | I32: =IS_Proj!I25/AVERAGE(H25,I25) -> -0.026433611 | J32: =IS_Proj!J25/AVERAGE(I25,J25) -> -0.026863104 | K32: =IS_Proj!K25/AVERAGE(J25,K25) -> -0.027199395 | ... M32: =IS_Proj!M25/AVERAGE(L25,M25) -> -0.027545259
A33: PB.ND_EBITDA | B33: Memo: utang neto / EBITDA | D33: =D31/IS_Proj!D15 -> 9.6085597 | E33: =E31/IS_Proj!E15 -> -11.238056 | F33: =F31/IS_Proj!F15 -> -29.459727 | G33: =G31/IS_Proj!G15 -> -112.28728 | H33: =H31/IS_Proj!H15 -> 6.8862123 | I33: =I31/IS_Proj!I15 -> 39.22306 | J33: =J31/IS_Proj!J15 -> 39.066654 | K33: =K31/IS_Proj!K15 -> 38.573983 | ... M33: =M31/IS_Proj!M15 -> 36.856737

Sheet CF_Proj
A1: Proyeksi arus kas (metode tidak langsung untuk tahun E)
