Workbook

Sheet Cover
B2: PT Cipta Sarana Medika Tbk (DKHH) - Model data fundamental 6 tahun & proyeksi ilustratif
B3: Historis FY2022-FY2025 (laporan keuangan konsolidasian audited) | proyeksi ilustratif FY2026-FY2030 | Format: PRO
B5: Penting - sifat dokumen
B6: Bukan rekomendasi | C6: Dokumen ini hanya ringkasan informasi dan analisis data fundamental yang bersumber dari laporan keuangan publik (audited) PT Cipta Sarana Medika Tbk. Dokumen ini BUKAN saran atau rekomendasi investasi, bukan ajakan membeli, menjual, atau menahan efek apa pun, dan tidak memuat target atau penilaian nilai wajar. Proyeksi bersifat ilustratif dan dapat berbeda jauh dari realisasi. Data dapat mengandung kesalahan ekstraksi; selalu cek ke laporan asli. Dokumen ini disusun dengan bantuan kecerdasan buatan (AI) dari laporan keuangan publik; kemungkinan kesalahan tetap ada, harap verifikasi ke sumber.
B7: Proyeksi | C7: Angka FY..E adalah proyeksi ILUSTRATIF berbasis asumsi transparan di sheet Asumsi (Base/Bull/Bear), dikalibrasi dari tren FY2022-2025. Tidak ada target, nilai wajar, atau kesimpulan nilai per saham.
B8: Sumber data | C8: Laporan keuangan konsolidasian audited PT Cipta Sarana Medika Tbk FY2025 (komparatif 2024; diunduh dari IDX; auditor KAP Jonnardi, Jamaludin, Sukimto & Rekan) dan Prospektus IPO 2025 (LK konsolidasian audited 2023 & 2022, auditor KAP Jamaludin, Ardi, Sukimto & Rekan; diunduh dari situs emiten karena salinan IDX ditolak/403). Tahun 2021 tidak disajikan (belum konsolidasi); laporan interim 10 bulan prospektus tidak dipakai. Lihat Data_Log & Temuan.
B10: Hak cipta & lisensi
B11: Hak cipta | C11: © 2026 Ryant Gabein Pasaribu. Kompilasi, struktur, metodologi, kode akun standar, dan analisis dalam file ini adalah ciptaan Ryant Gabein Pasaribu. Dilisensikan di bawah Creative Commons Atribusi 4.0 Internasional (CC BY 4.0): bebas digunakan dan dibagikan dengan wajib mencantumkan atribusi "Ryant Gabein Pasaribu" dan menyertakan tautan lisensi https://creativecommons.org/licenses/by/4.0/deed.id. Data laporan keuangan bersumber dari laporan publik emiten.
B12: Versi | C12: v1.0
B13: Tanggal terbit | C13: 2026-10-25
B14: ID file | C14: DKHH-FY2025-v1.0-36F09546
B16: Format
B17: Data terbuka | C17: Data dan model ini terbuka dan gratis untuk semua orang.
B18: Format output | C18: Tiga format (bukan tingkatan akses, semuanya gratis): Ritel (PDF ringkasan 4 halaman), Akademik (Excel data historis, rasio, rekonsiliasi), Pro (Excel model penuh dengan proyeksi ilustratif & template DCF kosong).
B20: Informasi model
B21: Emiten | C21: PT Cipta Sarana Medika Tbk dan Entitas Anak (kode DKHH) - pengelola rumah sakit tipe C "DKH Hospitals" (Kedungwaringin & Sukatani, Bekasi; Cibadak, Sukabumi)
B22: Satuan | C22: Rupiah penuh (Ringkasan/Dashboard: Rp miliar); beban & arus kas keluar negatif (kurung)
B23: Tahun historis | C23: FY2022, FY2023, FY2024, FY2025
B24: Status rekonsiliasi | C24: =Rekonsiliasi!$C$3 -> SEMUA 225 CEK SESUAI EKSPEKTASI
B25: Skenario aktif | C25: =Asumsi!C4 -> Base
B26: Dibangun | C26: 25-10-2026 oleh /workspace/emiten/common/build_model.py --ticker DKHH
B28: Daftar sheet
B29: Cover | C29: Sifat dokumen, lisensi, keterangan warna
B30: Panduan | C30: Cara memakai model ini
B31: Ringkasan | C31: Ringkasan siap cetak/PDF (A4): highlights, indikator utama, grafik, tanda perhatian
B32: Dashboard | C32: Indikator & grafik historis + proyeksi ilustratif
B33: Asumsi | C33: Selektor skenario Base/Bull/Bear & driver per tahun, dengan dasar kalibrasi FY2023-2025
B34: IS_Proj | C34: Proyeksi laba rugi (pendapatan per kelompok, EBITDA, laba)
B35: BS_Proj | C35: Proyeksi neraca agregat; kas = penyeimbang; cek balance
B36: CF_Proj | C36: Proyeksi arus kas tidak langsung; FCF
B37: Schedules_Proj | C37: Aset tetap, aset takberwujud, sewa, utang, modal kerja
B38: DCF_Template | C38: Kalkulator DCF opsional dengan input KOSONG (tanpa kesimpulan)
B39: Peer | C39: Tabel pembanding fundamental (input kosong, tanpa kelipatan pasar)
B40: IS | C40: Laba rugi & OCI FY2022-2025
... B48: Data_Log | C48: Sumber per tahun, pemetaan akun, override

Sheet Panduan
A1: Panduan pemakaian
A2: Format PRO (model penuh) - gratis & terbuka; bukan rekomendasi investasi
B4: Langkah
B5: 1. Mulai | C5: Baca Cover (sifat dokumen) lalu Ringkasan (siap cetak A4: File > Print/Export PDF untuk sheet Ringkasan).
B6: 2. Data historis | C6: IS, BS, CF berisi angka laporan (biru) dan subtotal rumus (hitam). Baris 3 menyebut sumber tiap kolom; kolom FY2022 berlatar oranye = kolom pertama, dari LK audited dalam prospektus IPO (Temuan D8).
B7: 3. Rincian & rasio | C7: Schedules memuat rincian catatan (CALK) FY2022-2025; bagian A merangkum angka yang dipakai Rasio. Rasio memakai rumus hidup dan kolom rata-rata FY2022-25.
B8: 4. Cek kualitas | C8: Rekonsiliasi: kolom "Sesuai ekspektasi?" harus ✔ untuk semua baris. ❌ yang diharapkan adalah selisih di laporan sumber dan dijelaskan di kolom Penjelasan / sheet Temuan.
B9: 5. Proyeksi ilustratif | C9: Pilih skenario di Asumsi!C4 (Base/Bull/Bear). Ubah sel biru di blok skenario untuk mencoba asumsi sendiri; IS_Proj, BS_Proj, CF_Proj ikut berubah. Cek BS_Proj baris "Cek" harus 0.
B10: 6. Template DCF (opsional) | C10: Isi sendiri sel kuning (Rf, ERP, beta, Kd, pajak, bobot utang, g / kelipatan). Tanpa input, template tidak menghitung apa pun. Hasil adalah keluaran rumus atas input Anda, bukan nilai wajar atau rekomendasi.
B11: 7. Peer | C11: Isi data fundamental pembanding dari laporan publik masing-masing emiten beserta sumbernya. Tidak ada angka pembanding yang dikarang di file ini.
B13: Keterangan warna
B14: Biru | C14: Input / angka dari laporan (bisa diubah)
B15: Hitam | C15: Rumus di sheet yang sama
B16: Hijau | C16: Rumus yang merujuk sheet lain
B17: Kuning | C17: Sel yang perlu diisi/diverifikasi pengguna atau angka yang dikoreksi (ada komentar sel)
B18: Oranye | C18: Kolom FY2022 (kolom pertama) dari LK audited dalam prospektus IPO
B19: Biru muda | C19: Kolom tahun proyeksi (E) - ilustratif
B21: Definisi penting
B22: EBITDA | C22: Laba usaha model (laba bruto - beban usaha + pendapatan lain-lain neto) + penyusutan aset tetap (Cat 26-27) + penyusutan aset hak guna (Cat 26).
B23: Utang | C23: Utang berbunga: utang bank jangka pendek & jangka panjang, pembiayaan konsumen, dan dana syirkah temporer (Temuan D2). Utang neto juga menambahkan liabilitas sewa dan mengurangi kas (negatif = kas neto).
B24: EPS | C24: EPS tercetak memakai saham rata-rata tertimbang (CALK; IPO 2025) dan dibulatkan ke Rupiah penuh 2024-2025 (Temuan D9).
B25: Satuan | C25: Rupiah penuh kecuali disebut (Ringkasan/Dashboard: Rp miliar). Beban & arus kas keluar bertanda negatif.
B27: Daftar sheet (format ini)
B28: Cover | C28: Sifat dokumen, lisensi, keterangan warna
B29: Panduan | C29: Cara memakai model ini
B30: Ringkasan | C30: Ringkasan siap cetak/PDF (A4): highlights, indikator utama, grafik, tanda perhatian
B31: Dashboard | C31: Indikator & grafik historis + proyeksi ilustratif
B32: Asumsi | C32: Selektor skenario Base/Bull/Bear & driver per tahun, dengan dasar kalibrasi FY2023-2025
B33: IS_Proj | C33: Proyeksi laba rugi (pendapatan per kelompok, EBITDA, laba)
B34: BS_Proj | C34: Proyeksi neraca agregat; kas = penyeimbang; cek balance
B35: CF_Proj | C35: Proyeksi arus kas tidak langsung; FCF
B36: Schedules_Proj | C36: Aset tetap, aset takberwujud, sewa, utang, modal kerja
B37: DCF_Template | C37: Kalkulator DCF opsional dengan input KOSONG (tanpa kesimpulan)
B38: Peer | C38: Tabel pembanding fundamental (input kosong, tanpa kelipatan pasar)
B39: IS | C39: Laba rugi & OCI FY2022-2025
... B47: Data_Log | C47: Sumber per tahun, pemetaan akun, override
B49: Batasan
B50: Data | C50: Angka diekstrak dari PDF dan dapat mengandung kesalahan; cek ke laporan asli sebelum dipakai.
B51: Proyeksi | C51: Asumsi sederhana: pos neraca lain konstan, utang & liabilitas sewa konstan (pembayaran sewa dikapitalisasi ke aset tetap), beban keuangan = suku bunga x rata-rata utang, aset hak guna konstan, tanpa OCI/revaluasi/penurunan nilai baru, tanpa penghasilan bunga pihak berelasi, tanpa transaksi saham, akuisisi atau pendanaan baru. Hasil sangat sensitif terhadap asumsi.
B52: Bukan saran | C52: Dokumen ini hanya ringkasan informasi dan analisis data fundamental yang bersumber dari laporan keuangan publik (audited) PT Cipta Sarana Medika Tbk. Dokumen ini BUKAN saran atau rekomendasi investasi, bukan ajakan membeli, menjual, atau menahan efek apa pun, dan tidak memuat target atau penilaian nilai wajar. Proyeksi bersifat ilustratif dan dapat berbeda jauh dari realisasi. Data dapat mengandung kesalahan ekstraksi; selalu cek ke laporan asli. Dokumen ini disusun dengan bantuan kecerdasan buatan (AI) dari laporan keuangan publik; kemungkinan kesalahan tetap ada, harap verifikasi ke sumber.

Sheet Ringkasan
B1: Cipta Sarana Medika (DKHH) | Ringkasan FY2022-FY2025
B2: DKH Hospitals - 3 rumah sakit tipe C di Bekasi & Sukabumi | sumber: LK audited FY2025 & prospektus IPO 2025 | gratis & terbuka | BUKAN rekomendasi investasi
B4: Penting: Dokumen ini hanya ringkasan informasi dan analisis data fundamental yang bersumber dari laporan keuangan publik (audited) PT Cipta Sarana Medika Tbk. Dokumen ini BUKAN saran atau rekomendasi investasi, bukan ajakan membeli, menjual, atau menahan efek apa pun, dan tidak memuat target atau penilaian nilai wajar. Proyeksi bersifat ilustratif dan dapat berbeda jauh dari realisasi. Data dapat mengandung kesalahan ekstraksi; selalu cek ke laporan asli. Dokumen ini disusun dengan bantuan kecerdasan buatan (AI) dari laporan keuangan publik; kemungkinan kesalahan tetap ada, harap verifikasi ke sumber.
B6: Ringkasan Eksekutif / Highlights
B7: • Pendapatan FY2025 Rp144,9 miliar (-4,8% vs FY2024): penunjang medis Rp30,6 miliar, rawat inap Rp74,1 miliar, rawat jalan Rp40,0 miliar, lainnya Rp0,2 miliar.
B8: • Pendapatan tumbuh 13,3% per tahun FY2022-2025 (naik 2023-2024, turun 2025); IPO 2025 dan pelaksanaan waran menghimpun Rp69,2 miliar.
B9: • Laba pemilik induk FY2025 Rp6,0 miliar (EPS tercetak Rp3) vs Rp2,8 miliar FY2024; margin laba bersih 4,2%. Laba 2025 ditopang penghasilan bunga dari pihak berelasi Rp13,2 miliar; laba sebelum pajak 2024 hampir nol.
B10: • Utang berbunga Rp90 miliar (termasuk dana syirkah Rp69 miliar) vs kas Rp4,0 miliar (FY2025); piutang pihak berelasi tidak lancar Rp117 miliar; utang neto / EBITDA 5,7x.
B11: • Data 4 tahun direkonsiliasi dengan 225 cek; 11 selisih di laporan sumber sudah diperkirakan dan dijelaskan (lihat tanda perhatian & sheet Temuan).
B13: Indikator utama (Rp miliar, kecuali disebut lain) - rumus hidup dari sheet IS/BS/CF/Rasio
B14: Indikator | C14: FY2022A | D14: FY2023A | E14: FY2024A | F14: FY2025A
B15: Pendapatan | C15: =IS!C6/1000000000 -> 99.578144 | D15: =IS!D6/1000000000 -> 134.18768 | E15: =IS!E6/1000000000 -> 152.14225 | F15: =IS!F6/1000000000 -> 144.87327
B16: Pertumbuhan | D16: =Rasio!D6 -> 0.34756155 | E16: =Rasio!E6 -> 0.13380193 | F16: =Rasio!F6 -> -0.047777527
B17: Porsi penunjang medis | C17: =Rasio!C26 -> 0.025457106 | D17: =Rasio!D26 -> 0.08856077 | E17: =Rasio!E26 -> 0.30323344 | F17: =Rasio!F26 -> 0.21122146
B18: EBITDA | C18: =Rasio!C16/1000000000 -> 15.15056 | D18: =Rasio!D16/1000000000 -> 17.504402 | E18: =Rasio!E16/1000000000 -> 21.381139 | F18: =Rasio!F16/1000000000 -> 15.3438
B19: Margin EBITDA | C19: =Rasio!C17 -> 0.15214744 | D19: =Rasio!D17 -> 0.13044716 | E19: =Rasio!E17 -> 0.14053387 | F19: =Rasio!F17 -> 0.10591188
B20: Laba tahun berjalan | C20: =IS!C20/1000000000 -> 4.8881658 | D20: =IS!D20/1000000000 -> 3.5397164 | E20: =IS!E20/1000000000 -> 2.8373633 | F20: =IS!F20/1000000000 -> 6.0218975
B21: Laba pemilik entitas induk | C21: =IS!C29/1000000000 -> 4.8881658 | D21: =IS!D29/1000000000 -> 3.5397164 | E21: =IS!E29/1000000000 -> 2.8372318 | F21: =IS!F29/1000000000 -> 6.0216481
B22: Porsi laba ke NCI | C22: =Rasio!C23 -> 0 | D22: =Rasio!D23 -> 0 | E22: =Rasio!E23 -> 4.6327871e-05 | F22: =Rasio!F23 -> 4.1416181e-05
B23: ROE (rata-rata ekuitas induk) | D23: =Rasio!D20 -> 0.039282225 | E23: =Rasio!E20 -> 0.02191938 | F23: =Rasio!F20 -> 0.035818841
B24: Arus kas operasi | C24: =CF!C14/1000000000 -> 7.7341001 | D24: =CF!D14/1000000000 -> 19.735705 | E24: =CF!E14/1000000000 -> 2.9976875 | F24: =CF!F14/1000000000 -> 5.5679514
B25: Capex | C25: =Rasio!C41/1000000000 -> 16.981554 | D25: =Rasio!D41/1000000000 -> 36.146492 | E25: =Rasio!E41/1000000000 -> 24.447662 | F25: =Rasio!F41/1000000000 -> 27.390828
B26: Utang neto (utang + sewa - kas) | C26: =Rasio!C36/1000000000 -> 64.124135 | D26: =Rasio!D36/1000000000 -> 142.65161 | E26: =Rasio!E36/1000000000 -> 111.51054 | F26: =Rasio!F36/1000000000 -> 87.265075
B27: Utang neto / EBITDA (x) | C27: =Rasio!C38 -> 4.2324598 | D27: =Rasio!D38 -> 8.1494706 | E27: =Rasio!E38 -> 5.2153695 | F27: =Rasio!F38 -> 5.6873182
B28: DSO piutang (hari) | C28: =Rasio!C28 -> 44.41957 | D28: =Rasio!D28 -> 45.652804 | E28: =Rasio!E28 -> 60.158756 | F28: =Rasio!F28 -> 47.54806
B29: Tarif pajak efektif | C29: =Rasio!C22 -> 0.25801251 | D29: =Rasio!D22 -> 0.76735139 | E29: =Rasio!E22 -> 6.9116652 | F29: =Rasio!F22 -> -0.058527227
B30: Catatan: kolom FY2022-FY2023 dari LK audited dalam prospektus IPO (proforma restrukturisasi); FY2024 dari komparatif LK FY2025. Laba usaha model = laba usaha tercetak + pendapatan lain-lain neto. EBITDA = laba usaha model + penyusutan aset tetap + penyusutan aset hak guna. Utang = bank + pembiayaan konsumen + dana syirkah temporer.
B32: Tren 4 tahun
B50: Batang = pendapatan per kelompok (Cat 25; lainnya = administrasi & lainnya); garis putus-putus = porsi penunjang medis terhadap pendapatan (sumbu kanan).
B68: Kiri: margin terhadap pendapatan. Kanan: arus kas operasi (abu-abu), capex (arsir), pembayaran sewa (titik), dan sisanya (garis).
B86: Tanda perhatian dari laporan keuangan (bahasa sederhana)
B87: 1. Pihak berelasi - Piutang ke pihak berelasi besar (2025 sekitar sepertiga aset) dan penghasilan bunga 2025 berasal dari pinjaman ke pihak berelasi yang sebagian belum diterima kas. (Temuan D3)
B88: 2. Utang & syirkah - Pembiayaan bank syariah (dana syirkah temporer) diperlakukan sebagai utang; kas akhir tahun kecil dibanding utang. (Temuan D2)
B89: 3. Laba tipis & pajak - Laba sebelum pajak 2024 hampir nol dan 2025 bergantung pada bunga pihak berelasi; tarif pajak efektif ekstrem. (Temuan D3, D11)
B90: 4. Proforma & sumber - Data 2022-2024 memuat laba/ekuitas proforma restrukturisasi; 2022-2023 dari prospektus; LAK prospektus tidak sama dengan kas neraca. (Temuan D1, D6, D8)
B91: 5. Pos tidak berulang - Revaluasi aset 2023, uang muka aset tetap 2025 dan bunga neto positif di arus kas operasi 2025. (Temuan D4, D5, D7)
B92: 6. Proyeksi ilustratif - Skenario Base/Bull/Bear bukan perkiraan; tidak ada target harga atau nilai wajar.
B93: Detail lengkap ada di sheet Temuan dan Rekonsiliasi. Tanda perhatian bukan tuduhan kecurangan; ini daftar hal yang perlu dicek ulang ke laporan asli.
... B103: Dokumen ini hanya ringkasan informasi dan analisis data fundamental yang bersumber dari laporan keuangan publik (audited) PT Cipta Sarana Medika Tbk. Dokumen ini BUKAN saran atau rekomendasi investasi, bukan ajakan membeli, menjual, atau menahan efek apa pun, dan tidak memuat target atau penilaian nilai wajar. Proyeksi bersifat ilustratif dan dapat berbeda jauh dari realisasi. Data dapat mengandung kesalahan ekstraksi; selalu cek ke laporan asli. Dokumen ini disusun dengan bantuan kecerdasan buatan (AI) dari laporan keuangan publik; kemungkinan kesalahan tetap ada, harap verifikasi ke sumber. Penyusun tidak bertanggung jawab atas keputusan apa pun yang diambil berdasarkan dokumen ini. Dokumen ini disusun pada 25-10-2026.

Sheet Dashboard
A1: Dashboard - historis FY2022-FY2025 & proyeksi ilustratif FY2026-FY2030 (skenario aktif)
A2: Rp miliar. Kolom E = Proyeksi ILUSTRATIF berbasis asumsi transparan - bukan rekomendasi investasi, bukan target, bukan nilai wajar. Tidak ada nilai per saham/target di sheet ini.
B3: Skenario aktif: | C3: =Asumsi!C4 -> Base
B4: Indikator | C4: FY2022A | D4: FY2023A | E4: FY2024A | F4: FY2025A | G4: FY2026E | H4: FY2027E | I4: FY2028E | J4: FY2029E | K4: FY2030E | L4: Catatan
B5: Pendapatan neto | C5: =IS_Proj!C10/1000000000 -> 99.578144 | D5: =IS_Proj!D10/1000000000 -> 134.18768 | E5: =IS_Proj!E10/1000000000 -> 152.14225 | F5: =IS_Proj!F10/1000000000 -> 144.87327 | G5: =IS_Proj!G10/1000000000 -> 156.40596 | H5: =IS_Proj!H10/1000000000 -> 168.91843 | I5: =IS_Proj!I10/1000000000 -> 182.43191 | J5: =IS_Proj!J10/1000000000 -> 197.02646 | K5: =IS_Proj!K10/1000000000 -> 212.78858
B6: Pertumbuhan pendapatan | D6: =IS_Proj!D11 -> 0.34756155 | E6: =IS_Proj!E11 -> 0.13380193 | F6: =IS_Proj!F11 -> -0.047777527 | G6: =IS_Proj!G11 -> 0.079605361 | H6: =IS_Proj!H11 -> 0.08 | I6: =IS_Proj!I11 -> 0.08 | J6: =IS_Proj!J11 -> 0.08 | K6: =IS_Proj!K11 -> 0.08
B7: EBITDA | C7: =IS_Proj!C17/1000000000 -> 15.15056 | D7: =IS_Proj!D17/1000000000 -> 17.504402 | E7: =IS_Proj!E17/1000000000 -> 21.381139 | F7: =IS_Proj!F17/1000000000 -> 15.3438 | G7: =IS_Proj!G17/1000000000 -> 20.645586 | H7: =IS_Proj!H17/1000000000 -> 22.297233 | I7: =IS_Proj!I17/1000000000 -> 24.081012 | J7: =IS_Proj!J17/1000000000 -> 26.007493 | K7: =IS_Proj!K17/1000000000 -> 28.088092
B8: Margin EBITDA | C8: =IS_Proj!C31 -> 0.15214744 | D8: =IS_Proj!D31 -> 0.13044716 | E8: =IS_Proj!E31 -> 0.14053387 | F8: =IS_Proj!F31 -> 0.10591188 | G8: =IS_Proj!G31 -> 0.132 | H8: =IS_Proj!H31 -> 0.132 | I8: =IS_Proj!I31 -> 0.132 | J8: =IS_Proj!J31 -> 0.132 | K8: =IS_Proj!K31 -> 0.132
B9: Laba tahun berjalan | C9: =IS_Proj!C25/1000000000 -> 4.8881658 | D9: =IS_Proj!D25/1000000000 -> 3.5397164 | E9: =IS_Proj!E25/1000000000 -> 2.8373633 | F9: =IS_Proj!F25/1000000000 -> 6.0218975 | G9: =IS_Proj!G25/1000000000 -> 0.31465181 | H9: =IS_Proj!H25/1000000000 -> 1.4042458 | I9: =IS_Proj!I25/1000000000 -> 2.5213667 | J9: =IS_Proj!J25/1000000000 -> 3.6740851 | K9: =IS_Proj!K25/1000000000 -> 4.8705401
B10: Laba pemilik entitas induk | C10: =IS_Proj!C27/1000000000 -> 4.8881658 | D10: =IS_Proj!D27/1000000000 -> 3.5397164 | E10: =IS_Proj!E27/1000000000 -> 2.8372318 | F10: =IS_Proj!F27/1000000000 -> 6.0216481 | G10: =IS_Proj!G27/1000000000 -> 0.31465181 | H10: =IS_Proj!H27/1000000000 -> 1.4042458 | I10: =IS_Proj!I27/1000000000 -> 2.5213667 | J10: =IS_Proj!J27/1000000000 -> 3.6740851 | K10: =IS_Proj!K27/1000000000 -> 4.8705401
B11: Arus kas operasi | C11: =CF_Proj!C11/1000000000 -> 7.7341001 | D11: =CF_Proj!D11/1000000000 -> 19.735705 | E11: =CF_Proj!E11/1000000000 -> 2.9976875 | F11: =CF_Proj!F11/1000000000 -> 5.5679514 | G11: =CF_Proj!G11/1000000000 -> 8.5522395 | H11: =CF_Proj!H11/1000000000 -> 12.752114 | I11: =CF_Proj!I11/1000000000 -> 14.048445 | J11: =CF_Proj!J11/1000000000 -> 15.466407 | K11: =CF_Proj!K11/1000000000 -> 17.013966
B12: Capex | C12: =CF_Proj!C13/1000000000 -> -16.981554 | D12: =CF_Proj!D13/1000000000 -> -36.146492 | E12: =CF_Proj!E13/1000000000 -> -24.447662 | F12: =CF_Proj!F13/1000000000 -> -27.390828 | G12: =CF_Proj!G13/1000000000 -> -14.076536 | H12: =CF_Proj!H13/1000000000 -> -15.202659 | I12: =CF_Proj!I13/1000000000 -> -16.418872 | J12: =CF_Proj!J13/1000000000 -> -17.732382 | K12: =CF_Proj!K13/1000000000 -> -19.150972
B13: FCF setelah sewa | C13: =CF_Proj!C27/1000000000 -> -9.410982 | D13: =CF_Proj!D27/1000000000 -> -16.410787 | E13: =CF_Proj!E27/1000000000 -> -21.955612 | F13: =CF_Proj!F27/1000000000 -> -22.821714 | G13: =CF_Proj!G27/1000000000 -> -6.0560769 | H13: =CF_Proj!H27/1000000000 -> -3.024868 | I13: =CF_Proj!I27/1000000000 -> -2.9906952 | J13: =CF_Proj!J27/1000000000 -> -2.9358644 | K13: =CF_Proj!K27/1000000000 -> -2.860487
B14: Kas akhir | C14: =BS_Proj!C6/1000000000 -> 29.547207 | D14: =BS_Proj!D6/1000000000 -> 2.4639738 | E14: =BS_Proj!E6/1000000000 -> 2.6633883 | F14: =BS_Proj!F6/1000000000 -> 4.036507 | G14: =BS_Proj!G6/1000000000 -> -2.0195699 | H14: =BS_Proj!H6/1000000000 -> -5.0444379 | I14: =BS_Proj!I6/1000000000 -> -8.0351331 | J14: =BS_Proj!J6/1000000000 -> -10.970998 | K14: =BS_Proj!K6/1000000000 -> -13.831484
B15: Utang neto (utang + sewa - kas) | C15: =BS_Proj!C31/1000000000 -> 64.124135 | D15: =BS_Proj!D31/1000000000 -> 142.65161 | E15: =BS_Proj!E31/1000000000 -> 111.51054 | F15: =BS_Proj!F31/1000000000 -> 87.265075 | G15: =BS_Proj!G31/1000000000 -> 93.321152 | H15: =BS_Proj!H31/1000000000 -> 96.34602 | I15: =BS_Proj!I31/1000000000 -> 99.336715 | J15: =BS_Proj!J31/1000000000 -> 102.27258 | K15: =BS_Proj!K31/1000000000 -> 105.13307
B16: Utang neto / EBITDA | C16: =BS_Proj!C33 -> 4.2324598 | D16: =BS_Proj!D33 -> 8.1494706 | E16: =BS_Proj!E33 -> 5.2153695 | F16: =BS_Proj!F33 -> 5.6873182 | G16: =BS_Proj!G33 -> 4.5201502 | H16: =BS_Proj!H33 -> 4.3209854 | I16: =BS_Proj!I33 -> 4.1251055 | J16: =BS_Proj!J33 -> 3.9324275 | K16: =BS_Proj!K33 -> 3.7429764
B17: ROE | D17: =BS_Proj!D32 -> 0.039282225 | E17: =BS_Proj!E32 -> 0.02191938 | F17: =BS_Proj!F32 -> 0.035818841 | G17: =BS_Proj!G32 -> 0.0015225618 | H17: =BS_Proj!H32 -> 0.006766833 | I17: =BS_Proj!I32 -> 0.012036213 | J17: =BS_Proj!J32 -> 0.017283351 | K17: =BS_Proj!K32 -> 0.022460229
B18: Cek balance BS_Proj (harus 0) | C18: =BS_Proj!C30 -> 0 | D18: =BS_Proj!D30 -> 0 | E18: =BS_Proj!E30 -> 0 | F18: =BS_Proj!F30 -> 0 | G18: =BS_Proj!G30 -> 0 | H18: =BS_Proj!H30 -> 0 | I18: =BS_Proj!I30 -> 0 | J18: =BS_Proj!J30 -> 0 | K18: =BS_Proj!K30 -> 0
B19: Status rekonsiliasi | C19: =Rekonsiliasi!$C$3 -> SEMUA 225 CEK SESUAI EKSPEKTASI

Sheet Asumsi
A1: Asumsi proyeksi ilustratif FY2026E-FY2030E (Base / Bull / Bear)
A2: Proyeksi ILUSTRATIF berbasis asumsi transparan - bukan rekomendasi investasi, bukan target, bukan nilai wajar.
A4: Skenario aktif | C4: Base | D4: =IF(C4="Bull",2,IF(C4="Bear",3,1)) -> 1 | E4: <- pilih Base / Bull / Bear. Kolom historis = aktual (rumus dari IS/BS/CF/Schedules); kolom E = asumsi skenario aktif.
A5: Kalibrasi | C5: Asumsi dikalibrasi dari FY2022-FY2025 (2022-2023 proforma restrukturisasi; 2025 tahun IPO). Pos tidak berulang (bunga pihak berelasi 2025, uang muka aset 2025, revaluasi 2023) tidak dipakai sebagai patokan.
A7: Kunci | B7: Driver | C7: FY2022A | D7: FY2023A | E7: FY2024A | F7: FY2025A | G7: FY2026E | H7: FY2027E | I7: FY2028E | J7: FY2029E | K7: FY2030E | L7: Dasar asumsi (kalibrasi FY2022-FY2025)
B8: ASUMSI AKTIF - kolom historis = aktual (rumus), kolom E = skenario terpilih
B9: PENDAPATAN (per kelompok, Cat 25)
A10: g_med | B10: Pertumbuhan pendapatan penunjang medis (farmasi, laboratorium, radiologi) | D10: =IFERROR(Schedules!D6/Schedules!C6-1,"") -> 3.6879283 | E10: =IFERROR(Schedules!E6/Schedules!D6-1,"") -> 2.8821553 | F10: =IFERROR(Schedules!F6/Schedules!E6-1,"") -> -0.33671624 | G10: =CHOOSE(Asumsi!$D$4,G38,G65,G92) -> 0.08 | H10: =CHOOSE(Asumsi!$D$4,H38,H65,H92) -> 0.08 | I10: =CHOOSE(Asumsi!$D$4,I38,I65,I92) -> 0.08 | J10: =CHOOSE(Asumsi!$D$4,J38,J65,J92) -> 0.08 | K10: =CHOOSE(Asumsi!$D$4,K38,K65,K92) -> 0.08 | L10: Pendapatan: 2022 3 M, 2023 12 M, 2024 46 M, 2025 31 M. CAGR 2022-25 129,4%; 2025 turun. Base 8%; Bull 12%; Bear 3% (3 RS tipe C, pasien BPJS dominan; tanpa RS baru).
A11: g_inpat | B11: Pertumbuhan pendapatan rawat inap | D11: =IFERROR(Schedules!D7/Schedules!C7-1,"") -> 0.48651982 | E11: =IFERROR(Schedules!E7/Schedules!D7-1,"") -> 0.079676764 | F11: =IFERROR(Schedules!F7/Schedules!E7-1,"") -> -0.13733116 | G11: =CHOOSE(Asumsi!$D$4,G39,G66,G93) -> 0.08 | H11: =CHOOSE(Asumsi!$D$4,H39,H66,H93) -> 0.08 | I11: =CHOOSE(Asumsi!$D$4,I39,I66,I93) -> 0.08 | J11: =CHOOSE(Asumsi!$D$4,J39,J66,J93) -> 0.08 | K11: =CHOOSE(Asumsi!$D$4,K39,K66,K93) -> 0.08 | L11: Pendapatan: 2022 54 M, 2023 80 M, 2024 86 M, 2025 74 M. CAGR 2022-25 11,5%. Base 8%; Bull 12%; Bear 3%.
A12: g_outpat | B12: Pertumbuhan pendapatan rawat jalan | D12: =IFERROR(Schedules!D8/Schedules!C8-1,"") -> -0.015719298 | E12: =IFERROR(Schedules!E8/Schedules!D8-1,"") -> -0.53269619 | F12: =IFERROR(Schedules!F8/Schedules!E8-1,"") -> 1.0053615 | G12: =CHOOSE(Asumsi!$D$4,G40,G67,G94) -> 0.08 | H12: =CHOOSE(Asumsi!$D$4,H40,H67,H94) -> 0.08 | I12: =CHOOSE(Asumsi!$D$4,I40,I67,I94) -> 0.08 | J12: =CHOOSE(Asumsi!$D$4,J40,J67,J94) -> 0.08 | K12: =CHOOSE(Asumsi!$D$4,K40,K67,K94) -> 0.08 | L12: Pendapatan: 2022 43 M, 2023 43 M, 2024 20 M, 2025 40 M. CAGR 2022-25 -2,7% (kategori berbeda antar sumber, Temuan D10). Base 8%; Bull 12%; Bear 3%.
A13: rev_oth | B13: Pendapatan lainnya (% 3 kelompok utama) | C13: =IFERROR(Schedules!C9/(Schedules!C6+Schedules!C7+Schedules!C8),"") -> 0.001775748 | D13: =IFERROR(Schedules!D9/(Schedules!D6+Schedules!D7+Schedules!D8),"") -> 0.00054476377 | E13: =IFERROR(Schedules!E9/(Schedules!E6+Schedules!E7+Schedules!E8),"") -> 0.001029331 | F13: =IFERROR(Schedules!F9/(Schedules!F6+Schedules!F7+Schedules!F8),"") -> 0.0012658688 | G13: =CHOOSE(Asumsi!$D$4,G41,G68,G95) -> 0.0009 | H13: =CHOOSE(Asumsi!$D$4,H41,H68,H95) -> 0.0009 | I13: =CHOOSE(Asumsi!$D$4,I41,I68,I95) -> 0.0009 | J13: =CHOOSE(Asumsi!$D$4,J41,J68,J95) -> 0.0009 | K13: =CHOOSE(Asumsi!$D$4,K41,K68,K95) -> 0.0009 | L13: Historis: 2022 0,2%, 2023 0,1%, 2024 0,1%, 2025 0,1%. Base/Bull/Bear = rata-rata 2023-25.
B14: MARGIN & BIAYA (% pendapatan)
A15: cogs | B15: Beban pokok di luar penyusutan aset tetap & aset hak guna | C15: =IFERROR(-(IS!C7+Schedules!C12+Schedules!C16+Schedules!C17)/IS!C6,"") -> 0.64108649 | D15: =IFERROR(-(IS!D7+Schedules!D12+Schedules!D16+Schedules!D17)/IS!D6,"") -> 0.6348373 | E15: =IFERROR(-(IS!E7+Schedules!E12+Schedules!E16+Schedules!E17)/IS!E6,"") -> 0.65153367 | F15: =IFERROR(-(IS!F7+Schedules!F12+Schedules!F16+Schedules!F17)/IS!F6,"") -> 0.69165664 | G15: =CHOOSE(Asumsi!$D$4,G43,G70,G97) -> 0.67 | H15: =CHOOSE(Asumsi!$D$4,H43,H70,H97) -> 0.67 | I15: =CHOOSE(Asumsi!$D$4,I43,I70,I97) -> 0.67 | J15: =CHOOSE(Asumsi!$D$4,J43,J70,J97) -> 0.67 | K15: =CHOOSE(Asumsi!$D$4,K43,K70,K97) -> 0.67 | L15: Historis: 2022 64,1%, 2023 63,5%, 2024 65,2%, 2025 69,2% (naik 2025). Base 67%; Bull 65%; Bear 69%.
A16: opex | B16: Beban penjualan + umum & administrasi di luar penyusutan | C16: =IFERROR(-(IS!C11+Schedules!C13+Schedules!C18)/IS!C6,"") -> 0.21908196 | D16: =IFERROR(-(IS!D11+Schedules!D13+Schedules!D18)/IS!D6,"") -> 0.23527689 | E16: =IFERROR(-(IS!E11+Schedules!E13+Schedules!E18)/IS!E6,"") -> 0.20999604 | F16: =IFERROR(-(IS!F11+Schedules!F13+Schedules!F18)/IS!F6,"") -> 0.19752974 | G16: =CHOOSE(Asumsi!$D$4,G44,G71,G98) -> 0.2 | H16: =CHOOSE(Asumsi!$D$4,H44,H71,H98) -> 0.2 | I16: =CHOOSE(Asumsi!$D$4,I44,I71,I98) -> 0.2 | J16: =CHOOSE(Asumsi!$D$4,J44,J71,J98) -> 0.2 | K16: =CHOOSE(Asumsi!$D$4,K44,K71,K98) -> 0.2 | L16: Historis: 2022 21,9%, 2023 23,5%, 2024 21,0%, 2025 19,8%. Base 20%; Bull 19%; Bear 21,5%.
A17: other_op | B17: Pendapatan (beban) lain-lain neto (% pendapatan) | C17: =IFERROR(IS!C13/IS!C6,"") -> 0.012315884 | D17: =IFERROR(IS!D13/IS!D6,"") -> 0.00056135103 | E17: =IFERROR(IS!E13/IS!E6,"") -> 0.0020635766 | F17: =IFERROR(IS!F13/IS!F6,"") -> -0.004901745 | G17: =CHOOSE(Asumsi!$D$4,G45,G72,G99) -> 0.002 | H17: =CHOOSE(Asumsi!$D$4,H45,H72,H99) -> 0.002 | I17: =CHOOSE(Asumsi!$D$4,I45,I72,I99) -> 0.002 | J17: =CHOOSE(Asumsi!$D$4,J45,J72,J99) -> 0.002 | K17: =CHOOSE(Asumsi!$D$4,K45,K72,K99) -> 0.002 | L17: Historis: 2022 1,2%, 2023 0,1%, 2024 0,2%, 2025 -0,5% (sewa & lain-lain; 2025 negatif). Base 0,2%; Bull 0,3%; Bear 0%.
B18: INVESTASI & ASET
A19: capex | B19: Capex aset tetap (% pendapatan) | C19: =IFERROR(-(CF!C16+CF!C17)/IS!C6,"") -> 0.17053495 | D19: =IFERROR(-(CF!D16+CF!D17)/IS!D6,"") -> 0.26937266 | E19: =IFERROR(-(CF!E16+CF!E17)/IS!E6,"") -> 0.1606895 | F19: =IFERROR(-(CF!F16+CF!F17)/IS!F6,"") -> 0.18906751 | G19: =CHOOSE(Asumsi!$D$4,G47,G74,G101) -> 0.09 | H19: =CHOOSE(Asumsi!$D$4,H47,H74,H101) -> 0.09 | I19: =CHOOSE(Asumsi!$D$4,I47,I74,I101) -> 0.09 | J19: =CHOOSE(Asumsi!$D$4,J47,J74,J101) -> 0.09 | K19: =CHOOSE(Asumsi!$D$4,K47,K74,K101) -> 0.09 | L19: Historis kas: 2022 17,1%, 2023 26,9%, 2024 16,1%, 2025 18,9% (2023 pembangunan RS; 2025 termasuk uang muka aset tetap 23,5 M, Temuan D4). Base 9% (kira-kira setara penyusutan, tanpa RS baru); Bull 7%; Bear 12%.
A20: lease_pd | B20: Pembayaran sewa dikapitalisasi ke aset tetap (% pendapatan) | C20: =IFERROR(-CF!C40/IS!C6,"") -> 0.0016422116 | D20: =IFERROR(-CF!D40/IS!D6,"") -> 0 | E20: =IFERROR(-CF!E40/IS!E6,"") -> 0.0033234514 | F20: =IFERROR(-CF!F40/IS!F6,"") -> 0.0068945572 | G20: =CHOOSE(Asumsi!$D$4,G48,G75,G102) -> 0.0034 | H20: =CHOOSE(Asumsi!$D$4,H48,H75,H102) -> 0.0034 | I20: =CHOOSE(Asumsi!$D$4,I48,I75,I102) -> 0.0034 | J20: =CHOOSE(Asumsi!$D$4,J48,J75,J102) -> 0.0034 | K20: =CHOOSE(Asumsi!$D$4,K48,K75,K102) -> 0.0034 | L20: Historis: 2022 0,2%, 2023 0,0%, 2024 0,3%, 2025 0,7% (kecil). Base/Bull/Bear = rata-rata 2023-25; liabilitas sewa & aset hak guna konstan.
A21: dep | B21: Penyusutan aset tetap + aset hak guna (% aset tetap neto awal) | D21: =IFERROR((Schedules!D14+Schedules!D16)/BS!C21,"") -> 0.11704763 | E21: =IFERROR((Schedules!E14+Schedules!E16)/BS!D21,"") -> 0.083087474 | F21: =IFERROR((Schedules!F14+Schedules!F16)/BS!E21,"") -> 0.095201334 | G21: =CHOOSE(Asumsi!$D$4,G49,G76,G103) -> 0.0984 | H21: =CHOOSE(Asumsi!$D$4,H49,H76,H103) -> 0.0984 | I21: =CHOOSE(Asumsi!$D$4,I49,I76,I103) -> 0.0984 | J21: =CHOOSE(Asumsi!$D$4,J49,J76,J103) -> 0.0984 | K21: =CHOOSE(Asumsi!$D$4,K49,K76,K103) -> 0.0984 | L21: Historis: 2023 11,7%, 2024 8,3%, 2025 9,5%. Base/Bull/Bear = rata-rata 2023-25.
A22: sw | B22: Amortisasi aset takberwujud (% saldo awal) | D22: =IFERROR(Schedules!D19/BS!C17,"") | E22: =IFERROR(Schedules!E19/BS!D17,"") | F22: =IFERROR(Schedules!F19/BS!E17,"") | G22: =CHOOSE(Asumsi!$D$4,G50,G77,G104) -> 0 | H22: =CHOOSE(Asumsi!$D$4,H50,H77,H104) -> 0 | I22: =CHOOSE(Asumsi!$D$4,I50,I77,I104) -> 0 | J22: =CHOOSE(Asumsi!$D$4,J50,J77,J104) -> 0 | K22: =CHOOSE(Asumsi!$D$4,K50,K77,K104) -> 0 | L22: DKHH tidak memiliki aset takberwujud. Semua skenario 0.
B23: MODAL KERJA (hari, saldo akhir, basis 365)
A24: dso | B24: DSO piutang usaha / pendapatan | C24: =IFERROR((BS!C8+BS!C9)/IS!C6*365,"") -> 44.41957 | D24: =IFERROR((BS!D8+BS!D9)/IS!D6*365,"") -> 45.652804 | E24: =IFERROR((BS!E8+BS!E9)/IS!E6*365,"") -> 60.158756 | F24: =IFERROR((BS!F8+BS!F9)/IS!F6*365,"") -> 47.54806 | G24: =CHOOSE(Asumsi!$D$4,G52,G79,G106) -> 50 | H24: =CHOOSE(Asumsi!$D$4,H52,H79,H106) -> 50 | I24: =CHOOSE(Asumsi!$D$4,I52,I79,I106) -> 50 | J24: =CHOOSE(Asumsi!$D$4,J52,J79,J106) -> 50 | K24: =CHOOSE(Asumsi!$D$4,K52,K79,K106) -> 50 | L24: Historis: 2022 44,4, 2023 45,7, 2024 60,2, 2025 47,5 (piutang BPJS). Base 50; Bull 45; Bear 60.
A25: dio | B25: DIO persediaan / beban pokok di luar penyusutan | C25: =IFERROR(BS!C12/-(IS!C7+Schedules!C12+Schedules!C16+Schedules!C17)*365,"") -> 12.949688 | D25: =IFERROR(BS!D12/-(IS!D7+Schedules!D12+Schedules!D16+Schedules!D17)*365,"") -> 17.293084 | E25: =IFERROR(BS!E12/-(IS!E7+Schedules!E12+Schedules!E16+Schedules!E17)*365,"") -> 15.228132 | F25: =IFERROR(BS!F12/-(IS!F7+Schedules!F12+Schedules!F16+Schedules!F17)*365,"") -> 4.8674244 | G25: =CHOOSE(Asumsi!$D$4,G53,G80,G107) -> 10 | H25: =CHOOSE(Asumsi!$D$4,H53,H80,H107) -> 10 | I25: =CHOOSE(Asumsi!$D$4,I53,I80,I107) -> 10 | J25: =CHOOSE(Asumsi!$D$4,J53,J80,J107) -> 10 | K25: =CHOOSE(Asumsi!$D$4,K53,K80,K107) -> 10 | L25: Historis: 2022 12,9, 2023 17,3, 2024 15,2, 2025 4,9 (2025 turun tajam). Base 10; Bull 8; Bear 14.
A26: dpo | B26: DPO utang usaha / beban pokok di luar penyusutan | C26: =IFERROR((BS!C30+BS!C31)/-(IS!C7+Schedules!C12+Schedules!C16+Schedules!C17)*365,"") -> 11.77416 | D26: =IFERROR((BS!D30+BS!D31)/-(IS!D7+Schedules!D12+Schedules!D16+Schedules!D17)*365,"") -> 20.448875 | E26: =IFERROR((BS!E30+BS!E31)/-(IS!E7+Schedules!E12+Schedules!E16+Schedules!E17)*365,"") -> 20.873114 | F26: =IFERROR((BS!F30+BS!F31)/-(IS!F7+Schedules!F12+Schedules!F16+Schedules!F17)*365,"") -> 23.962173 | G26: =CHOOSE(Asumsi!$D$4,G54,G81,G108) -> 22 | H26: =CHOOSE(Asumsi!$D$4,H54,H81,H108) -> 22 | I26: =CHOOSE(Asumsi!$D$4,I54,I81,I108) -> 22 | J26: =CHOOSE(Asumsi!$D$4,J54,J81,J108) -> 22 | K26: =CHOOSE(Asumsi!$D$4,K54,K81,K108) -> 22 | L26: Historis: 2022 11,8, 2023 20,4, 2024 20,9, 2025 24,0. Base 22; Bull 25; Bear 18.
B27: PAJAK, PENDANAAN, DISTRIBUSI
A28: tax | B28: Tarif pajak efektif (% laba sebelum pajak) | C28: =IFERROR(-IS!C18/IS!C17,"") -> 0.25801251 | D28: =IFERROR(-IS!D18/IS!D17,"") -> 0.76735139 | E28: =IFERROR(-IS!E18/IS!E17,"") -> 6.9116652 | F28: =IFERROR(-IS!F18/IS!F17,"") -> -0.058527227 | G28: =CHOOSE(Asumsi!$D$4,G56,G83,G110) -> 0.25 | H28: =CHOOSE(Asumsi!$D$4,H56,H83,H110) -> 0.25 | I28: =CHOOSE(Asumsi!$D$4,I56,I83,I110) -> 0.25 | J28: =CHOOSE(Asumsi!$D$4,J56,J83,J110) -> 0.25 | K28: =CHOOSE(Asumsi!$D$4,K56,K83,K110) -> 0.25 | L28: Historis: 2022 25,8%, 2023 76,7%, 2024 691,2%, 2025 -5,9% (laba sebelum pajak sangat kecil 2024; 2025 manfaat pajak, Temuan D11). Base 25%; Bull 22% (tarif badan); Bear 30%.
A29: fin_cost | B29: Suku bunga efektif (beban keuangan / rata-rata utang berbunga) | D29: =IFERROR(-IS!D15/AVERAGE((BS!D29+BS!D38+BS!D43+BS!D39+BS!D44+BS!D40+BS!D45+BS!D49+BS!D50),(BS!C29+BS!C38+BS!C43+BS!C39+BS!C44+BS!C40+BS!C45+BS!C49+BS!C50)),"") -> 0.063370183 | E29: =IFERROR(-IS!E15/AVERAGE((BS!E29+BS!E38+BS!E43+BS!E39+BS!E44+BS!E40+BS!E45+BS!E49+BS!E50),(BS!D29+BS!D38+BS!D43+BS!D39+BS!D44+BS!D40+BS!D45+BS!D49+BS!D50)),"") -> 0.089940574 | F29: =IFERROR(-IS!F15/AVERAGE((BS!F29+BS!F38+BS!F43+BS!F39+BS!F44+BS!F40+BS!F45+BS!F49+BS!F50),(BS!E29+BS!E38+BS!E43+BS!E39+BS!E44+BS!E40+BS!E45+BS!E49+BS!E50)),"") -> 0.10149914 | G29: =CHOOSE(Asumsi!$D$4,G57,G84,G111) -> 0.0849 | H29: =CHOOSE(Asumsi!$D$4,H57,H84,H111) -> 0.0849 | I29: =CHOOSE(Asumsi!$D$4,I57,I84,I111) -> 0.0849 | J29: =CHOOSE(Asumsi!$D$4,J57,J84,J111) -> 0.0849 | K29: =CHOOSE(Asumsi!$D$4,K57,K84,K111) -> 0.0849 | L29: Historis: 2023 6,34%, 2024 8,99%, 2025 10,15% (termasuk bagi hasil syirkah & bunga sewa). Base = rata-rata 2023-25; Bull x0,9; Bear x1,1 (Temuan D2).
A30: yld | B30: Imbal hasil kas (penghasilan keuangan / kas awal) | D30: =IFERROR(IS!D16/BS!C6,"") -> 0 | E30: =IFERROR(IS!E16/BS!D6,"") -> 0 | F30: =IFERROR(IS!F16/BS!E6,"") -> 4.9525548 | G30: =CHOOSE(Asumsi!$D$4,G58,G85,G112) -> 0 | H30: =CHOOSE(Asumsi!$D$4,H58,H85,H112) -> 0 | I30: =CHOOSE(Asumsi!$D$4,I58,I85,I112) -> 0 | J30: =CHOOSE(Asumsi!$D$4,J58,J85,J112) -> 0 | K30: =CHOOSE(Asumsi!$D$4,K58,K85,K112) -> 0 | L30: Historis: 2023 0%, 2024 0%, 2025 495%. Penghasilan keuangan 2025 = bunga pinjaman ke pihak berelasi, bukan imbal hasil kas (Temuan D3). Semua skenario 0.
A31: debt_chg | B31: Perubahan neto utang (Rp; + = tambah) | D31: =(BS!D29+BS!D38+BS!D43+BS!D39+BS!D44+BS!D40+BS!D45+BS!D49+BS!D50)-(BS!C29+BS!C38+BS!C43+BS!C39+BS!C44+BS!C40+BS!C45+BS!C49+BS!C50) -> 51444241469 | E31: =(BS!E29+BS!E38+BS!E43+BS!E39+BS!E44+BS!E40+BS!E45+BS!E49+BS!E50)-(BS!D29+BS!D38+BS!D43+BS!D39+BS!D44+BS!D40+BS!D45+BS!D49+BS!D50) -> -33270144518 | F31: =(BS!F29+BS!F38+BS!F43+BS!F39+BS!F44+BS!F40+BS!F45+BS!F49+BS!F50)-(BS!E29+BS!E38+BS!E43+BS!E39+BS!E44+BS!E40+BS!E45+BS!E49+BS!E50) -> -21873507264 | G31: =CHOOSE(Asumsi!$D$4,G59,G86,G113) -> 0 | H31: =CHOOSE(Asumsi!$D$4,H59,H86,H113) -> 0 | I31: =CHOOSE(Asumsi!$D$4,I59,I86,I113) -> 0 | J31: =CHOOSE(Asumsi!$D$4,J59,J86,J113) -> 0 | K31: =CHOOSE(Asumsi!$D$4,K59,K86,K113) -> 0 | L31: Historis utang berbunga (termasuk syirkah): 2022 94 M, 2023 145 M, 2024 112 M, 2025 90 M. Semua skenario 0 (kas = penyeimbang; jadwal pelunasan tidak dimodelkan).
A32: payout | B32: Payout dividen (% laba induk tahun lalu) | D32: =IFERROR(-CF!D41/IS!C29,"") -> 0 | E32: =IFERROR(-CF!E41/IS!D29,"") -> 0 | F32: =IFERROR(-CF!F41/IS!E29,"") -> 0 | G32: =CHOOSE(Asumsi!$D$4,G60,G87,G114) -> 0 | H32: =CHOOSE(Asumsi!$D$4,H60,H87,H114) -> 0 | I32: =CHOOSE(Asumsi!$D$4,I60,I87,I114) -> 0 | J32: =CHOOSE(Asumsi!$D$4,J60,J87,J114) -> 0 | K32: =CHOOSE(Asumsi!$D$4,K60,K87,K114) -> 0 | L32: Tidak ada dividen ke pemilik induk 2022-2025 (Temuan D11). Semua skenario 0%.
A33: nci_share | B33: Porsi laba ke NCI (% laba tahun berjalan) | C33: =IFERROR(IS!C30/IS!C20,"") -> 0 | D33: =IFERROR(IS!D30/IS!D20,"") -> 0 | E33: =IFERROR(IS!E30/IS!E20,"") -> 4.6327871e-05 | F33: =IFERROR(IS!F30/IS!F20,"") -> 4.1416181e-05 | G33: =CHOOSE(Asumsi!$D$4,G61,G88,G115) -> 0 | H33: =CHOOSE(Asumsi!$D$4,H61,H88,H115) -> 0 | I33: =CHOOSE(Asumsi!$D$4,I61,I88,I115) -> 0 | J33: =CHOOSE(Asumsi!$D$4,J61,J88,J115) -> 0 | K33: =CHOOSE(Asumsi!$D$4,K61,K88,K115) -> 0 | L33: Historis: 2022 0,000%, 2023 0,000%, 2024 0,005%, 2025 0,004% (sangat kecil). Semua skenario 0%.
B36: SKENARIO BASE - input biru per tahun (boleh diubah pengguna)
B37: PENDAPATAN (per kelompok, Cat 25)
A38: Base.g_med | B38: Pertumbuhan pendapatan penunjang medis (farmasi, laboratorium, radiologi) | G38: 0.08 | H38: 0.08 | I38: 0.08 | J38: 0.08 | K38: 0.08
A39: Base.g_inpat | B39: Pertumbuhan pendapatan rawat inap | G39: 0.08 | H39: 0.08 | I39: 0.08 | J39: 0.08 | K39: 0.08
A40: Base.g_outpat | B40: Pertumbuhan pendapatan rawat jalan | G40: 0.08 | H40: 0.08 | I40: 0.08 | J40: 0.08 | K40: 0.08
A41: Base.rev_oth | B41: Pendapatan lainnya (% 3 kelompok utama) | G41: 0.0009 | H41: 0.0009 | I41: 0.0009 | J41: 0.0009 | K41: 0.0009
B42: MARGIN & BIAYA (% pendapatan)
A43: Base.cogs | B43: Beban pokok di luar penyusutan aset tetap & aset hak guna | G43: 0.67 | H43: 0.67 | I43: 0.67 | J43: 0.67 | K43: 0.67
A44: Base.opex | B44: Beban penjualan + umum & administrasi di luar penyusutan | G44: 0.2 | H44: 0.2 | I44: 0.2 | J44: 0.2 | K44: 0.2
...

Sheet IS_Proj
A1: Proyeksi laba rugi (ilustratif)
A2: Rp penuh | kolom A = aktual (link ke IS/BS/CF/Schedules), kolom E = proyeksi | Proyeksi ILUSTRATIF berbasis asumsi transparan - bukan rekomendasi investasi, bukan target, bukan nilai wajar.
A3: Skenario aktif: | C3: =Asumsi!C4 -> Base | G3: ilustratif | H3: ilustratif | I3: ilustratif | J3: ilustratif | K3: ilustratif
A4: Kode | B4: Akun | C4: FY2022A | D4: FY2023A | E4: FY2024A | F4: FY2025A | G4: FY2026E | H4: FY2027E | I4: FY2028E | J4: FY2029E | K4: FY2030E | L4: Catatan / sumber
B5: PENDAPATAN (per kelompok)
A6: P.REV_MED | B6: Penunjang medis | C6: =Schedules!C6 -> 2534971388 | D6: =Schedules!D6 -> 11883764227 | E6: =Schedules!E6 -> 46134618145 | F6: =Schedules!F6 -> 30600343048 | G6: =F6*(1+Asumsi!G10) -> 3.304837e+10 | H6: =G6*(1+Asumsi!H10) -> 3.569224e+10 | I6: =H6*(1+Asumsi!I10) -> 3.8547619e+10 | J6: =I6*(1+Asumsi!J10) -> 4.1631429e+10 | K6: =J6*(1+Asumsi!K10) -> 4.4961943e+10
A7: P.REV_INPAT | B7: Rawat inap | C7: =Schedules!C7 -> 53534000426 | D7: =Schedules!D7 -> 79579352582 | E7: =Schedules!E7 -> 85919977894 | F7: =Schedules!F7 -> 74120487810 | G7: =F7*(1+Asumsi!G11) -> 8.0050127e+10 | H7: =G7*(1+Asumsi!H11) -> 8.6454137e+10 | I7: =H7*(1+Asumsi!I11) -> 9.3370468e+10 | J7: =I7*(1+Asumsi!J11) -> 1.0084011e+11 | K7: =J7*(1+Asumsi!K11) -> 1.0890731e+11
A8: P.REV_OUTPAT | B8: Rawat jalan | C8: =Schedules!C8 -> 43332660354 | D8: =Schedules!D8 -> 42651501335 | E8: =Schedules!E8 -> 19931209046 | F8: =Schedules!F8 -> 39969278831 | G8: =F8*(1+Asumsi!G12) -> 4.3166821e+10 | H8: =G8*(1+Asumsi!H12) -> 4.6620167e+10 | I8: =H8*(1+Asumsi!I12) -> 5.034978e+10 | J8: =I8*(1+Asumsi!J12) -> 5.4377763e+10 | K8: =J8*(1+Asumsi!K12) -> 5.8727984e+10
A9: P.REV_OTHER | B9: Lainnya (administrasi & lainnya) | C9: =Schedules!C9 -> 176512253 | D9: =Schedules!D9 -> 73060785 | E9: =Schedules!E9 -> 156443699 | F9: =Schedules!F9 -> 183158700 | G9: =(G6+G7+G8)*Asumsi!G13 -> 1.4063879e+08 | H9: =(H6+H7+H8)*Asumsi!H13 -> 1.5188989e+08 | I9: =(I6+I7+I8)*Asumsi!I13 -> 1.6404108e+08 | J9: =(J6+J7+J8)*Asumsi!J13 -> 1.7716437e+08 | K9: =(K6+K7+K8)*Asumsi!K13 -> 1.9133752e+08
A10: P.REVENUE | B10: Pendapatan | C10: =IS!C6 -> 99578144421 | D10: =IS!D6 -> 134187678929 | E10: =IS!E6 -> 152142248784 | F10: =IS!F6 -> 144873268389 | G10: =G6+G7+G8+G9 -> 1.5640596e+11 | H10: =H6+H7+H8+H9 -> 1.6891843e+11 | I10: =I6+I7+I8+I9 -> 1.8243191e+11 | J10: =J6+J7+J8+J9 -> 1.9702646e+11 | K10: =K6+K7+K8+K9 -> 2.1278858e+11
A11: P.REV_GROWTH | B11: Pertumbuhan pendapatan | D11: =D10/C10-1 -> 0.34756155 | E11: =E10/D10-1 -> 0.13380193 | F11: =F10/E10-1 -> -0.047777527 | G11: =G10/F10-1 -> 0.079605361 | H11: =H10/G10-1 -> 0.08 | I11: =I10/H10-1 -> 0.08 | J11: =J10/I10-1 -> 0.08 | K11: =K10/J10-1 -> 0.08
B12: BIAYA & EBITDA
A13: P.COGS_X | B13: Beban pokok di luar penyusutan (aset tetap & aset hak guna) | C13: =IS!C7+Schedules!C12+Schedules!C16+Schedules!C17 -> -63838203004 | D13: =IS!D7+Schedules!D12+Schedules!D16+Schedules!D17 -> -85187343300 | E13: =IS!E7+Schedules!E12+Schedules!E16+Schedules!E17 -> -99125797801 | F13: =IS!F7+Schedules!F12+Schedules!F16+Schedules!F17 -> -100202557824 | G13: =-G10*Asumsi!G15 -> -1.0479199e+11 | H13: =-H10*Asumsi!H15 -> -1.1317535e+11 | I13: =-I10*Asumsi!I15 -> -1.2222938e+11 | J13: =-J10*Asumsi!J15 -> -1.3200773e+11 | K13: =-K10*Asumsi!K15 -> -1.4256835e+11
A14: P.GP_X | B14: Laba bruto sebelum penyusutan | C14: =C10+C13 -> 35739941417 | D14: =D10+D13 -> 49000335629 | E14: =E10+E13 -> 53016450983 | F14: =F10+F13 -> 44670710565 | G14: =G10+G13 -> 5.1613966e+10 | H14: =H10+H13 -> 5.5743083e+10 | I14: =I10+I13 -> 6.020253e+10 | J14: =J10+J13 -> 6.5018732e+10 | K14: =K10+K13 -> 7.0220231e+10
A15: P.OPEX_X | B15: Beban usaha di luar penyusutan | C15: =IS!C11+Schedules!C13+Schedules!C18 -> -21815774673 | D15: =IS!D11+Schedules!D13+Schedules!D18 -> -31571259863 | E15: =IS!E11+Schedules!E13+Schedules!E18 -> -31949269543 | F15: =IS!F11+Schedules!F13+Schedules!F18 -> -28616778422 | G15: =-G10*Asumsi!G16 -> -3.1281191e+10 | H15: =-H10*Asumsi!H16 -> -3.3783687e+10 | I15: =-I10*Asumsi!I16 -> -3.6486382e+10 | J15: =-J10*Asumsi!J16 -> -3.9405292e+10 | K15: =-K10*Asumsi!K16 -> -4.2557716e+10
A16: P.OTHER_OP | B16: Pendapatan (beban) lain-lain neto | C16: =IS!C13 -> 1226392843 | D16: =IS!D13 -> 75326392 | E16: =IS!E13 -> 313957191 | F16: =IS!F13 -> -710131821 | G16: =G10*Asumsi!G17 -> 3.1281191e+08 | H16: =H10*Asumsi!H17 -> 3.3783687e+08 | I16: =I10*Asumsi!I17 -> 3.6486382e+08 | J16: =J10*Asumsi!J17 -> 3.9405292e+08 | K16: =K10*Asumsi!K17 -> 4.2557716e+08
A17: P.EBITDA | B17: EBITDA | C17: =C14+C15+C16 -> 15150559587 | D17: =D14+D15+D16 -> 17504402158 | E17: =E14+E15+E16 -> 21381138631 | F17: =F14+F15+F16 -> 15343800322 | G17: =G14+G15+G16 -> 2.0645586e+10 | H17: =H14+H15+H16 -> 2.2297233e+10 | I17: =I14+I15+I16 -> 2.4081012e+10 | J17: =J14+J15+J16 -> 2.6007493e+10 | K17: =K14+K15+K16 -> 2.8088092e+10 | L17: laba usaha model + penyusutan aset tetap + penyusutan aset hak guna
A18: P.DA | B18: Penyusutan & amortisasi | C18: =-Schedules!C20 -> -6778169378 | D18: =-Schedules!D20 -> -7754681103 | E18: =-Schedules!E20 -> -9756026475 | F18: =-Schedules!F20 -> -12603292085 | G18: =-(Schedules_Proj!G9+Schedules_Proj!G13) -> -1.2587434e+10 | H18: =-(Schedules_Proj!H9+Schedules_Proj!H13) -> -1.2786288e+10 | I18: =-(Schedules_Proj!I9+Schedules_Proj!I13) -> -1.3080573e+10 | J18: =-(Schedules_Proj!J9+Schedules_Proj!J13) -> -1.3470096e+10 | K18: =-(Schedules_Proj!K9+Schedules_Proj!K13) -> -1.3955422e+10
A19: P.EBIT | B19: Laba usaha (EBIT) | C19: =C17+C18 -> 8372390209 | D19: =D17+D18 -> 9749721055 | E19: =E17+E18 -> 11625112156 | F19: =F17+F18 -> 2740508237 | G19: =G17+G18 -> 8.0581528e+09 | H19: =H17+H18 -> 9.5109448e+09 | I19: =I17+I18 -> 1.1000439e+10 | J19: =J17+J18 -> 1.2537397e+10 | K19: =K17+K18 -> 1.413267e+10 | L19: historis: = laba usaha model IS (cek di Rekonsiliasi; Temuan D9)
A20: P.FIN_INC | B20: Penghasilan keuangan | C20: =IS!C16 -> 0 | D20: =IS!D16 -> 0 | E20: =IS!E16 -> 0 | F20: =IS!F16 -> 13190576716 | G20: =BS_Proj!F6*Asumsi!G30 -> 0 | H20: =BS_Proj!G6*Asumsi!H30 -> 0 | I20: =BS_Proj!H6*Asumsi!I30 -> 0 | J20: =BS_Proj!I6*Asumsi!J30 -> 0 | K20: =BS_Proj!J6*Asumsi!K30 -> 0 | L20: E: imbal hasil x kas awal (0; Temuan D3)
A21: P.FIN_COST | B21: Beban keuangan | C21: =IS!C15 -> -3643595812 | D21: =IS!D15 -> -7565985614 | E21: =IS!E15 -> -11555610977 | F21: =IS!F15 -> -10242145297 | G21: =-Schedules_Proj!G24*Asumsi!G29 -> -7.638617e+09 | H21: =-Schedules_Proj!H24*Asumsi!H29 -> -7.638617e+09 | I21: =-Schedules_Proj!I24*Asumsi!I29 -> -7.638617e+09 | J21: =-Schedules_Proj!J24*Asumsi!J29 -> -7.638617e+09 | K21: =-Schedules_Proj!K24*Asumsi!K29 -> -7.638617e+09 | L21: E: suku bunga x rata-rata utang berbunga termasuk syirkah (Temuan D2)
A22: P.PBT | B22: Laba sebelum pajak | C22: =C19+C20+C21 -> 4728794397 | D22: =D19+D20+D21 -> 2183735441 | E22: =E19+E20+E21 -> 69501179 | F22: =F19+F20+F21 -> 5688939656 | G22: =G19+G20+G21 -> 4.1953574e+08 | H22: =H19+H20+H21 -> 1.8723278e+09 | I22: =I19+I20+I21 -> 3.3618222e+09 | J22: =J19+J20+J21 -> 4.8987801e+09 | K22: =K19+K20+K21 -> 6.4940535e+09
A23: P.TAX | B23: Beban pajak | C23: =IS!C18 -> -1220088106 | D23: =IS!D18 -> -1675692417 | E23: =IS!E18 -> -480368880 | F23: =IS!F18 -> 332957861 | G23: =-MAX(G22,0)*Asumsi!G28 -> -1.0488394e+08 | H23: =-MAX(H22,0)*Asumsi!H28 -> -4.6808195e+08 | I23: =-MAX(I22,0)*Asumsi!I28 -> -8.4045556e+08 | J23: =-MAX(J22,0)*Asumsi!J28 -> -1.224695e+09 | K23: =-MAX(K22,0)*Asumsi!K28 -> -1.6235134e+09
A24: P.MERGING | B24: Laba proforma entitas anak sebelum restrukturisasi | C24: =IS!C19 -> 1379459473 | D24: =IS!D19 -> 3031673373 | E24: =IS!E19 -> 3248230974 | F24: =IS!F19 -> 0 | G24: =0 -> 0 | H24: =0 -> 0 | I24: =0 -> 0 | J24: =0 -> 0 | K24: =0 -> 0 | L24: E: 0 (restrukturisasi selesai 2024; Temuan D1)
A25: P.NI | B25: Laba tahun berjalan | C25: =C22+C23+C24 -> 4888165764 | D25: =D22+D23+D24 -> 3539716397 | E25: =E22+E23+E24 -> 2837363273 | F25: =F22+F23+F24 -> 6021897517 | G25: =G22+G23+G24 -> 3.1465181e+08 | H25: =H22+H23+H24 -> 1.4042458e+09 | I25: =I22+I23+I24 -> 2.5213667e+09 | J25: =J22+J23+J24 -> 3.6740851e+09 | K25: =K22+K23+K24 -> 4.8705401e+09
A26: P.NI_NCI | B26: Diatribusikan ke NCI | C26: =IS!C30 -> 0 | D26: =IS!D30 -> 0 | E26: =IS!E30 -> 131449 | F26: =IS!F30 -> 249404 | G26: =G25*Asumsi!G33 -> 0 | H26: =H25*Asumsi!H33 -> 0 | I26: =I25*Asumsi!I33 -> 0 | J26: =J25*Asumsi!J33 -> 0 | K26: =K25*Asumsi!K33 -> 0
A27: P.NI_PARENT | B27: Diatribusikan ke pemilik entitas induk | C27: =C25-C26 -> 4888165764 | D27: =D25-D26 -> 3539716397 | E27: =E25-E26 -> 2837231824 | F27: =F25-F26 -> 6021648113 | G27: =G25-G26 -> 3.1465181e+08 | H27: =H25-H26 -> 1.4042458e+09 | I27: =I25-I26 -> 2.5213667e+09 | J27: =J25-J26 -> 3.6740851e+09 | K27: =K25-K26 -> 4.8705401e+09
A28: P.EPS | B28: Laba induk per saham (Rp; / 2.550.078.941 saham) | C28: =C27/Asumsi!$C$118 -> 1.9168684 | D28: =D27/Asumsi!$C$118 -> 1.3880811 | E28: =E27/Asumsi!$C$118 -> 1.1126055 | F28: =F27/Asumsi!$C$118 -> 2.3613575 | G28: =G27/Asumsi!$C$118 -> 0.12338905 | H28: =H27/Asumsi!$C$118 -> 0.55066759 | I28: =I27/Asumsi!$C$118 -> 0.98874063 | J28: =J27/Asumsi!$C$118 -> 1.4407731 | K28: =K27/Asumsi!$C$118 -> 1.9099566 | L28: EPS tercetak memakai saham rata-rata tertimbang (IPO 2025)
B29: MARGIN
A30: P.GM_X | B30: Margin laba bruto sebelum penyusutan | C30: =C14/C10 -> 0.35891351 | D30: =D14/D10 -> 0.3651627 | E30: =E14/E10 -> 0.34846633 | F30: =F14/F10 -> 0.30834336 | G30: =G14/G10 -> 0.33 | H30: =H14/H10 -> 0.33 | I30: =I14/I10 -> 0.33 | J30: =J14/J10 -> 0.33 | K30: =K14/K10 -> 0.33
A31: P.EBITDA_M | B31: Margin EBITDA | C31: =C17/C10 -> 0.15214744 | D31: =D17/D10 -> 0.13044716 | E31: =E17/E10 -> 0.14053387 | F31: =F17/F10 -> 0.10591188 | G31: =G17/G10 -> 0.132 | H31: =H17/H10 -> 0.132 | I31: =I17/I10 -> 0.132 | J31: =J17/J10 -> 0.132 | K31: =K17/K10 -> 0.132
A32: P.EBIT_M | B32: Margin EBIT | C32: =C19/C10 -> 0.084078592 | D32: =D19/D10 -> 0.072657349 | E32: =E19/E10 -> 0.076409493 | F32: =F19/F10 -> 0.01891659 | G32: =G19/G10 -> 0.051520754 | H32: =H19/H10 -> 0.056304955 | I32: =I19/I10 -> 0.060298877 | J32: =J19/J10 -> 0.063633063 | K32: =K19/K10 -> 0.06641649
A33: P.NI_M | B33: Margin laba bersih | C33: =C25/C10 -> 0.049088741 | D33: =D25/D10 -> 0.026378848 | E33: =E25/E10 -> 0.018649411 | F33: =F25/F10 -> 0.041566657 | G33: =G25/G10 -> 0.0020117636 | H33: =H25/H10 -> 0.0083131592 | I33: =I25/I10 -> 0.013820864 | J33: =J25/J10 -> 0.018647673 | K33: =K25/K10 -> 0.022889105

Sheet BS_Proj
A1: Proyeksi posisi keuangan agregat (ilustratif)
A2: Rp penuh | kolom A = aktual (link ke IS/BS/CF/Schedules), kolom E = proyeksi | Proyeksi ILUSTRATIF berbasis asumsi transparan - bukan rekomendasi investasi, bukan target, bukan nilai wajar.
A3: Skenario aktif: | C3: =Asumsi!C4 -> Base | G3: ilustratif | H3: ilustratif | I3: ilustratif | J3: ilustratif | K3: ilustratif
A4: Kode | B4: Akun | C4: FY2022A | D4: FY2023A | E4: FY2024A | F4: FY2025A | G4: FY2026E | H4: FY2027E | I4: FY2028E | J4: FY2029E | K4: FY2030E | L4: Catatan / sumber
B5: ASET
A6: PB.CASH | B6: Kas dan setara kas | C6: =BS!C6 -> 29547207476 | D6: =BS!D6 -> 2463973775 | E6: =BS!E6 -> 2663388349 | F6: =BS!F6 -> 4036506961 | G6: =CF_Proj!G24 -> -2.0195699e+09 | H6: =CF_Proj!H24 -> -5.0444379e+09 | I6: =CF_Proj!I24 -> -8.0351331e+09 | J6: =CF_Proj!J24 -> -1.0970998e+10 | K6: =CF_Proj!K24 -> -1.3831484e+10 | L6: E: penyeimbang dari CF_Proj
A7: PB.AR | B7: Piutang usaha (pihak ketiga + berelasi) | C7: =(BS!C8+BS!C9) -> 12118406500 | D7: =(BS!D8+BS!D9) -> 16783681668 | E7: =(BS!E8+BS!E9) -> 25075858587 | F7: =(BS!F8+BS!F9) -> 18872446355 | G7: =Schedules_Proj!G26 -> 2.1425474e+10 | H7: =Schedules_Proj!H26 -> 2.3139511e+10 | I7: =Schedules_Proj!I26 -> 2.4990672e+10 | J7: =Schedules_Proj!J26 -> 2.6989926e+10 | K7: =Schedules_Proj!K26 -> 2.914912e+10
A8: PB.INV | B8: Persediaan | C8: =BS!C12 -> 2264889867 | D8: =BS!D12 -> 4036032457 | E8: =BS!E12 -> 4135618544 | F8: =BS!F12 -> 1336242114 | G8: =Schedules_Proj!G27 -> 2.8710135e+09 | H8: =Schedules_Proj!H27 -> 3.1006945e+09 | I8: =Schedules_Proj!I27 -> 3.3487501e+09 | J8: =Schedules_Proj!J27 -> 3.6166501e+09 | K8: =Schedules_Proj!K27 -> 3.9059821e+09
A9: PB.OCA | B9: Aset lancar lainnya | C9: =BS!C16-BS!C6-BS!C8-BS!C9-BS!C12 -> 1685855107 | D9: =BS!D16-BS!D6-BS!D8-BS!D9-BS!D12 -> 4616338154 | E9: =BS!E16-BS!E6-BS!E8-BS!E9-BS!E12 -> 3217661624 | F9: =BS!F16-BS!F6-BS!F8-BS!F9-BS!F12 -> 15099657194 | G9: =F9 -> 15099657194 | H9: =G9 -> 15099657194 | I9: =H9 -> 15099657194 | J9: =I9 -> 15099657194 | K9: =J9 -> 15099657194 | L9: E: konstan
A10: PB.TCA | B10: Jumlah aset lancar | C10: =C6+C7+C8+C9 -> 45616358950 | D10: =D6+D7+D8+D9 -> 27900026054 | E10: =E6+E7+E8+E9 -> 35092527104 | F10: =F6+F7+F8+F9 -> 39344852624 | G10: =G6+G7+G8+G9 -> 3.7376574e+10 | H10: =H6+H7+H8+H9 -> 3.6295425e+10 | I10: =I6+I7+I8+I9 -> 3.5403947e+10 | J10: =J6+J7+J8+J9 -> 3.4735236e+10 | K10: =K6+K7+K8+K9 -> 3.4323275e+10
A11: PB.PPE | B11: Aset tetap - neto | C11: =BS!C21 -> 66252356120 | D11: =BS!D21 -> 117418739194 | E11: =BS!E21 -> 132385666764 | F11: =BS!F21 -> 127921073027 | G11: =Schedules_Proj!G10 -> 1.2994196e+11 | H11: =Schedules_Proj!H10 -> 1.3293265e+11 | I11: =Schedules_Proj!I10 -> 1.3689122e+11 | J11: =Schedules_Proj!J10 -> 1.4182339e+11 | K11: =Schedules_Proj!K10 -> 1.4774242e+11
A12: PB.INTANG | B12: Aset takberwujud | C12: =BS!C17 -> 0 | D12: =BS!D17 -> 0 | E12: =BS!E17 -> 0 | F12: =BS!F17 -> 0 | G12: =Schedules_Proj!G15 -> 0 | H12: =Schedules_Proj!H15 -> 0 | I12: =Schedules_Proj!I15 -> 0 | J12: =Schedules_Proj!J15 -> 0 | K12: =Schedules_Proj!K15 -> 0
A13: PB.ONCA | B13: Aset tidak lancar lain (piutang pihak berelasi, uang muka aset, aset hak guna, pajak tangguhan, uang muka investasi 2022-23) | C13: =BS!C26-BS!C21-BS!C17 -> 48124674181 | D13: =BS!D26-BS!D21-BS!D17 -> 155351127589 | E13: =BS!E26-BS!E21-BS!E17 -> 100622046044 | F13: =BS!F26-BS!F21-BS!F17 -> 162946944844 | G13: =F13 -> 162946944844 | H13: =G13 -> 162946944844 | I13: =H13 -> 162946944844 | J13: =I13 -> 162946944844 | K13: =J13 -> 162946944844 | L13: E: konstan
A14: PB.TNCA | B14: Jumlah aset tidak lancar | C14: =C11+C12+C13 -> 114377030301 | D14: =D11+D12+D13 -> 272769866783 | E14: =E11+E12+E13 -> 233007712808 | F14: =F11+F12+F13 -> 290868017871 | G14: =G11+G12+G13 -> 2.928889e+11 | H14: =H11+H12+H13 -> 2.9587959e+11 | I14: =I11+I12+I13 -> 2.9983816e+11 | J14: =J11+J12+J13 -> 3.0477034e+11 | K14: =K11+K12+K13 -> 3.1068937e+11
A15: PB.TA | B15: JUMLAH ASET | C15: =C10+C14 -> 159993389251 | D15: =D10+D14 -> 300669892837 | E15: =E10+E14 -> 268100239912 | F15: =F10+F14 -> 330212870495 | G15: =G10+G14 -> 3.3026548e+11 | H15: =H10+H14 -> 3.3217502e+11 | I15: =I10+I14 -> 3.3524211e+11 | J15: =J10+J14 -> 3.3950557e+11 | K15: =K10+K14 -> 3.4501264e+11
B16: LIABILITAS
A17: PB.AP | B17: Utang usaha (pihak ketiga + berelasi) | C17: =(BS!C30+BS!C31) -> 2059291014 | D17: =(BS!D30+BS!D31) -> 4772562529 | E17: =(BS!E30+BS!E31) -> 5668668826 | F17: =(BS!F30+BS!F31) -> 6578276878 | G17: =Schedules_Proj!G28 -> 6.3162296e+09 | H17: =Schedules_Proj!H28 -> 6.821528e+09 | I17: =Schedules_Proj!I28 -> 7.3672502e+09 | J17: =Schedules_Proj!J28 -> 7.9566302e+09 | K17: =Schedules_Proj!K28 -> 8.5931607e+09
A18: PB.DEBT | B18: Utang berbunga (bank, pembiayaan konsumen, syirkah) | C18: =(BS!C29+BS!C38+BS!C43+BS!C39+BS!C44+BS!C40+BS!C45+BS!C49+BS!C50) -> 93671342320 | D18: =(BS!D29+BS!D38+BS!D43+BS!D39+BS!D44+BS!D40+BS!D45+BS!D49+BS!D50) -> 145115583789 | E18: =(BS!E29+BS!E38+BS!E43+BS!E39+BS!E44+BS!E40+BS!E45+BS!E49+BS!E50) -> 111845439271 | F18: =(BS!F29+BS!F38+BS!F43+BS!F39+BS!F44+BS!F40+BS!F45+BS!F49+BS!F50) -> 89971932007 | G18: =Schedules_Proj!G23 -> 89971932007 | H18: =Schedules_Proj!H23 -> 89971932007 | I18: =Schedules_Proj!I23 -> 89971932007 | J18: =Schedules_Proj!J23 -> 89971932007 | K18: =Schedules_Proj!K23 -> 89971932007
A19: PB.LEASE | B19: Liabilitas sewa | C19: =(BS!C41+BS!C46) -> 0 | D19: =(BS!D41+BS!D46) -> 0 | E19: =(BS!E41+BS!E46) -> 2328487150 | F19: =(BS!F41+BS!F46) -> 1329650108 | G19: =Schedules_Proj!G18 -> 1329650108 | H19: =Schedules_Proj!H18 -> 1329650108 | I19: =Schedules_Proj!I18 -> 1329650108 | J19: =Schedules_Proj!J18 -> 1329650108 | K19: =Schedules_Proj!K18 -> 1329650108
A20: PB.OL | B20: Liabilitas lainnya | C20: =BS!C52-BS!C30-BS!C31-(BS!C29+BS!C38+BS!C43+BS!C39+BS!C44+BS!C40+BS!C45+BS!C49+BS!C50)-BS!C41-BS!C46 -> 13196011190 | D20: =BS!D52-BS!D30-BS!D31-(BS!D29+BS!D38+BS!D43+BS!D39+BS!D44+BS!D40+BS!D45+BS!D49+BS!D50)-BS!D41-BS!D46 -> 21628740131 | E20: =BS!E52-BS!E30-BS!E31-(BS!E29+BS!E38+BS!E43+BS!E39+BS!E44+BS!E40+BS!E45+BS!E49+BS!E50)-BS!E41-BS!E46 -> 18528254195 | F20: =BS!F52-BS!F30-BS!F31-(BS!F29+BS!F38+BS!F43+BS!F39+BS!F44+BS!F40+BS!F45+BS!F49+BS!F50)-BS!F41-BS!F46 -> 25827020582 | G20: =F20 -> 25827020582 | H20: =G20 -> 25827020582 | I20: =H20 -> 25827020582 | J20: =I20 -> 25827020582 | K20: =J20 -> 25827020582 | L20: utang lain, akrual, pajak, liabilitas kontrak, imbalan kerja; E: konstan
A21: PB.TL | B21: JUMLAH LIABILITAS | C21: =C17+C18+C19+C20 -> 108926644524 | D21: =D17+D18+D19+D20 -> 171516886449 | E21: =E17+E18+E19+E20 -> 138370849442 | F21: =F17+F18+F19+F20 -> 123706879575 | G21: =G17+G18+G19+G20 -> 1.2344483e+11 | H21: =H17+H18+H19+H20 -> 1.2395013e+11 | I21: =I17+I18+I19+I20 -> 1.2449585e+11 | J21: =J17+J18+J19+J20 -> 1.2508523e+11 | K21: =K17+K18+K19+K20 -> 1.2572176e+11
B22: EKUITAS
A23: PB.EQ_OTHER | B23: Modal & cadangan (selain saldo laba; termasuk surplus revaluasi & ekuitas proforma) | C23: =BS!C59-BS!C58 -> 31525576875 | D23: =BS!D59-BS!D58 -> 106072122139 | E23: =BS!E59-BS!E58 -> 103807584338 | F23: =BS!F59-BS!F58 -> 174562244493 | G23: =F23 -> 174562244493 | H23: =G23 -> 174562244493 | I23: =H23 -> 174562244493 | J23: =I23 -> 174562244493 | K23: =J23 -> 174562244493 | L23: E: konstan
A24: PB.RE | B24: Saldo laba | C24: =BS!C58 -> 19541167852 | D24: =BS!D58 -> 23080884249 | E24: =BS!E58 -> 25918247522 | F24: =BS!F58 -> 31939895635 | G24: =F24+IS_Proj!G27+CF_Proj!G19 -> 3.2254547e+10 | H24: =G24+IS_Proj!H27+CF_Proj!H19 -> 3.3658793e+10 | I24: =H24+IS_Proj!I27+CF_Proj!I19 -> 3.618016e+10 | J24: =I24+IS_Proj!J27+CF_Proj!J19 -> 3.9854245e+10 | K24: =J24+IS_Proj!K27+CF_Proj!K19 -> 4.4724785e+10
A25: PB.EQ_PARENT | B25: Ekuitas pemilik entitas induk | C25: =C23+C24 -> 51066744727 | D25: =D23+D24 -> 129153006388 | E25: =E23+E24 -> 129725831860 | F25: =F23+F24 -> 206502140128 | G25: =G23+G24 -> 2.0681679e+11 | H25: =H23+H24 -> 2.0822104e+11 | I25: =I23+I24 -> 2.107424e+11 | J25: =J23+J24 -> 2.1441649e+11 | K25: =K23+K24 -> 2.1928703e+11
A26: PB.NCI | B26: Kepentingan nonpengendali | C26: =BS!C60 -> 0 | D26: =BS!D60 -> 0 | E26: =BS!E60 -> 3558610 | F26: =BS!F60 -> 3850792 | G26: =F26+IS_Proj!G26 -> 3850792 | H26: =G26+IS_Proj!H26 -> 3850792 | I26: =H26+IS_Proj!I26 -> 3850792 | J26: =I26+IS_Proj!J26 -> 3850792 | K26: =J26+IS_Proj!K26 -> 3850792 | L26: E: tanpa dividen ke NCI (ilustratif)
A27: PB.TE | B27: JUMLAH EKUITAS | C27: =C25+C26 -> 51066744727 | D27: =D25+D26 -> 129153006388 | E27: =E25+E26 -> 129729390470 | F27: =F25+F26 -> 206505990920 | G27: =G25+G26 -> 2.0682064e+11 | H27: =H25+H26 -> 2.0822489e+11 | I27: =I25+I26 -> 2.1074626e+11 | J27: =J25+J26 -> 2.1442034e+11 | K27: =K25+K26 -> 2.1929088e+11
A28: PB.TLE | B28: JUMLAH LIABILITAS DAN EKUITAS | C28: =C21+C27 -> 159993389251 | D28: =D21+D27 -> 300669892837 | E28: =E21+E27 -> 268100239912 | F28: =F21+F27 -> 330212870495 | G28: =G21+G27 -> 3.3026548e+11 | H28: =H21+H27 -> 3.3217502e+11 | I28: =I21+I27 -> 3.3524211e+11 | J28: =J21+J27 -> 3.3950557e+11 | K28: =K21+K27 -> 3.4501264e+11
A30: PB.CHECK | B30: Cek: aset - (liabilitas + ekuitas), harus 0 | C30: =ROUND(C15-C28,0) -> 0 | D30: =ROUND(D15-D28,0) -> 0 | E30: =ROUND(E15-E28,0) -> 0 | F30: =ROUND(F15-F28,0) -> 0 | G30: =ROUND(G15-G28,0) -> 0 | H30: =ROUND(H15-H28,0) -> 0 | I30: =ROUND(I15-I28,0) -> 0 | J30: =ROUND(J15-J28,0) -> 0 | K30: =ROUND(K15-K28,0) -> 0
A31: PB.NETDEBT | B31: Memo: utang neto (utang + sewa - kas) | C31: =C18+C19-C6 -> 64124134844 | D31: =D18+D19-D6 -> 142651610014 | E31: =E18+E19-E6 -> 111510538072 | F31: =F18+F19-F6 -> 87265075154 | G31: =G18+G19-G6 -> 9.3321152e+10 | H31: =H18+H19-H6 -> 9.634602e+10 | I31: =I18+I19-I6 -> 9.9336715e+10 | J31: =J18+J19-J6 -> 1.0227258e+11 | K31: =K18+K19-K6 -> 1.0513307e+11
A32: PB.ROE | B32: Memo: ROE (laba induk / rata-rata ekuitas induk) | D32: =IS_Proj!D27/AVERAGE(C25,D25) -> 0.039282225 | E32: =IS_Proj!E27/AVERAGE(D25,E25) -> 0.02191938 | F32: =IS_Proj!F27/AVERAGE(E25,F25) -> 0.035818841 | G32: =IS_Proj!G27/AVERAGE(F25,G25) -> 0.0015225618 | H32: =IS_Proj!H27/AVERAGE(G25,H25) -> 0.006766833 | I32: =IS_Proj!I27/AVERAGE(H25,I25) -> 0.012036213 | J32: =IS_Proj!J27/AVERAGE(I25,J25) -> 0.017283351 | K32: =IS_Proj!K27/AVERAGE(J25,K25) -> 0.022460229
A33: PB.ND_EBITDA | B33: Memo: utang neto / EBITDA | C33: =C31/IS_Proj!C17 -> 4.2324598 | D33: =D31/IS_Proj!D17 -> 8.1494706 | E33: =E31/IS_Proj!E17 -> 5.2153695 | F33: =F31/IS_Proj!F17 -> 5.6873182 | G33: =G31/IS_Proj!G17 -> 4.5201502 | H33: =H31/IS_Proj!H17 -> 4.3209854 | I33: =I31/IS_Proj!I17 -> 4.1251055 | J33: =J31/IS_Proj!J17 -> 3.9324275 | K33: =K31/IS_Proj!K17 -> 3.7429764

Sheet CF_Proj
A1: Proyeksi arus kas (metode tidak langsung untuk tahun E)
A2: Rp penuh | kolom A = aktual (link ke IS/BS/CF/Schedules), kolom E = proyeksi | Proyeksi ILUSTRATIF berbasis asumsi transparan - bukan rekomendasi investasi, bukan target, bukan nilai wajar.
A3: Skenario aktif: | C3: =Asumsi!C4 -> Base | G3: ilustratif | H3: ilustratif | I3: ilustratif | J3: ilustratif | K3: ilustratif
A4: Kode | B4: Akun | C4: FY2022A | D4: FY2023A | E4: FY2024A | F4: FY2025A | G4: FY2026E | H4: FY2027E | I4: FY2028E | J4: FY2029E | K4: FY2030E | L4: Catatan / sumber
B5: ARUS KAS OPERASI
A6: PC.NI | B6: Laba tahun berjalan | C6: =IS_Proj!C25 -> 4888165764 | D6: =IS_Proj!D25 -> 3539716397 | E6: =IS_Proj!E25 -> 2837363273 | F6: =IS_Proj!F25 -> 6021897517 | G6: =IS_Proj!G25 -> 3.1465181e+08 | H6: =IS_Proj!H25 -> 1.4042458e+09 | I6: =IS_Proj!I25 -> 2.5213667e+09 | J6: =IS_Proj!J25 -> 3.6740851e+09 | K6: =IS_Proj!K25 -> 4.8705401e+09
A7: PC.DA | B7: Penyusutan & amortisasi (nonkas) | G7: =-IS_Proj!G18 -> 1.2587434e+10 | H7: =-IS_Proj!H18 -> 1.2786288e+10 | I7: =-IS_Proj!I18 -> 1.3080573e+10 | J7: =-IS_Proj!J18 -> 1.3470096e+10 | K7: =-IS_Proj!K18 -> 1.3955422e+10
A8: PC.D_AR | B8: (Kenaikan) piutang usaha | G8: =BS_Proj!F7-BS_Proj!G7 -> -2.5530272e+09 | H8: =BS_Proj!G7-BS_Proj!H7 -> -1.7140379e+09 | I8: =BS_Proj!H7-BS_Proj!I7 -> -1.8511609e+09 | J8: =BS_Proj!I7-BS_Proj!J7 -> -1.9992538e+09 | K8: =BS_Proj!J7-BS_Proj!K7 -> -2.1591941e+09
