Workbook

Sheet Cover
B2: PT Sejahteraraya Anugrahjaya Tbk (SRAJ) - Model data fundamental 6 tahun & proyeksi ilustratif
B3: Historis FY2020-FY2025 (laporan keuangan konsolidasian audited) | proyeksi ilustratif FY2026-FY2030 | Format: PRO
B5: Penting - sifat dokumen
B6: Bukan rekomendasi | C6: Dokumen ini hanya ringkasan informasi dan analisis data fundamental yang bersumber dari laporan keuangan publik (audited) PT Sejahteraraya Anugrahjaya Tbk. Dokumen ini BUKAN saran atau rekomendasi investasi, bukan ajakan membeli, menjual, atau menahan efek apa pun, dan tidak memuat target atau penilaian nilai wajar. Proyeksi bersifat ilustratif dan dapat berbeda jauh dari realisasi. Data dapat mengandung kesalahan ekstraksi; selalu cek ke laporan asli. Dokumen ini disusun dengan bantuan kecerdasan buatan (AI) dari laporan keuangan publik; kemungkinan kesalahan tetap ada, harap verifikasi ke sumber.
B7: Proyeksi | C7: Angka FY..E adalah proyeksi ILUSTRATIF berbasis asumsi transparan di sheet Asumsi (Base/Bull/Bear), dikalibrasi dari tren FY2022-2025. Tidak ada target, nilai wajar, atau kesimpulan nilai per saham.
B8: Sumber data | C8: Laporan keuangan konsolidasian audited PT Sejahteraraya Anugrahjaya Tbk FY2020-FY2025 (diunduh dari situs perusahaan mayapadahospital.com, halaman hubungan investor). Kolom 2020-2023 dan 2025 dari LK tahun masing-masing (dasar asli); kolom 2024 dari komparatif LK FY2025 yang disajikan kembali (PSAK 115: Grup sebagai agen atas jasa dokter). LK FY2023-FY2025 dalam jutaan Rupiah (dikonversi ke Rupiah penuh). Lihat Data_Log & Temuan.
B10: Hak cipta & lisensi
B11: Hak cipta | C11: © 2026 Ryant Gabein Pasaribu. Kompilasi, struktur, metodologi, kode akun standar, dan analisis dalam file ini adalah ciptaan Ryant Gabein Pasaribu. Dilisensikan di bawah Creative Commons Atribusi 4.0 Internasional (CC BY 4.0): bebas digunakan dan dibagikan dengan wajib mencantumkan atribusi "Ryant Gabein Pasaribu" dan menyertakan tautan lisensi https://creativecommons.org/licenses/by/4.0/deed.id. Data laporan keuangan bersumber dari laporan publik emiten.
B12: Versi | C12: v1.0
B13: Tanggal terbit | C13: 2026-10-26
B14: ID file | C14: SRAJ-FY2025-v1.0-79A95C20
B16: Format
B17: Data terbuka | C17: Data dan model ini terbuka dan gratis untuk semua orang.
B18: Format output | C18: Tiga format (bukan tingkatan akses, semuanya gratis): Ritel (PDF ringkasan 4 halaman), Akademik (Excel data historis, rasio, rekonsiliasi), Pro (Excel model penuh dengan proyeksi ilustratif & template DCF kosong).
B20: Informasi model
B21: Emiten | C21: PT Sejahteraraya Anugrahjaya Tbk dan Entitas Anaknya (kode SRAJ) - jaringan rumah sakit swasta Mayapada Hospital (Jakarta, Tangerang, Bogor, Surabaya, Bandung)
B22: Satuan | C22: Rupiah penuh (Ringkasan/Dashboard: Rp miliar); beban & arus kas keluar negatif (kurung)
B23: Tahun historis | C23: FY2020, FY2021, FY2022, FY2023, FY2024, FY2025
B24: Status rekonsiliasi | C24: =Rekonsiliasi!$C$3 -> SEMUA 330 CEK SESUAI EKSPEKTASI
B25: Skenario aktif | C25: =Asumsi!C4 -> Base
B26: Dibangun | C26: 26-10-2026 oleh /workspace/emiten/common/build_model.py --ticker SRAJ
B28: Daftar sheet
B29: Cover | C29: Sifat dokumen, lisensi, keterangan warna
B30: Panduan | C30: Cara memakai model ini
B31: Ringkasan | C31: Ringkasan siap cetak/PDF (A4): highlights, indikator utama, grafik, tanda perhatian
B32: Dashboard | C32: Indikator & grafik historis + proyeksi ilustratif
B33: Asumsi | C33: Selektor skenario Base/Bull/Bear & driver per tahun, dengan dasar kalibrasi FY2023-2025
B34: IS_Proj | C34: Proyeksi laba rugi (pendapatan per kelompok, EBITDA, laba)
B35: BS_Proj | C35: Proyeksi neraca agregat; kas = penyeimbang; cek balance
B36: CF_Proj | C36: Proyeksi arus kas tidak langsung; FCF
B37: Schedules_Proj | C37: Aset tetap, aset takberwujud, sewa, utang, modal kerja
B38: DCF_Template | C38: Kalkulator DCF opsional dengan input KOSONG (tanpa kesimpulan)
B39: Peer | C39: Tabel pembanding fundamental (input kosong, tanpa kelipatan pasar)
B40: IS | C40: Laba rugi & OCI FY2020-2025
... B48: Data_Log | C48: Sumber per tahun, pemetaan akun, override

Sheet Panduan
A1: Panduan pemakaian
A2: Format PRO (model penuh) - gratis & terbuka; bukan rekomendasi investasi
B4: Langkah
B5: 1. Mulai | C5: Baca Cover (sifat dokumen) lalu Ringkasan (siap cetak A4: File > Print/Export PDF untuk sheet Ringkasan).
B6: 2. Data historis | C6: IS, BS, CF berisi angka laporan (biru) dan subtotal rumus (hitam). Baris 3 menyebut sumber tiap kolom; kolom FY2020 berlatar oranye = kolom pertama (LK FY2020); kolom 2024 dari komparatif LK FY2025 yang disajikan kembali (Temuan S1-S2).
B7: 3. Rincian & rasio | C7: Schedules memuat rincian catatan (CALK) FY2020-2025; bagian A merangkum angka yang dipakai Rasio. Rasio memakai rumus hidup dan kolom rata-rata FY2022-25.
B8: 4. Cek kualitas | C8: Rekonsiliasi: kolom "Sesuai ekspektasi?" harus ✔ untuk semua baris. ❌ yang diharapkan adalah selisih di laporan sumber dan dijelaskan di kolom Penjelasan / sheet Temuan.
B9: 5. Proyeksi ilustratif | C9: Pilih skenario di Asumsi!C4 (Base/Bull/Bear). Ubah sel biru di blok skenario untuk mencoba asumsi sendiri; IS_Proj, BS_Proj, CF_Proj ikut berubah. Cek BS_Proj baris "Cek" harus 0.
B10: 6. Template DCF (opsional) | C10: Isi sendiri sel kuning (Rf, ERP, beta, Kd, pajak, bobot utang, g / kelipatan). Tanpa input, template tidak menghitung apa pun. Hasil adalah keluaran rumus atas input Anda, bukan nilai wajar atau rekomendasi.
B11: 7. Peer | C11: Isi data fundamental pembanding dari laporan publik masing-masing emiten beserta sumbernya. Tidak ada angka pembanding yang dikarang di file ini.
B13: Keterangan warna
B14: Biru | C14: Input / angka dari laporan (bisa diubah)
B15: Hitam | C15: Rumus di sheet yang sama
B16: Hijau | C16: Rumus yang merujuk sheet lain
B17: Kuning | C17: Sel yang perlu diisi/diverifikasi pengguna atau angka yang dikoreksi (ada komentar sel)
B18: Oranye | C18: Kolom FY2020 (kolom pertama) dari LK FY2020
B19: Biru muda | C19: Kolom tahun proyeksi (E) - ilustratif
B21: Definisi penting
B22: EBITDA | C22: Laba usaha dihitung (laba bruto - beban penjualan - beban umum & administrasi + pendapatan lain neto) + penyusutan aset tetap (Cat 27-28) + penyusutan aset hak guna + amortisasi aset takberwujud (Cat 28).
B23: Utang | C23: Utang berbunga: utang bank, pinjaman non-bank, surat utang/obligasi dan utang pembiayaan. Utang neto juga menambahkan liabilitas sewa dan mengurangi kas (negatif = kas neto).
B24: EPS | C24: EPS tercetak memakai saham rata-rata tertimbang (CALK) (Temuan S9).
B25: Satuan | C25: Rupiah penuh kecuali disebut (Ringkasan/Dashboard: Rp miliar). Beban & arus kas keluar bertanda negatif.
B27: Daftar sheet (format ini)
B28: Cover | C28: Sifat dokumen, lisensi, keterangan warna
B29: Panduan | C29: Cara memakai model ini
B30: Ringkasan | C30: Ringkasan siap cetak/PDF (A4): highlights, indikator utama, grafik, tanda perhatian
B31: Dashboard | C31: Indikator & grafik historis + proyeksi ilustratif
B32: Asumsi | C32: Selektor skenario Base/Bull/Bear & driver per tahun, dengan dasar kalibrasi FY2023-2025
B33: IS_Proj | C33: Proyeksi laba rugi (pendapatan per kelompok, EBITDA, laba)
B34: BS_Proj | C34: Proyeksi neraca agregat; kas = penyeimbang; cek balance
B35: CF_Proj | C35: Proyeksi arus kas tidak langsung; FCF
B36: Schedules_Proj | C36: Aset tetap, aset takberwujud, sewa, utang, modal kerja
B37: DCF_Template | C37: Kalkulator DCF opsional dengan input KOSONG (tanpa kesimpulan)
B38: Peer | C38: Tabel pembanding fundamental (input kosong, tanpa kelipatan pasar)
B39: IS | C39: Laba rugi & OCI FY2020-2025
... B47: Data_Log | C47: Sumber per tahun, pemetaan akun, override
B49: Batasan
B50: Data | C50: Angka diekstrak dari PDF dan dapat mengandung kesalahan; cek ke laporan asli sebelum dipakai.
B51: Proyeksi | C51: Asumsi sederhana: pos neraca lain konstan, utang & liabilitas sewa konstan (pembayaran sewa dikapitalisasi ke aset tetap), beban keuangan = suku bunga x rata-rata utang, aset hak guna konstan, tanpa OCI/penurunan nilai baru, tanpa transaksi saham, akuisisi atau pendanaan baru. Hasil sangat sensitif terhadap asumsi.
B52: Bukan saran | C52: Dokumen ini hanya ringkasan informasi dan analisis data fundamental yang bersumber dari laporan keuangan publik (audited) PT Sejahteraraya Anugrahjaya Tbk. Dokumen ini BUKAN saran atau rekomendasi investasi, bukan ajakan membeli, menjual, atau menahan efek apa pun, dan tidak memuat target atau penilaian nilai wajar. Proyeksi bersifat ilustratif dan dapat berbeda jauh dari realisasi. Data dapat mengandung kesalahan ekstraksi; selalu cek ke laporan asli. Dokumen ini disusun dengan bantuan kecerdasan buatan (AI) dari laporan keuangan publik; kemungkinan kesalahan tetap ada, harap verifikasi ke sumber.

Sheet Ringkasan
B1: Mayapada Hospital (SRAJ) | Ringkasan FY2020-FY2025
B2: Jaringan rumah sakit swasta Mayapada Hospital (Jakarta, Tangerang, Bogor, Surabaya, Bandung) | sumber: laporan keuangan konsolidasian audited | gratis & terbuka | BUKAN rekomendasi investasi
B4: Penting: Dokumen ini hanya ringkasan informasi dan analisis data fundamental yang bersumber dari laporan keuangan publik (audited) PT Sejahteraraya Anugrahjaya Tbk. Dokumen ini BUKAN saran atau rekomendasi investasi, bukan ajakan membeli, menjual, atau menahan efek apa pun, dan tidak memuat target atau penilaian nilai wajar. Proyeksi bersifat ilustratif dan dapat berbeda jauh dari realisasi. Data dapat mengandung kesalahan ekstraksi; selalu cek ke laporan asli. Dokumen ini disusun dengan bantuan kecerdasan buatan (AI) dari laporan keuangan publik; kemungkinan kesalahan tetap ada, harap verifikasi ke sumber.
B6: Ringkasan Eksekutif / Highlights
B7: • Pendapatan FY2025 Rp2.589 miliar (+10,6% vs FY2024, basis neto agen): obat & perlengkapan medis Rp1.292 miliar, rawat inap Rp1.400 miliar, rawat jalan & penunjang Rp810 miliar, dikurangi jasa tenaga ahli (agen) & diskon Rp912 miliar.
B8: • Pendapatan tercetak naik dari Rp1.284 miliar (FY2020) ke Rp2.503 miliar (FY2023, bruto); 2024 disajikan kembali menjadi Rp2.340 miliar karena jasa dokter dicatat neto (agen).
B9: • Rugi pemilik induk FY2025 Rp199,0 miliar (EPS Rp-16,31) vs Rp-23,5 miliar FY2024; margin laba bersih -7,7%. Beban keuangan FY2025 Rp388 miliar.
B10: • Utang berbunga Rp4.684 miliar vs kas Rp1.826 miliar (FY2025), naik dari Rp1.072 miliar (FY2020) untuk ekspansi rumah sakit (termasuk surat utang 2025); utang neto / EBITDA 6,1x.
B11: • Data 6 tahun direkonsiliasi dengan 330 cek; 5 selisih di laporan sumber sudah diperkirakan dan dijelaskan (lihat tanda perhatian & sheet Temuan).
B13: Indikator utama (Rp miliar, kecuali disebut lain) - rumus hidup dari sheet IS/BS/CF/Rasio
B14: Indikator | C14: FY2020A | D14: FY2021A | E14: FY2022A | F14: FY2023A | G14: FY2024A | H14: FY2025A
B15: Pendapatan | C15: =IS!C6/1000000000 -> 1283.7986 | D15: =IS!D6/1000000000 -> 1924.4531 | E15: =IS!E6/1000000000 -> 1934.1637 | F15: =IS!F6/1000000000 -> 2503.174 | G15: =IS!G6/1000000000 -> 2340.431 | H15: =IS!H6/1000000000 -> 2589.44
B16: Pertumbuhan | D16: =Rasio!D6 -> 0.4990304 | E16: =Rasio!E6 -> 0.0050458698 | F16: =Rasio!F6 -> 0.29418933 | G16: =Rasio!G6 -> -0.065014657 | H16: =Rasio!H6 -> 0.10639451
B17: Porsi obat & perlengkapan medis | C17: =Rasio!C26 -> 0.19780117 | D17: =Rasio!D26 -> 0.21709091 | E17: =Rasio!E26 -> 0.22323405 | F17: =Rasio!F26 -> 0.30145088 | G17: =Rasio!G26 -> 0.49735369 | H17: =Rasio!H26 -> 0.49884145
B18: EBITDA | C18: =Rasio!C16/1000000000 -> 176.84041 | D18: =Rasio!D16/1000000000 -> 431.70323 | E18: =Rasio!E16/1000000000 -> 268.70754 | F18: =Rasio!F16/1000000000 -> 402.552 | G18: =Rasio!G16/1000000000 -> 484.442 | H18: =Rasio!H16/1000000000 -> 466.738
B19: Margin EBITDA | C19: =Rasio!C17 -> 0.13774778 | D19: =Rasio!D17 -> 0.22432515 | E19: =Rasio!E17 -> 0.13892699 | F19: =Rasio!F17 -> 0.16081663 | G19: =Rasio!G17 -> 0.20698837 | H19: =Rasio!H17 -> 0.18024669
B20: Laba tahun berjalan | C20: =IS!C19/1000000000 -> -14.498058 | D20: =IS!D19/1000000000 -> 165.60405 | E20: =IS!E19/1000000000 -> -44.187231 | F20: =IS!F19/1000000000 -> -38.313 | G20: =IS!G19/1000000000 -> -23.344 | H20: =IS!H19/1000000000 -> -198.79
B21: Laba pemilik entitas induk | C21: =IS!C26/1000000000 -> -14.380627 | D21: =IS!D26/1000000000 -> 165.30824 | E21: =IS!E26/1000000000 -> -44.314949 | F21: =IS!F26/1000000000 -> -38.49 | G21: =IS!G26/1000000000 -> -23.513 | H21: =IS!H26/1000000000 -> -199
B22: Porsi laba ke NCI | C22: =Rasio!C23 -> 0.0080997698 | D22: =Rasio!D23 -> 0.0017862363 | E22: =Rasio!E23 -> -0.0028903894 | F22: =Rasio!F23 -> -0.0046198418 | G22: =Rasio!G23 -> -0.0072395476 | H22: =Rasio!H23 -> -0.0010563912
B23: ROE (rata-rata ekuitas induk) | D23: =Rasio!D20 -> 0.089835082 | E23: =Rasio!E20 -> -0.023200175 | F23: =Rasio!F20 -> -0.020528177 | G23: =Rasio!G20 -> -0.012756941 | H23: =Rasio!H20 -> -0.12583619
B24: Arus kas operasi | C24: =CF!C13/1000000000 -> 93.881891 | D24: =CF!D13/1000000000 -> 336.78666 | E24: =CF!E13/1000000000 -> 210.47482 | F24: =CF!F13/1000000000 -> 55.917 | G24: =CF!G13/1000000000 -> 273.248 | H24: =CF!H13/1000000000 -> 129.67
B25: Capex | C25: =Rasio!C41/1000000000 -> 544.12234 | D25: =Rasio!D41/1000000000 -> 464.02328 | E25: =Rasio!E41/1000000000 -> 655.54652 | F25: =Rasio!F41/1000000000 -> 583.532 | G25: =Rasio!G41/1000000000 -> 525.029 | H25: =Rasio!H41/1000000000 -> 579.605
B26: Utang neto (utang + sewa - kas) | C26: =Rasio!C36/1000000000 -> 442.64253 | D26: =Rasio!D36/1000000000 -> 145.27236 | E26: =Rasio!E36/1000000000 -> 607.05664 | F26: =Rasio!F36/1000000000 -> 1135.049 | G26: =Rasio!G36/1000000000 -> 1391.934 | H26: =Rasio!H36/1000000000 -> 2865.829
B27: Utang neto / EBITDA (x) | C27: =Rasio!C38 -> 2.5030622 | D27: =Rasio!D38 -> 0.33650978 | E27: =Rasio!E38 -> 2.2591723 | F27: =Rasio!F38 -> 2.8196332 | G27: =Rasio!G38 -> 2.8732728 | H27: =Rasio!H38 -> 6.1401236
B28: DSO piutang (hari) | C28: =Rasio!C28 -> 64.090527 | D28: =Rasio!D28 -> 44.362731 | E28: =Rasio!E28 -> 45.853511 | F28: =Rasio!F28 -> 57.643682 | G28: =Rasio!G28 -> 66.171047 | H28: =Rasio!H28 -> 78.644628
B29: Tarif pajak efektif | C29: =Rasio!C22 -> 76.751242 | D29: =Rasio!D22 -> -0.058717335 | E29: =Rasio!E22 -> -0.049904963 | F29: =Rasio!F22 -> -0.22440957 | G29: =Rasio!G22 -> -7.8424242 | H29: =Rasio!H22 -> 0.1546966
B30: Catatan: tiap kolom dari LK tahun itu (dasar asli); 2024 = komparatif LK FY2025 yang disajikan kembali (PSAK 115: Grup sebagai agen atas jasa dokter), sehingga pendapatan & margin bruto 2020-2023 (basis bruto) tidak sebanding dengan 2024-2025. Laba usaha tidak dicetak di LK dan dihitung model. (Temuan S1-S4)
B32: Tren 5 tahun
B50: Batang = pendapatan per kelompok (Cat 26; lainnya = administrasi & operasional lain dikurangi diskon); garis putus-putus = porsi obat & perlengkapan medis terhadap pendapatan (sumbu kanan).
B68: Kiri: margin terhadap pendapatan. Kanan: arus kas operasi (abu-abu), capex (arsir), pembayaran sewa (titik), dan sisanya (garis).
B86: Tanda perhatian dari laporan keuangan (bahasa sederhana)
B87: 1. Rugi berulang - Grup rugi bersih pada 2020 dan 2022-2025 (2025 rugi sekitar Rp199 miliar), hanya 2021 laba; tidak ada dividen. (Temuan S9)
B88: 2. Utang & beban bunga naik tajam - Utang berbunga (termasuk surat utang 2025) naik tajam; beban keuangan 2025 sekitar Rp388 miliar. Proyeksi Base dapat menunjukkan kebutuhan pendanaan. (Temuan S6)
B89: 3. Penyajian kembali 2024 - LK FY2025 menyajikan kembali 2024: jasa dokter dicatat neto (agen), pendapatan turun sekitar Rp808 miliar tanpa mengubah laba; 2020-2023 masih bruto. (Temuan S2)
B90: 4. Pihak berelasi - Utang lain-lain kepada pihak berelasi besar (sekitar Rp1,0-1,5 triliun) dan menjadi sumber pendanaan. (Temuan S7)
B91: 5. Definisi kas & kategori pendapatan - Kas di laporan arus kas berbeda dengan kas neraca pada beberapa tahun (cerukan, penyajian kembali); kategori pendapatan berubah di LK FY2023. (Temuan S3, S5)
B92: 6. Proyeksi ilustratif - Skenario Base/Bull/Bear bukan perkiraan; tidak ada target harga atau nilai wajar.
B93: Detail lengkap ada di sheet Temuan dan Rekonsiliasi. Tanda perhatian bukan tuduhan kecurangan; ini daftar hal yang perlu dicek ulang ke laporan asli.
... B103: Dokumen ini hanya ringkasan informasi dan analisis data fundamental yang bersumber dari laporan keuangan publik (audited) PT Sejahteraraya Anugrahjaya Tbk. Dokumen ini BUKAN saran atau rekomendasi investasi, bukan ajakan membeli, menjual, atau menahan efek apa pun, dan tidak memuat target atau penilaian nilai wajar. Proyeksi bersifat ilustratif dan dapat berbeda jauh dari realisasi. Data dapat mengandung kesalahan ekstraksi; selalu cek ke laporan asli. Dokumen ini disusun dengan bantuan kecerdasan buatan (AI) dari laporan keuangan publik; kemungkinan kesalahan tetap ada, harap verifikasi ke sumber. Penyusun tidak bertanggung jawab atas keputusan apa pun yang diambil berdasarkan dokumen ini. Dokumen ini disusun pada 26-10-2026.

Sheet Dashboard
A1: Dashboard - historis FY2020-FY2025 & proyeksi ilustratif FY2026-FY2030 (skenario aktif)
A2: Rp miliar. Kolom E = Proyeksi ILUSTRATIF berbasis asumsi transparan - bukan rekomendasi investasi, bukan target, bukan nilai wajar. Tidak ada nilai per saham/target di sheet ini.
B3: Skenario aktif: | C3: =Asumsi!C4 -> Base
B4: Indikator | C4: FY2020A | D4: FY2021A | E4: FY2022A | F4: FY2023A | G4: FY2024A | H4: FY2025A | I4: FY2026E | J4: FY2027E | K4: FY2028E | L4: FY2029E | M4: FY2030E | N4: Catatan
B5: Pendapatan neto | C5: =IS_Proj!C10/1000000000 -> 1283.7986 | D5: =IS_Proj!D10/1000000000 -> 1924.4531 | E5: =IS_Proj!E10/1000000000 -> 1934.1637 | F5: =IS_Proj!F10/1000000000 -> 2503.174 | G5: =IS_Proj!G10/1000000000 -> 2340.431 | H5: =IS_Proj!H10/1000000000 -> 2589.44 | I5: =IS_Proj!I10/1000000000 -> 2829.5602 | J5: =IS_Proj!J10/1000000000 -> 3090.1339 | ... M5: =IS_Proj!M10/1000000000 -> 4026.8064
B6: Pertumbuhan pendapatan | D6: =IS_Proj!D11 -> 0.4990304 | E6: =IS_Proj!E11 -> 0.0050458698 | F6: =IS_Proj!F11 -> 0.29418933 | G6: =IS_Proj!G11 -> -0.065014657 | H6: =IS_Proj!H11 -> 0.10639451 | I6: =IS_Proj!I11 -> 0.092730535 | J6: =IS_Proj!J11 -> 0.092089837 | K6: =IS_Proj!K11 -> 0.092177405 | ... M6: =IS_Proj!M11 -> 0.092351482
B7: EBITDA | C7: =IS_Proj!C17/1000000000 -> 176.84041 | D7: =IS_Proj!D17/1000000000 -> 431.70323 | E7: =IS_Proj!E17/1000000000 -> 268.70754 | F7: =IS_Proj!F17/1000000000 -> 402.552 | G7: =IS_Proj!G17/1000000000 -> 484.442 | H7: =IS_Proj!H17/1000000000 -> 466.738 | I7: =IS_Proj!I17/1000000000 -> 591.37807 | J7: =IS_Proj!J17/1000000000 -> 645.83798 | ... M7: =IS_Proj!M17/1000000000 -> 841.60255
B8: Margin EBITDA | C8: =IS_Proj!C30 -> 0.13774778 | D8: =IS_Proj!D30 -> 0.22432515 | E8: =IS_Proj!E30 -> 0.13892699 | F8: =IS_Proj!F30 -> 0.16081663 | G8: =IS_Proj!G30 -> 0.20698837 | H8: =IS_Proj!H30 -> 0.18024669 | I8: =IS_Proj!I30 -> 0.209 | J8: =IS_Proj!J30 -> 0.209 | ... M8: =IS_Proj!M30 -> 0.209
B9: Laba tahun berjalan | C9: =IS_Proj!C24/1000000000 -> -14.498058 | D9: =IS_Proj!D24/1000000000 -> 165.60405 | E9: =IS_Proj!E24/1000000000 -> -44.187231 | F9: =IS_Proj!F24/1000000000 -> -38.313 | G9: =IS_Proj!G24/1000000000 -> -23.344 | H9: =IS_Proj!H24/1000000000 -> -198.79 | I9: =IS_Proj!I24/1000000000 -> -133.78239 | J9: =IS_Proj!J24/1000000000 -> -110.28182 | ... M9: =IS_Proj!M24/1000000000 -> -32.064487
B10: Laba pemilik entitas induk | C10: =IS_Proj!C26/1000000000 -> -14.380627 | D10: =IS_Proj!D26/1000000000 -> 165.30824 | E10: =IS_Proj!E26/1000000000 -> -44.314949 | F10: =IS_Proj!F26/1000000000 -> -38.49 | G10: =IS_Proj!G26/1000000000 -> -23.513 | H10: =IS_Proj!H26/1000000000 -> -199 | I10: =IS_Proj!I26/1000000000 -> -133.78239 | J10: =IS_Proj!J26/1000000000 -> -110.28182 | ... M10: =IS_Proj!M26/1000000000 -> -32.064487
B11: Arus kas operasi | C11: =CF_Proj!C11/1000000000 -> 93.881891 | D11: =CF_Proj!D11/1000000000 -> 336.78666 | E11: =CF_Proj!E11/1000000000 -> 210.47482 | F11: =CF_Proj!F11/1000000000 -> 55.917 | G11: =CF_Proj!G11/1000000000 -> 273.248 | H11: =CF_Proj!H11/1000000000 -> 129.67 | I11: =CF_Proj!I11/1000000000 -> 205.27465 | J11: =CF_Proj!J11/1000000000 -> 231.9646 | ... M11: =CF_Proj!M11/1000000000 -> 328.82262
B12: Capex | C12: =CF_Proj!C13/1000000000 -> -544.12234 | D12: =CF_Proj!D13/1000000000 -> -464.02328 | E12: =CF_Proj!E13/1000000000 -> -655.54652 | F12: =CF_Proj!F13/1000000000 -> -583.532 | G12: =CF_Proj!G13/1000000000 -> -525.029 | H12: =CF_Proj!H13/1000000000 -> -584.29 | I12: =CF_Proj!I13/1000000000 -> -424.43402 | J12: =CF_Proj!J13/1000000000 -> -463.52008 | ... M12: =CF_Proj!M13/1000000000 -> -604.02097
B13: FCF setelah sewa | C13: =CF_Proj!C28/1000000000 -> -786.93779 | D13: =CF_Proj!D28/1000000000 -> -130.40213 | E13: =CF_Proj!E28/1000000000 -> -449.41567 | F13: =CF_Proj!F28/1000000000 -> -533.388 | G13: =CF_Proj!G28/1000000000 -> -260.057 | H13: =CF_Proj!H28/1000000000 -> -484.436 | I13: =CF_Proj!I28/1000000000 -> -255.58119 | J13: =CF_Proj!J28/1000000000 -> -268.08153 | ... M13: =CF_Proj!M28/1000000000 -> -312.09906
B14: Kas akhir | C14: =BS_Proj!C6/1000000000 -> 629.60869 | D14: =BS_Proj!D6/1000000000 -> 700.92236 | E14: =BS_Proj!E6/1000000000 -> 1118.2543 | F14: =BS_Proj!F6/1000000000 -> 515.185 | G14: =BS_Proj!G6/1000000000 -> 277.208 | H14: =BS_Proj!H6/1000000000 -> 1826.263 | I14: =BS_Proj!I6/1000000000 -> 1570.6818 | J14: =BS_Proj!J6/1000000000 -> 1302.6003 | ... M14: =BS_Proj!M6/1000000000 -> 410.86524
B15: Utang neto (utang + sewa - kas) | C15: =BS_Proj!C31/1000000000 -> 442.64253 | D15: =BS_Proj!D31/1000000000 -> 145.27236 | E15: =BS_Proj!E31/1000000000 -> 607.05664 | F15: =BS_Proj!F31/1000000000 -> 1135.049 | G15: =BS_Proj!G31/1000000000 -> 1391.934 | H15: =BS_Proj!H31/1000000000 -> 2865.829 | I15: =BS_Proj!I31/1000000000 -> 3121.4102 | J15: =BS_Proj!J31/1000000000 -> 3389.4917 | ... M15: =BS_Proj!M31/1000000000 -> 4281.2268
B16: Utang neto / EBITDA | C16: =BS_Proj!C33 -> 2.5030622 | D16: =BS_Proj!D33 -> 0.33650978 | E16: =BS_Proj!E33 -> 2.2591723 | F16: =BS_Proj!F33 -> 2.8196332 | G16: =BS_Proj!G33 -> 2.8732728 | H16: =BS_Proj!H33 -> 6.1401236 | I16: =BS_Proj!I33 -> 5.2781974 | J16: =BS_Proj!J33 -> 5.2482075 | ... M16: =BS_Proj!M33 -> 5.0869936
B17: ROE | D17: =BS_Proj!D32 -> 0.089835082 | E17: =BS_Proj!E32 -> -0.023200175 | F17: =BS_Proj!F32 -> -0.020528177 | G17: =BS_Proj!G32 -> -0.012756941 | H17: =BS_Proj!H32 -> -0.12583619 | I17: =BS_Proj!I32 -> -0.10569844 | J17: =BS_Proj!J32 -> -0.096428286 | K17: =BS_Proj!K32 -> -0.081926611 | ... M17: =BS_Proj!M32 -> -0.034585997
B18: Cek balance BS_Proj (harus 0) | C18: =BS_Proj!C30 -> 0 | D18: =BS_Proj!D30 -> 0 | E18: =BS_Proj!E30 -> 0 | F18: =BS_Proj!F30 -> 0 | G18: =BS_Proj!G30 -> 0 | H18: =BS_Proj!H30 -> 0 | I18: =BS_Proj!I30 -> 0 | J18: =BS_Proj!J30 -> 0 | ... M18: =BS_Proj!M30 -> 0
B19: Status rekonsiliasi | C19: =Rekonsiliasi!$C$3 -> SEMUA 330 CEK SESUAI EKSPEKTASI

Sheet Asumsi
A1: Asumsi proyeksi ilustratif FY2026E-FY2030E (Base / Bull / Bear)
A2: Proyeksi ILUSTRATIF berbasis asumsi transparan - bukan rekomendasi investasi, bukan target, bukan nilai wajar.
A4: Skenario aktif | C4: Base | D4: =IF(C4="Bull",2,IF(C4="Bear",3,1)) -> 1 | E4: <- pilih Base / Bull / Bear. Kolom historis = aktual (rumus dari IS/BS/CF/Schedules); kolom E = asumsi skenario aktif.
A5: Kalibrasi | C5: Margin & modal kerja dikalibrasi dari FY2024-FY2025 (basis agen/neto setelah penyajian kembali PSAK 115). FY2020-2023 basis bruto (jasa dokter di pendapatan & beban pokok) tidak dipakai sebagai patokan margin.
A7: Kunci | B7: Driver | C7: FY2020A | D7: FY2021A | E7: FY2022A | F7: FY2023A | G7: FY2024A | H7: FY2025A | I7: FY2026E | J7: FY2027E | K7: FY2028E | L7: FY2029E | M7: FY2030E | N7: Dasar asumsi (kalibrasi FY2022-FY2025)
B8: ASUMSI AKTIF - kolom historis = aktual (rumus), kolom E = skenario terpilih
B9: PENDAPATAN (per kelompok, Cat 26)
A10: g_med | B10: Pertumbuhan pendapatan obat & perlengkapan medis | D10: =IFERROR(Schedules!D6/Schedules!C6-1,"") -> 0.64521714 | E10: =IFERROR(Schedules!E6/Schedules!D6-1,"") -> 0.033486197 | F10: =IFERROR(Schedules!F6/Schedules!E6-1,"") -> 0.74764788 | G10: =IFERROR(Schedules!G6/Schedules!F6-1,"") -> 0.54260096 | H10: =IFERROR(Schedules!H6/Schedules!G6-1,"") -> 0.10970411 | I10: =CHOOSE(Asumsi!$D$4,I38,I65,I92) -> 0.1 | J10: =CHOOSE(Asumsi!$D$4,J38,J65,J92) -> 0.1 | K10: =CHOOSE(Asumsi!$D$4,K38,K65,K92) -> 0.1 | L10: =CHOOSE(Asumsi!$D$4,L38,L65,L92) -> 0.1 | M10: =CHOOSE(Asumsi!$D$4,M38,M65,M92) -> 0.1 | N10: Pendapatan: 2022 432 M, 2023 755 M, 2024 1.164 M, 2025 1.292 M. CAGR 2023-25 30,8%. Base 10%; Bull 14%; Bear 5%.
A11: g_inpat | B11: Pertumbuhan pendapatan rawat inap (bruto sebelum pengurang agen) | D11: =IFERROR(Schedules!D7/Schedules!C7-1,"") -> 0.61122023 | E11: =IFERROR(Schedules!E7/Schedules!D7-1,"") -> 0.084318065 | F11: =IFERROR(Schedules!F7/Schedules!E7-1,"") -> 0.30407456 | G11: =IFERROR(Schedules!G7/Schedules!F7-1,"") -> 0.25075627 | H11: =IFERROR(Schedules!H7/Schedules!G7-1,"") -> 0.050800054 | I11: =CHOOSE(Asumsi!$D$4,I39,I66,I93) -> 0.08 | J11: =CHOOSE(Asumsi!$D$4,J39,J66,J93) -> 0.08 | K11: =CHOOSE(Asumsi!$D$4,K39,K66,K93) -> 0.08 | L11: =CHOOSE(Asumsi!$D$4,L39,L66,L93) -> 0.08 | M11: =CHOOSE(Asumsi!$D$4,M39,M66,M93) -> 0.08 | N11: Pendapatan: 2022 817 M, 2023 1.065 M, 2024 1.333 M, 2025 1.400 M. CAGR 2023-25 14,6%. Base 8%; Bull 12%; Bear 4%.
A12: g_outpat | B12: Pertumbuhan pendapatan rawat jalan & penunjang (bruto) | D12: =IFERROR(Schedules!D8/Schedules!C8-1,"") -> 0.32221062 | E12: =IFERROR(Schedules!E8/Schedules!D8-1,"") -> -0.10684834 | F12: =IFERROR(Schedules!F8/Schedules!E8-1,"") -> -0.030236747 | G12: =IFERROR(Schedules!G8/Schedules!F8-1,"") -> -0.046008458 | H12: =IFERROR(Schedules!H8/Schedules!G8-1,"") -> 0.24218613 | I12: =CHOOSE(Asumsi!$D$4,I40,I67,I94) -> 0.1 | J12: =CHOOSE(Asumsi!$D$4,J40,J67,J94) -> 0.1 | K12: =CHOOSE(Asumsi!$D$4,K40,K67,K94) -> 0.1 | L12: =CHOOSE(Asumsi!$D$4,L40,L67,L94) -> 0.1 | M12: =CHOOSE(Asumsi!$D$4,M40,M67,M94) -> 0.1 | N12: Pendapatan: 2022 704 M, 2023 683 M, 2024 652 M, 2025 810 M. CAGR 2023-25 8,9% (kategori berubah 2023, Temuan S3). Base 10%; Bull 14%; Bear 5%.
A13: rev_oth | B13: Lainnya: diskon & pengurang jasa tenaga ahli/agen (% 3 kelompok bruto) | C13: =IFERROR(Schedules!C9/(Schedules!C6+Schedules!C7+Schedules!C8),"") -> -0.026025415 | D13: =IFERROR(Schedules!D9/(Schedules!D6+Schedules!D7+Schedules!D8),"") -> -0.018128818 | E13: =IFERROR(Schedules!E9/(Schedules!E6+Schedules!E7+Schedules!E8),"") -> -0.0097623541 | F13: =IFERROR(Schedules!F9/(Schedules!F6+Schedules!F7+Schedules!F8),"") -> 0 | G13: =IFERROR(Schedules!G9/(Schedules!G6+Schedules!G7+Schedules!G8),"") -> -0.25661546 | H13: =IFERROR(Schedules!H9/(Schedules!H6+Schedules!H7+Schedules!H8),"") -> -0.26049341 | I13: =CHOOSE(Asumsi!$D$4,I41,I68,I95) -> -0.26 | J13: =CHOOSE(Asumsi!$D$4,J41,J68,J95) -> -0.26 | K13: =CHOOSE(Asumsi!$D$4,K41,K68,K95) -> -0.26 | L13: =CHOOSE(Asumsi!$D$4,L41,L68,L95) -> -0.26 | M13: =CHOOSE(Asumsi!$D$4,M41,M68,M95) -> -0.26 | N13: Historis: 2022 -1,0%, 2023 0,0%, 2024 -25,7%, 2025 -26,0% (2020-23 hanya diskon; 2024-25 pengurang agen PSAK 115, Temuan S2-S3). Semua skenario = rasio 2025.
B14: MARGIN & BIAYA (% pendapatan)
A15: cogs | B15: Beban pokok di luar penyusutan | C15: =IFERROR(-(IS!C7+Schedules!C12+Schedules!C17)/IS!C6,"") -> 0.60810027 | D15: =IFERROR(-(IS!D7+Schedules!D12+Schedules!D17)/IS!D6,"") -> 0.5759391 | E15: =IFERROR(-(IS!E7+Schedules!E12+Schedules!E17)/IS!E6,"") -> 0.6349414 | F15: =IFERROR(-(IS!F7+Schedules!F12+Schedules!F17)/IS!F6,"") -> 0.63567694 | G15: =IFERROR(-(IS!G7+Schedules!G12+Schedules!G17)/IS!G6,"") -> 0.51201937 | H15: =IFERROR(-(IS!H7+Schedules!H12+Schedules!H17)/IS!H6,"") -> 0.49002062 | I15: =CHOOSE(Asumsi!$D$4,I43,I70,I97) -> 0.49 | J15: =CHOOSE(Asumsi!$D$4,J43,J70,J97) -> 0.49 | K15: =CHOOSE(Asumsi!$D$4,K43,K70,K97) -> 0.49 | L15: =CHOOSE(Asumsi!$D$4,L43,L70,L97) -> 0.49 | M15: =CHOOSE(Asumsi!$D$4,M43,M70,M97) -> 0.49 | N15: Historis: 2022 63,5%, 2023 63,6%, 2024 51,2%, 2025 49,0% (2022-23 basis bruto, tidak sebanding). Base = 2025 (49,0%); Bull -1,5 poin; Bear +1,5 poin.
A16: opex | B16: Beban usaha di luar penyusutan, penyusutan aset hak guna & amortisasi | C16: =IFERROR(-(IS!C11+Schedules!C13+Schedules!C16+Schedules!C18)/IS!C6,"") -> 0.27629681 | D16: =IFERROR(-(IS!D11+Schedules!D13+Schedules!D16+Schedules!D18)/IS!D6,"") -> 0.21222146 | E16: =IFERROR(-(IS!E11+Schedules!E13+Schedules!E16+Schedules!E18)/IS!E6,"") -> 0.22828234 | F16: =IFERROR(-(IS!F11+Schedules!F13+Schedules!F16+Schedules!F18)/IS!F6,"") -> 0.20630847 | G16: =IFERROR(-(IS!G11+Schedules!G13+Schedules!G16+Schedules!G18)/IS!G6,"") -> 0.27040575 | H16: =IFERROR(-(IS!H11+Schedules!H13+Schedules!H16+Schedules!H18)/IS!H6,"") -> 0.33084605 | I16: =CHOOSE(Asumsi!$D$4,I44,I71,I98) -> 0.301 | J16: =CHOOSE(Asumsi!$D$4,J44,J71,J98) -> 0.301 | K16: =CHOOSE(Asumsi!$D$4,K44,K71,K98) -> 0.301 | L16: =CHOOSE(Asumsi!$D$4,L44,L71,L98) -> 0.301 | M16: =CHOOSE(Asumsi!$D$4,M44,M71,M98) -> 0.301 | N16: Historis: 2022 22,8%, 2023 20,6%, 2024 27,0%, 2025 33,1% (2025 naik: rumah sakit baru). Base = rata-rata 2024-25 (30,1%); Bull -2 poin; Bear = 2025.
A17: other_op | B17: Pendapatan (beban) lain-lain neto (% pendapatan) | C17: =IFERROR(IS!C13/IS!C6,"") -> 0.022144854 | D17: =IFERROR(IS!D13/IS!D6,"") -> 0.012485705 | E17: =IFERROR(IS!E13/IS!E6,"") -> 0.0021507288 | F17: =IFERROR(IS!F13/IS!F6,"") -> 0.0028020425 | G17: =IFERROR(IS!G13/IS!G6,"") -> -0.010586512 | H17: =IFERROR(IS!H13/IS!H6,"") -> 0.0011133681 | I17: =CHOOSE(Asumsi!$D$4,I45,I72,I99) -> 0 | J17: =CHOOSE(Asumsi!$D$4,J45,J72,J99) -> 0 | K17: =CHOOSE(Asumsi!$D$4,K45,K72,K99) -> 0 | L17: =CHOOSE(Asumsi!$D$4,L45,L72,L99) -> 0 | M17: =CHOOSE(Asumsi!$D$4,M45,M72,M99) -> 0 | N17: Historis: 2022 0,2%, 2023 0,3%, 2024 -1,1%, 2025 0,1% (memuat penurunan nilai piutang & selisih kurs). Base 0%; Bull 0,2%; Bear -0,5%.
B18: INVESTASI & ASET
A19: capex | B19: Capex aset tetap (% pendapatan) | C19: =IFERROR(-(CF!C15+CF!C16)/IS!C6,"") -> 0.42383777 | D19: =IFERROR(-(CF!D15+CF!D16)/IS!D6,"") -> 0.24111955 | E19: =IFERROR(-(CF!E15+CF!E16)/IS!E6,"") -> 0.33893022 | F19: =IFERROR(-(CF!F15+CF!F16)/IS!F6,"") -> 0.23311683 | G19: =IFERROR(-(CF!G15+CF!G16)/IS!G6,"") -> 0.22433005 | H19: =IFERROR(-(CF!H15+CF!H16)/IS!H6,"") -> 0.22383411 | I19: =CHOOSE(Asumsi!$D$4,I47,I74,I101) -> 0.15 | J19: =CHOOSE(Asumsi!$D$4,J47,J74,J101) -> 0.15 | K19: =CHOOSE(Asumsi!$D$4,K47,K74,K101) -> 0.15 | L19: =CHOOSE(Asumsi!$D$4,L47,L74,L101) -> 0.15 | M19: =CHOOSE(Asumsi!$D$4,M47,M74,M101) -> 0.15 | N19: Historis kas: 2022 33,9%, 2023 23,3%, 2024 22,4%, 2025 22,4% (pembangunan rumah sakit baru). Base 15%; Bull 12%; Bear 20%.
A20: lease_pd | B20: Pembayaran sewa dikapitalisasi ke aset tetap (% pendapatan) | C20: =IFERROR(-CF!C35/IS!C6,"") -> 0.25704966 | D20: =IFERROR(-CF!D35/IS!D6,"") -> 0 | E20: =IFERROR(-CF!E35/IS!E6,"") -> 0 | F20: =IFERROR(-CF!F35/IS!F6,"") -> 0.00028244141 | G20: =IFERROR(-CF!G35/IS!G6,"") -> 0.00030250838 | H20: =IFERROR(-CF!H35/IS!H6,"") -> 0.00061750803 | I20: =CHOOSE(Asumsi!$D$4,I48,I75,I102) -> 0.0004 | J20: =CHOOSE(Asumsi!$D$4,J48,J75,J102) -> 0.0004 | K20: =CHOOSE(Asumsi!$D$4,K48,K75,K102) -> 0.0004 | L20: =CHOOSE(Asumsi!$D$4,L48,L75,L102) -> 0.0004 | M20: =CHOOSE(Asumsi!$D$4,M48,M75,M102) -> 0.0004 | N20: Historis: 2022 0,0%, 2023 0,0%, 2024 0,0%, 2025 0,1%. Base/Bull/Bear = rata-rata 2023-25; liabilitas sewa & aset hak guna konstan.
A21: dep | B21: Penyusutan aset tetap + aset hak guna (% aset tetap neto awal) | D21: =IFERROR((Schedules!D14+Schedules!D16)/BS!C19,"") -> 0.06688873 | E21: =IFERROR((Schedules!E14+Schedules!E16)/BS!D19,"") -> 0.071688859 | F21: =IFERROR((Schedules!F14+Schedules!F16)/BS!E19,"") -> 0.078537243 | G21: =IFERROR((Schedules!G14+Schedules!G16)/BS!F19,"") -> 0.080706432 | H21: =IFERROR((Schedules!H14+Schedules!H16)/BS!G19,"") -> 0.087860639 | I21: =CHOOSE(Asumsi!$D$4,I49,I76,I103) -> 0.0824 | J21: =CHOOSE(Asumsi!$D$4,J49,J76,J103) -> 0.0824 | K21: =CHOOSE(Asumsi!$D$4,K49,K76,K103) -> 0.0824 | L21: =CHOOSE(Asumsi!$D$4,L49,L76,L103) -> 0.0824 | M21: =CHOOSE(Asumsi!$D$4,M49,M76,M103) -> 0.0824 | N21: Historis: 2022 7,2%, 2023 7,9%, 2024 8,1%, 2025 8,8%. Base/Bull/Bear = rata-rata 2023-25.
A22: sw | B22: Amortisasi aset takberwujud (% saldo awal) | D22: =IFERROR(Schedules!D19/BS!C22,"") -> 0.44820278 | E22: =IFERROR(Schedules!E19/BS!D22,"") -> 0.34947122 | F22: =IFERROR(Schedules!F19/BS!E22,"") -> 0.46646772 | G22: =IFERROR(Schedules!G19/BS!F22,"") -> 0.65616241 | H22: =IFERROR(Schedules!H19/BS!G22,"") -> 1.3246384 | I22: =CHOOSE(Asumsi!$D$4,I50,I77,I104) -> 1.3246 | J22: =CHOOSE(Asumsi!$D$4,J50,J77,J104) -> 1.3246 | K22: =CHOOSE(Asumsi!$D$4,K50,K77,K104) -> 1.3246 | L22: =CHOOSE(Asumsi!$D$4,L50,L77,L104) -> 1.3246 | M22: =CHOOSE(Asumsi!$D$4,M50,M77,M104) -> 1.3246 | N22: Historis: 2022 34,9%, 2023 46,6%, 2024 65,6%, 2025 132,5%. Penambahan E = amortisasi (saldo konstan). Base/Bull/Bear = 2025.
B23: MODAL KERJA (hari, saldo akhir, basis 365)
A24: dso | B24: DSO piutang usaha / pendapatan | C24: =IFERROR((BS!C8+BS!C9)/IS!C6*365,"") -> 64.090527 | D24: =IFERROR((BS!D8+BS!D9)/IS!D6*365,"") -> 44.362731 | E24: =IFERROR((BS!E8+BS!E9)/IS!E6*365,"") -> 45.853511 | F24: =IFERROR((BS!F8+BS!F9)/IS!F6*365,"") -> 57.643682 | G24: =IFERROR((BS!G8+BS!G9)/IS!G6*365,"") -> 66.171047 | H24: =IFERROR((BS!H8+BS!H9)/IS!H6*365,"") -> 78.644628 | I24: =CHOOSE(Asumsi!$D$4,I52,I79,I106) -> 79 | J24: =CHOOSE(Asumsi!$D$4,J52,J79,J106) -> 79 | K24: =CHOOSE(Asumsi!$D$4,K52,K79,K106) -> 79 | L24: =CHOOSE(Asumsi!$D$4,L52,L79,L106) -> 79 | M24: =CHOOSE(Asumsi!$D$4,M52,M79,M106) -> 79 | N24: Historis: 2022 45,9, 2023 57,6, 2024 66,2, 2025 78,6 (piutang asuransi/korporasi/BPJS; 2024-25 atas pendapatan neto agen). Base = 2025; Bull -5; Bear +10.
A25: dio | B25: DIO persediaan / beban pokok di luar penyusutan | C25: =IFERROR(BS!C12/-(IS!C7+Schedules!C12+Schedules!C17)*365,"") -> 34.921294 | D25: =IFERROR(BS!D12/-(IS!D7+Schedules!D12+Schedules!D17)*365,"") -> 23.186631 | E25: =IFERROR(BS!E12/-(IS!E7+Schedules!E12+Schedules!E17)*365,"") -> 14.748203 | F25: =IFERROR(BS!F12/-(IS!F7+Schedules!F12+Schedules!F17)*365,"") -> 11.226111 | G25: =IFERROR(BS!G12/-(IS!G7+Schedules!G12+Schedules!G17)*365,"") -> 18.676025 | H25: =IFERROR(BS!H12/-(IS!H7+Schedules!H12+Schedules!H17)*365,"") -> 21.091763 | I25: =CHOOSE(Asumsi!$D$4,I53,I80,I107) -> 21 | J25: =CHOOSE(Asumsi!$D$4,J53,J80,J107) -> 21 | K25: =CHOOSE(Asumsi!$D$4,K53,K80,K107) -> 21 | L25: =CHOOSE(Asumsi!$D$4,L53,L80,L107) -> 21 | M25: =CHOOSE(Asumsi!$D$4,M53,M80,M107) -> 21 | N25: Historis: 2022 14,7, 2023 11,2, 2024 18,7, 2025 21,1. Base = 2025; Bull -2; Bear +4.
A26: dpo | B26: DPO utang usaha / beban pokok di luar penyusutan | C26: =IFERROR((BS!C30+BS!C31)/-(IS!C7+Schedules!C12+Schedules!C17)*365,"") -> 81.916469 | D26: =IFERROR((BS!D30+BS!D31)/-(IS!D7+Schedules!D12+Schedules!D17)*365,"") -> 63.327242 | E26: =IFERROR((BS!E30+BS!E31)/-(IS!E7+Schedules!E12+Schedules!E17)*365,"") -> 48.145702 | F26: =IFERROR((BS!F30+BS!F31)/-(IS!F7+Schedules!F12+Schedules!F17)*365,"") -> 32.274954 | G26: =IFERROR((BS!G30+BS!G31)/-(IS!G7+Schedules!G12+Schedules!G17)*365,"") -> 47.574582 | H26: =IFERROR((BS!H30+BS!H31)/-(IS!H7+Schedules!H12+Schedules!H17)*365,"") -> 32.7467 | I26: =CHOOSE(Asumsi!$D$4,I54,I81,I108) -> 33 | J26: =CHOOSE(Asumsi!$D$4,J54,J81,J108) -> 33 | K26: =CHOOSE(Asumsi!$D$4,K54,K81,K108) -> 33 | L26: =CHOOSE(Asumsi!$D$4,L54,L81,L108) -> 33 | M26: =CHOOSE(Asumsi!$D$4,M54,M81,M108) -> 33 | N26: Historis: 2022 48,1, 2023 32,3, 2024 47,6, 2025 32,7 (termasuk utang jasa dokter). Base = 2025; Bull +10; Bear -15.
B27: PAJAK, PENDANAAN, DISTRIBUSI
A28: tax | B28: Tarif pajak efektif (% laba sebelum pajak) | C28: =IFERROR(-IS!C18/IS!C17,"") -> 76.751242 | D28: =IFERROR(-IS!D18/IS!D17,"") -> -0.058717335 | E28: =IFERROR(-IS!E18/IS!E17,"") -> -0.049904963 | F28: =IFERROR(-IS!F18/IS!F17,"") -> -0.22440957 | G28: =IFERROR(-IS!G18/IS!G17,"") -> -7.8424242 | H28: =IFERROR(-IS!H18/IS!H17,"") -> 0.1546966 | I28: =CHOOSE(Asumsi!$D$4,I56,I83,I110) -> 0.25 | J28: =CHOOSE(Asumsi!$D$4,J56,J83,J110) -> 0.25 | K28: =CHOOSE(Asumsi!$D$4,K56,K83,K110) -> 0.25 | L28: =CHOOSE(Asumsi!$D$4,L56,L83,L110) -> 0.25 | M28: =CHOOSE(Asumsi!$D$4,M56,M83,M110) -> 0.25 | N28: Historis: 2022 -5,0%, 2023 -22,4%, 2024 -784,2%, 2025 15,5% (rugi sebelum pajak 2022-25 membuat tarif efektif tidak bermakna, Temuan S9). Base 25%; Bull 22%; Bear 30% (tarif normatif 22% + beban tidak dapat dikurangkan; manfaat pajak saat rugi).
A29: fin_cost | B29: Suku bunga efektif (beban keuangan / rata-rata utang berbunga) | D29: =IFERROR(-IS!D15/AVERAGE((BS!D29+BS!D38+BS!D45+BS!D39+BS!D46+BS!D40+BS!D47+BS!D41+BS!D48),(BS!C29+BS!C38+BS!C45+BS!C39+BS!C46+BS!C40+BS!C47+BS!C41+BS!C48)),"") -> 0.12305174 | E29: =IFERROR(-IS!E15/AVERAGE((BS!E29+BS!E38+BS!E45+BS!E39+BS!E46+BS!E40+BS!E47+BS!E41+BS!E48),(BS!D29+BS!D38+BS!D45+BS!D39+BS!D46+BS!D40+BS!D47+BS!D41+BS!D48)),"") -> 0.07518173 | F29: =IFERROR(-IS!F15/AVERAGE((BS!F29+BS!F38+BS!F45+BS!F39+BS!F46+BS!F40+BS!F47+BS!F41+BS!F48),(BS!E29+BS!E38+BS!E45+BS!E39+BS!E46+BS!E40+BS!E47+BS!E41+BS!E48)),"") -> 0.10302659 | G29: =IFERROR(-IS!G15/AVERAGE((BS!G29+BS!G38+BS!G45+BS!G39+BS!G46+BS!G40+BS!G47+BS!G41+BS!G48),(BS!F29+BS!F38+BS!F45+BS!F39+BS!F46+BS!F40+BS!F47+BS!F41+BS!F48)),"") -> 0.10498311 | H29: =IFERROR(-IS!H15/AVERAGE((BS!H29+BS!H38+BS!H45+BS!H39+BS!H46+BS!H40+BS!H47+BS!H41+BS!H48),(BS!G29+BS!G38+BS!G45+BS!G39+BS!G46+BS!G40+BS!G47+BS!G41+BS!G48)),"") -> 0.12205885 | I29: =CHOOSE(Asumsi!$D$4,I57,I84,I111) -> 0.11 | J29: =CHOOSE(Asumsi!$D$4,J57,J84,J111) -> 0.11 | K29: =CHOOSE(Asumsi!$D$4,K57,K84,K111) -> 0.11 | L29: =CHOOSE(Asumsi!$D$4,L57,L84,L111) -> 0.11 | M29: =CHOOSE(Asumsi!$D$4,M57,M84,M111) -> 0.11 | N29: Historis: 2023 10,30%, 2024 10,50%, 2025 12,21% (beban keuangan termasuk bunga sewa & amortisasi surat utang). Base = rata-rata 2023-25; Bull x0,9; Bear x1,1 (Temuan S6).
A30: yld | B30: Imbal hasil kas (penghasilan keuangan / kas awal) | D30: =IFERROR(IS!D16/BS!C6,"") -> 0.038025105 | E30: =IFERROR(IS!E16/BS!D6,"") -> 0.027684355 | F30: =IFERROR(IS!F16/BS!E6,"") -> 0.026039695 | G30: =IFERROR(IS!G16/BS!F6,"") -> 0.026171181 | H30: =IFERROR(IS!H16/BS!G6,"") -> 0.2413242 | I30: =CHOOSE(Asumsi!$D$4,I58,I85,I112) -> 0.0978 | J30: =CHOOSE(Asumsi!$D$4,J58,J85,J112) -> 0.0978 | K30: =CHOOSE(Asumsi!$D$4,K58,K85,K112) -> 0.0978 | L30: =CHOOSE(Asumsi!$D$4,L58,L85,L112) -> 0.0978 | M30: =CHOOSE(Asumsi!$D$4,M58,M85,M112) -> 0.0978 | N30: Historis: 2022 2,77%, 2023 2,60%, 2024 2,62%, 2025 24,13%. Base = rata-rata 2023-25; Bear x0,8; tanpa circular reference.
A31: debt_chg | B31: Perubahan neto utang (Rp; + = tambah) | D31: =(BS!D29+BS!D38+BS!D45+BS!D39+BS!D46+BS!D40+BS!D47+BS!D41+BS!D48)-(BS!C29+BS!C38+BS!C45+BS!C39+BS!C46+BS!C40+BS!C47+BS!C41+BS!C48) -> -226056502380 | E31: =(BS!E29+BS!E38+BS!E45+BS!E39+BS!E46+BS!E40+BS!E47+BS!E41+BS!E48)-(BS!D29+BS!D38+BS!D45+BS!D39+BS!D46+BS!D40+BS!D47+BS!D41+BS!D48) -> 879116171608 | F31: =(BS!F29+BS!F38+BS!F45+BS!F39+BS!F46+BS!F40+BS!F47+BS!F41+BS!F48)-(BS!E29+BS!E38+BS!E45+BS!E39+BS!E46+BS!E40+BS!E47+BS!E41+BS!E48) -> -78967890922 | G31: =(BS!G29+BS!G38+BS!G45+BS!G39+BS!G46+BS!G40+BS!G47+BS!G41+BS!G48)-(BS!F29+BS!F38+BS!F45+BS!F39+BS!F46+BS!F40+BS!F47+BS!F41+BS!F48) -> 19523000000 | H31: =(BS!H29+BS!H38+BS!H45+BS!H39+BS!H46+BS!H40+BS!H47+BS!H41+BS!H48)-(BS!G29+BS!G38+BS!G45+BS!G39+BS!G46+BS!G40+BS!G47+BS!G41+BS!G48) -> 3018549000000 | I31: =CHOOSE(Asumsi!$D$4,I59,I86,I113) -> 0 | J31: =CHOOSE(Asumsi!$D$4,J59,J86,J113) -> 0 | K31: =CHOOSE(Asumsi!$D$4,K59,K86,K113) -> 0 | L31: =CHOOSE(Asumsi!$D$4,L59,L86,L113) -> 0 | M31: =CHOOSE(Asumsi!$D$4,M59,M86,M113) -> 0 | N31: Historis utang berbunga: 2022 1.725 M, 2023 1.646 M, 2024 1.666 M, 2025 4.684 M. Semua skenario 0 (kas = penyeimbang; pendanaan ekspansi tidak dimodelkan).
A32: payout | B32: Payout dividen (% laba induk tahun lalu) | D32: =IFERROR(-CF!D36/IS!C26,"") -> 0 | E32: =IFERROR(-CF!E36/IS!D26,"") -> 0 | F32: =IFERROR(-CF!F36/IS!E26,"") -> 0 | G32: =IFERROR(-CF!G36/IS!F26,"") -> 0 | H32: =IFERROR(-CF!H36/IS!G26,"") -> 0 | I32: =CHOOSE(Asumsi!$D$4,I60,I87,I114) -> 0 | J32: =CHOOSE(Asumsi!$D$4,J60,J87,J114) -> 0 | K32: =CHOOSE(Asumsi!$D$4,K60,K87,K114) -> 0 | L32: =CHOOSE(Asumsi!$D$4,L60,L87,L114) -> 0 | M32: =CHOOSE(Asumsi!$D$4,M60,M87,M114) -> 0 | N32: Tidak ada dividen ke pemilik induk 2020-2025 (Temuan S9). Semua skenario 0%.
A33: nci_share | B33: Porsi laba ke NCI (% laba tahun berjalan) | C33: =IFERROR(IS!C27/IS!C19,"") -> 0.0080997698 | D33: =IFERROR(IS!D27/IS!D19,"") -> 0.0017862363 | E33: =IFERROR(IS!E27/IS!E19,"") -> -0.0028903894 | F33: =IFERROR(IS!F27/IS!F19,"") -> -0.0046198418 | G33: =IFERROR(IS!G27/IS!G19,"") -> -0.0072395476 | H33: =IFERROR(IS!H27/IS!H19,"") -> -0.0010563912 | I33: =CHOOSE(Asumsi!$D$4,I61,I88,I115) -> 0 | J33: =CHOOSE(Asumsi!$D$4,J61,J88,J115) -> 0 | K33: =CHOOSE(Asumsi!$D$4,K61,K88,K115) -> 0 | L33: =CHOOSE(Asumsi!$D$4,L61,L88,L115) -> 0 | M33: =CHOOSE(Asumsi!$D$4,M61,M88,M115) -> 0 | N33: Historis: 2022 -0,3%, 2023 -0,5%, 2024 -0,7%, 2025 -0,1% (sangat kecil; tanda terbalik karena grup rugi). Semua skenario 0%.
B36: SKENARIO BASE - input biru per tahun (boleh diubah pengguna)
B37: PENDAPATAN (per kelompok, Cat 26)
A38: Base.g_med | B38: Pertumbuhan pendapatan obat & perlengkapan medis | I38: 0.1 | J38: 0.1 | K38: 0.1 | L38: 0.1 | M38: 0.1
A39: Base.g_inpat | B39: Pertumbuhan pendapatan rawat inap (bruto sebelum pengurang agen) | I39: 0.08 | J39: 0.08 | K39: 0.08 | L39: 0.08 | M39: 0.08
A40: Base.g_outpat | B40: Pertumbuhan pendapatan rawat jalan & penunjang (bruto) | I40: 0.1 | J40: 0.1 | K40: 0.1 | L40: 0.1 | M40: 0.1
A41: Base.rev_oth | B41: Lainnya: diskon & pengurang jasa tenaga ahli/agen (% 3 kelompok bruto) | I41: -0.26 | J41: -0.26 | K41: -0.26 | L41: -0.26 | M41: -0.26
B42: MARGIN & BIAYA (% pendapatan)
A43: Base.cogs | B43: Beban pokok di luar penyusutan | I43: 0.49 | J43: 0.49 | K43: 0.49 | L43: 0.49 | M43: 0.49
A44: Base.opex | B44: Beban usaha di luar penyusutan, penyusutan aset hak guna & amortisasi | I44: 0.301 | J44: 0.301 | K44: 0.301 | L44: 0.301 | M44: 0.301
...

Sheet IS_Proj
A1: Proyeksi laba rugi (ilustratif)
A2: Rp penuh | kolom A = aktual (link ke IS/BS/CF/Schedules), kolom E = proyeksi | Proyeksi ILUSTRATIF berbasis asumsi transparan - bukan rekomendasi investasi, bukan target, bukan nilai wajar.
A3: Skenario aktif: | C3: =Asumsi!C4 -> Base | I3: ilustratif | J3: ilustratif | K3: ilustratif | L3: ilustratif | M3: ilustratif
A4: Kode | B4: Akun | C4: FY2020A | D4: FY2021A | E4: FY2022A | F4: FY2023A | G4: FY2024A | H4: FY2025A | I4: FY2026E | J4: FY2027E | K4: FY2028E | L4: FY2029E | M4: FY2030E | N4: Catatan / sumber
B5: PENDAPATAN (per kelompok)
A6: P.REV_MED | B6: Obat & perlengkapan medis | C6: =Schedules!C6 -> 253936863405 | D6: =Schedules!D6 -> 417781280603 | E6: =Schedules!E6 -> 431771186720 | F6: =Schedules!F6 -> 754584000000 | G6: =Schedules!G6 -> 1164022000000 | H6: =Schedules!H6 -> 1291720000000 | I6: =H6*(1+Asumsi!I10) -> 1420892000000 | J6: =I6*(1+Asumsi!J10) -> 1562981200000 | K6: =J6*(1+Asumsi!K10) -> 1719279320000 | L6: =K6*(1+Asumsi!L10) -> 1891207252000 | M6: =L6*(1+Asumsi!M10) -> 2080327977200
A7: P.REV_INPAT | B7: Rawat inap (bruto) | C7: =Schedules!C7 -> 467640506965 | D7: =Schedules!D7 -> 753471843387 | E7: =Schedules!E7 -> 817003131432 | F7: =Schedules!F7 -> 1065433000000 | G7: =Schedules!G7 -> 1332597000000 | H7: =Schedules!H7 -> 1400293000000 | I7: =H7*(1+Asumsi!I11) -> 1512316440000 | J7: =I7*(1+Asumsi!J11) -> 1633301755200 | K7: =J7*(1+Asumsi!K11) -> 1763965895616 | L7: =K7*(1+Asumsi!L11) -> 1.9050832e+12 | M7: =L7*(1+Asumsi!M11) -> 2.0574898e+12
A8: P.REV_OUTPAT | B8: Rawat jalan & penunjang (bruto) | C8: =Schedules!C8 -> 596525411320 | D8: =Schedules!D8 -> 788732235692 | E8: =Schedules!E8 -> 704457503479 | F8: =Schedules!F8 -> 683157000000 | G8: =Schedules!G8 -> 651726000000 | H8: =Schedules!H8 -> 809565000000 | I8: =H8*(1+Asumsi!I12) -> 890521500000 | J8: =I8*(1+Asumsi!J12) -> 979573650000 | K8: =J8*(1+Asumsi!K12) -> 1077531015000 | L8: =K8*(1+Asumsi!L12) -> 1185284116500 | M8: =L8*(1+Asumsi!M12) -> 1303812528150
A9: P.REV_OTHER | B9: Lainnya (administrasi, operasional lain, dikurangi diskon) | C9: =Schedules!C9 -> -34304172516 | D9: =Schedules!D9 -> -35532218704 | E9: =Schedules!E9 -> -19068140667 | F9: =Schedules!F9 -> 0 | G9: =Schedules!G9 -> -807914000000 | H9: =Schedules!H9 -> -912138000000 | I9: =(I6+I7+I8)*Asumsi!I13 -> -994169784400 | J9: =(J6+J7+J8)*Asumsi!J13 -> -1085722717352 | K9: =(K6+K7+K8)*Asumsi!K13 -> -1.1858018e+12 | L9: =(L6+L7+L8)*Asumsi!L13 -> -1.2952094e+12 | M9: =(M6+M7+M8)*Asumsi!M13 -> -1.4148239e+12
A10: P.REVENUE | B10: Pendapatan | C10: =IS!C6 -> 1283798609174 | D10: =IS!D6 -> 1924453140978 | E10: =IS!E6 -> 1934163680964 | F10: =IS!F6 -> 2503174000000 | G10: =IS!G6 -> 2340431000000 | H10: =IS!H6 -> 2589440000000 | I10: =I6+I7+I8+I9 -> 2829560155600 | J10: =J6+J7+J8+J9 -> 3090133887848 | K10: =K6+K7+K8+K9 -> 3.3749744e+12 | L10: =L6+L7+L8+L9 -> 3.6863652e+12 | M10: =M6+M7+M8+M9 -> 4.0268064e+12
A11: P.REV_GROWTH | B11: Pertumbuhan pendapatan | D11: =D10/C10-1 -> 0.4990304 | E11: =E10/D10-1 -> 0.0050458698 | F11: =F10/E10-1 -> 0.29418933 | G11: =G10/F10-1 -> -0.065014657 | H11: =H10/G10-1 -> 0.10639451 | I11: =I10/H10-1 -> 0.092730535 | J11: =J10/I10-1 -> 0.092089837 | K11: =K10/J10-1 -> 0.092177405 | ... M11: =M10/L10-1 -> 0.092351482
B12: BIAYA & EBITDA
A13: P.COGS_X | B13: Beban pokok di luar penyusutan & amortisasi | C13: =IS!C7+Schedules!C12+Schedules!C17 -> -780678281447 | D13: =IS!D7+Schedules!D12+Schedules!D17 -> -1108367805956 | E13: =IS!E7+Schedules!E12+Schedules!E17 -> -1228080599500 | F13: =IS!F7+Schedules!F12+Schedules!F17 -> -1591210000000 | G13: =IS!G7+Schedules!G12+Schedules!G17 -> -1198346000000 | H13: =IS!H7+Schedules!H12+Schedules!H17 -> -1268879000000 | I13: =-I10*Asumsi!I15 -> -1386484476244 | J13: =-J10*Asumsi!J15 -> -1.5141656e+12 | K13: =-K10*Asumsi!K15 -> -1.6537375e+12 | L13: =-L10*Asumsi!L15 -> -1.8063189e+12 | M13: =-M10*Asumsi!M15 -> -1.9731352e+12
A14: P.GP_X | B14: Laba bruto sebelum penyusutan | C14: =C10+C13 -> 503120327727 | D14: =D10+D13 -> 816085335022 | E14: =E10+E13 -> 706083081464 | F14: =F10+F13 -> 911964000000 | G14: =G10+G13 -> 1142085000000 | H14: =H10+H13 -> 1320561000000 | I14: =I10+I13 -> 1443075679356 | J14: =J10+J13 -> 1.5759683e+12 | ... M14: =M10+M13 -> 2.0536713e+12
A15: P.OPEX_X | B15: Beban usaha di luar penyusutan & amortisasi | C15: =IS!C11+Schedules!C13+Schedules!C16+Schedules!C18 -> -354709454153 | D15: =IS!D11+Schedules!D13+Schedules!D16+Schedules!D18 -> -408410258960 | E15: =IS!E11+Schedules!E13+Schedules!E16+Schedules!E18 -> -441535401895 | F15: =IS!F11+Schedules!F13+Schedules!F16+Schedules!F18 -> -516426000000 | G15: =IS!G11+Schedules!G13+Schedules!G16+Schedules!G18 -> -632866000000 | H15: =IS!H11+Schedules!H13+Schedules!H16+Schedules!H18 -> -856706000000 | I15: =-I10*Asumsi!I16 -> -8.5169761e+11 | J15: =-J10*Asumsi!J16 -> -9.301303e+11 | K15: =-K10*Asumsi!K16 -> -1.0158673e+12 | L15: =-L10*Asumsi!L16 -> -1.1095959e+12 | M15: =-M10*Asumsi!M16 -> -1.2120687e+12
A16: P.OTHER_OP | B16: Pendapatan (beban) lain-lain neto | C16: =IS!C13 -> 28429533228 | D16: =IS!D13 -> 24028154926 | E16: =IS!E13 -> 4159861446 | F16: =IS!F13 -> 7014000000 | G16: =IS!G13 -> -24777000000 | H16: =IS!H13 -> 2883000000 | I16: =I10*Asumsi!I17 -> 0 | J16: =J10*Asumsi!J17 -> 0 | K16: =K10*Asumsi!K17 -> 0 | L16: =L10*Asumsi!L17 -> 0 | M16: =M10*Asumsi!M17 -> 0
A17: P.EBITDA | B17: EBITDA | C17: =C14+C15+C16 -> 176840406802 | D17: =D14+D15+D16 -> 431703230988 | E17: =E14+E15+E16 -> 268707541015 | F17: =F14+F15+F16 -> 402552000000 | G17: =G14+G15+G16 -> 484442000000 | H17: =H14+H15+H16 -> 466738000000 | I17: =I14+I15+I16 -> 5.9137807e+11 | J17: =J14+J15+J16 -> 6.4583798e+11 | ... M17: =M14+M15+M16 -> 8.4160255e+11 | N17: laba usaha (dihitung) + penyusutan aset tetap + penyusutan aset hak guna + amortisasi
A18: P.DA | B18: Penyusutan & amortisasi | C18: =-Schedules!C20 -> -132557566789 | D18: =-Schedules!D20 -> -181190606441 | E18: =-Schedules!E20 -> -233533889845 | F18: =-Schedules!F20 -> -289277000000 | G18: =-Schedules!G20 -> -326702000000 | H18: =-Schedules!H20 -> -381251000000 | I18: =-(Schedules_Proj!I9+Schedules_Proj!I13) -> -388483338000 | J18: =-(Schedules_Proj!J9+Schedules_Proj!J13) -> -3.9444683e+11 | K18: =-(Schedules_Proj!K9+Schedules_Proj!K13) -> -4.0314821e+11 | L18: =-(Schedules_Proj!L9+Schedules_Proj!L13) -> -4.1466262e+11 | M18: =-(Schedules_Proj!M9+Schedules_Proj!M13) -> -4.2908729e+11
A19: P.EBIT | B19: Laba usaha (EBIT) | C19: =C17+C18 -> 44282840013 | D19: =D17+D18 -> 250512624547 | E19: =E17+E18 -> 35173651170 | F19: =F17+F18 -> 113275000000 | G19: =G17+G18 -> 157740000000 | H19: =H17+H18 -> 85487000000 | I19: =I17+I18 -> 2.0289473e+11 | J19: =J17+J18 -> 2.5139115e+11 | ... M19: =M17+M18 -> 4.1251525e+11 | N19: historis: = laba usaha IS hasil hitung (cek di Rekonsiliasi; Temuan S4)
A20: P.FIN_INC | B20: Penghasilan keuangan | C20: =IS!C16 -> 26470099827 | D20: =IS!D16 -> 23940936423 | E20: =IS!E16 -> 19404583424 | F20: =IS!F16 -> 29119000000 | G20: =IS!G16 -> 13483000000 | H20: =IS!H16 -> 66897000000 | I20: =BS_Proj!H6*Asumsi!I30 -> 178608521400 | J20: =BS_Proj!I6*Asumsi!J30 -> 1.5361268e+11 | K20: =BS_Proj!J6*Asumsi!K30 -> 1.2739431e+11 | L20: =BS_Proj!K6*Asumsi!L30 -> 9.9768781e+10 | M20: =BS_Proj!L6*Asumsi!M30 -> 7.0705909e+10 | N20: E: imbal hasil x kas awal
A21: P.FIN_COST | B21: Beban keuangan | C21: =IS!C15 -> -70561549474 | D21: =IS!D15 -> -118034051135 | E21: =IS!E15 -> -96665120830 | F21: =IS!F15 -> -173685000000 | G21: =IS!G15 -> -173863000000 | H21: =IS!H15 -> -387554000000 | I21: =-Schedules_Proj!I24*Asumsi!I29 -> -515285650000 | J21: =-Schedules_Proj!J24*Asumsi!J29 -> -515285650000 | K21: =-Schedules_Proj!K24*Asumsi!K29 -> -515285650000 | L21: =-Schedules_Proj!L24*Asumsi!L29 -> -515285650000 | M21: =-Schedules_Proj!M24*Asumsi!M29 -> -515285650000 | N21: E: suku bunga x rata-rata utang (Temuan S6)
A22: P.PBT | B22: Laba sebelum pajak | C22: =C19+C20+C21 -> 191390366 | D22: =D19+D20+D21 -> 156419509835 | E22: =E19+E20+E21 -> -42086886236 | F22: =F19+F20+F21 -> -31291000000 | G22: =G19+G20+G21 -> -2640000000 | H22: =H19+H20+H21 -> -235170000000 | I22: =I19+I20+I21 -> -1.3378239e+11 | J22: =J19+J20+J21 -> -1.1028182e+11 | ... M22: =M19+M20+M21 -> -3.2064487e+10
A23: P.TAX | B23: Beban pajak | C23: =IS!C18 -> -14689448354 | D23: =IS!D18 -> 9184536739 | E23: =IS!E18 -> -2100344487 | F23: =IS!F18 -> -7022000000 | G23: =IS!G18 -> -20704000000 | H23: =IS!H18 -> 36380000000 | I23: =-MAX(I22,0)*Asumsi!I28 -> 0 | J23: =-MAX(J22,0)*Asumsi!J28 -> 0 | K23: =-MAX(K22,0)*Asumsi!K28 -> 0 | L23: =-MAX(L22,0)*Asumsi!L28 -> 0 | M23: =-MAX(M22,0)*Asumsi!M28 -> 0
A24: P.NI | B24: Laba tahun berjalan | C24: =C22+C23 -> -14498057988 | D24: =D22+D23 -> 165604046574 | E24: =E22+E23 -> -44187230723 | F24: =F22+F23 -> -38313000000 | G24: =G22+G23 -> -23344000000 | H24: =H22+H23 -> -198790000000 | I24: =I22+I23 -> -1.3378239e+11 | J24: =J22+J23 -> -1.1028182e+11 | ... M24: =M22+M23 -> -3.2064487e+10
A25: P.NI_NCI | B25: Diatribusikan ke NCI | C25: =IS!C27 -> -117430932 | D25: =IS!D27 -> 295807955 | E25: =IS!E27 -> 127718302 | F25: =IS!F27 -> 177000000 | G25: =IS!G27 -> 169000000 | H25: =IS!H27 -> 210000000 | I25: =I24*Asumsi!I33 -> 0 | J25: =J24*Asumsi!J33 -> 0 | K25: =K24*Asumsi!K33 -> 0 | L25: =L24*Asumsi!L33 -> 0 | M25: =M24*Asumsi!M33 -> 0
A26: P.NI_PARENT | B26: Diatribusikan ke pemilik entitas induk | C26: =C24-C25 -> -14380627056 | D26: =D24-D25 -> 165308238619 | E26: =E24-E25 -> -44314949025 | F26: =F24-F25 -> -38490000000 | G26: =G24-G25 -> -23513000000 | H26: =H24-H25 -> -199000000000 | I26: =I24-I25 -> -1.3378239e+11 | J26: =J24-J25 -> -1.1028182e+11 | ... M26: =M24-M25 -> -3.2064487e+10
A27: P.EPS | B27: Laba induk per saham (Rp; / 12.238.959.990 saham) | C27: =C26/Asumsi!$C$118 -> -1.1749877 | D27: =D26/Asumsi!$C$118 -> 13.506723 | E27: =E26/Asumsi!$C$118 -> -3.62081 | F27: =F26/Asumsi!$C$118 -> -3.1448751 | G27: =G26/Asumsi!$C$118 -> -1.92116 | H27: =H26/Asumsi!$C$118 -> -16.259551 | I27: =I26/Asumsi!$C$118 -> -10.930863 | J27: =J26/Asumsi!$C$118 -> -9.0107182 | ... M27: =M26/Asumsi!$C$118 -> -2.6198702 | N27: EPS tercetak memakai saham tertimbang (Temuan S9)
B28: MARGIN
A29: P.GM_X | B29: Margin laba bruto sebelum penyusutan | C29: =C14/C10 -> 0.39189973 | D29: =D14/D10 -> 0.4240609 | E29: =E14/E10 -> 0.3650586 | F29: =F14/F10 -> 0.36432306 | G29: =G14/G10 -> 0.48798063 | H29: =H14/H10 -> 0.50997938 | I29: =I14/I10 -> 0.51 | J29: =J14/J10 -> 0.51 | ... M29: =M14/M10 -> 0.51
A30: P.EBITDA_M | B30: Margin EBITDA | C30: =C17/C10 -> 0.13774778 | D30: =D17/D10 -> 0.22432515 | E30: =E17/E10 -> 0.13892699 | F30: =F17/F10 -> 0.16081663 | G30: =G17/G10 -> 0.20698837 | H30: =H17/H10 -> 0.18024669 | I30: =I17/I10 -> 0.209 | J30: =J17/J10 -> 0.209 | ... M30: =M17/M10 -> 0.209
A31: P.EBIT_M | B31: Margin EBIT | C31: =C19/C10 -> 0.034493603 | D31: =D19/D10 -> 0.13017341 | E31: =E19/E10 -> 0.018185457 | F31: =F19/F10 -> 0.045252547 | G31: =G19/G10 -> 0.067397843 | H31: =H19/H10 -> 0.033013702 | I31: =I19/I10 -> 0.071705397 | J31: =J19/J10 -> 0.081352834 | ... M31: =M19/M10 -> 0.10244229
A32: P.NI_M | B32: Margin laba bersih | C32: =C24/C10 -> -0.011293094 | D32: =D24/D10 -> 0.086052522 | E32: =E24/E10 -> -0.022845652 | F32: =F24/F10 -> -0.015305768 | G32: =G24/G10 -> -0.0099742312 | H32: =H24/H10 -> -0.076769495 | I32: =I24/I10 -> -0.047280279 | J32: =J24/J10 -> -0.035688363 | ... M32: =M24/M10 -> -0.0079627583

Sheet BS_Proj
A1: Proyeksi posisi keuangan agregat (ilustratif)
A2: Rp penuh | kolom A = aktual (link ke IS/BS/CF/Schedules), kolom E = proyeksi | Proyeksi ILUSTRATIF berbasis asumsi transparan - bukan rekomendasi investasi, bukan target, bukan nilai wajar.
A3: Skenario aktif: | C3: =Asumsi!C4 -> Base | I3: ilustratif | J3: ilustratif | K3: ilustratif | L3: ilustratif | M3: ilustratif
A4: Kode | B4: Akun | C4: FY2020A | D4: FY2021A | E4: FY2022A | F4: FY2023A | G4: FY2024A | H4: FY2025A | I4: FY2026E | J4: FY2027E | K4: FY2028E | L4: FY2029E | M4: FY2030E | N4: Catatan / sumber
B5: ASET
A6: PB.CASH | B6: Kas dan setara kas | C6: =BS!C6 -> 629608688874 | D6: =BS!D6 -> 700922359619 | E6: =BS!E6 -> 1118254250664 | F6: =BS!F6 -> 515185000000 | G6: =BS!G6 -> 277208000000 | H6: =BS!H6 -> 1826263000000 | I6: =CF_Proj!I25 -> 1.5706818e+12 | J6: =CF_Proj!J25 -> 1.3026003e+12 | K6: =CF_Proj!K25 -> 1.0201307e+12 | L6: =CF_Proj!L25 -> 7.229643e+11 | M6: =CF_Proj!M25 -> 4.1086524e+11 | N6: E: penyeimbang dari CF_Proj
A7: PB.AR | B7: Piutang usaha (pihak ketiga + berelasi) | C7: =(BS!C8+BS!C9) -> 225422821680 | D7: =(BS!D8+BS!D9) -> 233901361278 | E7: =(BS!E8+BS!E9) -> 242981358318 | F7: =(BS!F8+BS!F9) -> 395321000000 | G7: =(BS!G8+BS!G9) -> 424298000000 | H7: =(BS!H8+BS!H9) -> 557933000000 | I7: =Schedules_Proj!I26 -> 6.1242535e+11 | J7: =Schedules_Proj!J26 -> 6.688235e+11 | K7: =Schedules_Proj!K26 -> 7.3047391e+11 | L7: =Schedules_Proj!L26 -> 7.9787081e+11 | M7: =Schedules_Proj!M26 -> 8.7155537e+11
A8: PB.INV | B8: Persediaan | C8: =BS!C12 -> 74691220678 | D8: =BS!D12 -> 70409082280 | E8: =BS!E12 -> 49621868590 | F8: =BS!F12 -> 48940000000 | G8: =BS!G12 -> 61316000000 | H8: =BS!H12 -> 73323000000 | I8: =Schedules_Proj!I27 -> 7.977034e+10 | J8: =Schedules_Proj!J27 -> 8.7116377e+10 | K8: =Schedules_Proj!K27 -> 9.5146539e+10 | L8: =Schedules_Proj!L27 -> 1.039252e+11 | M8: =Schedules_Proj!M27 -> 1.1352284e+11
A9: PB.OCA | B9: Aset lancar lainnya | C9: =BS!C16-BS!C6-BS!C8-BS!C9-BS!C12 -> 10112775510 | D9: =BS!D16-BS!D6-BS!D8-BS!D9-BS!D12 -> 16221734195 | E9: =BS!E16-BS!E6-BS!E8-BS!E9-BS!E12 -> 34756121020 | F9: =BS!F16-BS!F6-BS!F8-BS!F9-BS!F12 -> 38803000000 | G9: =BS!G16-BS!G6-BS!G8-BS!G9-BS!G12 -> 69980000000 | H9: =BS!H16-BS!H6-BS!H8-BS!H9-BS!H12 -> 70398000000 | I9: =H9 -> 70398000000 | J9: =I9 -> 70398000000 | K9: =J9 -> 70398000000 | L9: =K9 -> 70398000000 | M9: =L9 -> 70398000000 | N9: E: konstan
A10: PB.TCA | B10: Jumlah aset lancar | C10: =C6+C7+C8+C9 -> 939835506742 | D10: =D6+D7+D8+D9 -> 1021454537372 | E10: =E6+E7+E8+E9 -> 1445613598592 | F10: =F6+F7+F8+F9 -> 998249000000 | G10: =G6+G7+G8+G9 -> 832802000000 | H10: =H6+H7+H8+H9 -> 2527917000000 | I10: =I6+I7+I8+I9 -> 2.3332755e+12 | J10: =J6+J7+J8+J9 -> 2.1289382e+12 | ... M10: =M6+M7+M8+M9 -> 1.4663415e+12
A11: PB.PPE | B11: Aset tetap - neto | C11: =BS!C19 -> 2641613456689 | D11: =BS!D19 -> 3169775593830 | E11: =BS!E19 -> 3607142163990 | F11: =BS!F19 -> 3952312000000 | G11: =BS!G19 -> 4164140000000 | H11: =BS!H19 -> 4286327000000 | I11: =Schedules_Proj!I10 -> 4.3586995e+12 | J11: =Schedules_Proj!J10 -> 4.4642988e+12 | K11: =Schedules_Proj!K10 -> 4.6040367e+12 | L11: =Schedules_Proj!L10 -> 4.7790934e+12 | M11: =Schedules_Proj!M10 -> 4.9909278e+12
A12: PB.INTANG | B12: Aset takberwujud | C12: =BS!C22 -> 10032147719 | D12: =BS!D22 -> 18016628295 | E12: =BS!E22 -> 12824038513 | F12: =BS!F22 -> 11773000000 | G12: =BS!G22 -> 11616000000 | H12: =BS!H22 -> 26642000000 | I12: =Schedules_Proj!I15 -> 26642000000 | J12: =Schedules_Proj!J15 -> 26642000000 | K12: =Schedules_Proj!K15 -> 26642000000 | L12: =Schedules_Proj!L15 -> 26642000000 | M12: =Schedules_Proj!M15 -> 26642000000
A13: PB.ONCA | B13: Aset tidak lancar lain (aset hak guna, properti investasi, goodwill, uang muka, pajak tangguhan) | C13: =BS!C26-BS!C19-BS!C22 -> 754847976856 | D13: =BS!D26-BS!D19-BS!D22 -> 662559848864 | E13: =BS!E26-BS!E19-BS!E22 -> 684019446657 | F13: =BS!F26-BS!F19-BS!F22 -> 643957000000 | G13: =BS!G26-BS!G19-BS!G22 -> 674464000000 | H13: =BS!H26-BS!H19-BS!H22 -> 783024000000 | I13: =H13 -> 783024000000 | J13: =I13 -> 783024000000 | K13: =J13 -> 783024000000 | L13: =K13 -> 783024000000 | M13: =L13 -> 783024000000 | N13: E: konstan
A14: PB.TNCA | B14: Jumlah aset tidak lancar | C14: =C11+C12+C13 -> 3406493581264 | D14: =D11+D12+D13 -> 3850352070989 | E14: =E11+E12+E13 -> 4303985649160 | F14: =F11+F12+F13 -> 4608042000000 | G14: =G11+G12+G13 -> 4850220000000 | H14: =H11+H12+H13 -> 5095993000000 | I14: =I11+I12+I13 -> 5.1683655e+12 | J14: =J11+J12+J13 -> 5.2739648e+12 | ... M14: =M11+M12+M13 -> 5.8005938e+12
A15: PB.TA | B15: JUMLAH ASET | C15: =C10+C14 -> 4346329088006 | D15: =D10+D14 -> 4871806608361 | E15: =E10+E14 -> 5749599247752 | F15: =F10+F14 -> 5606291000000 | G15: =G10+G14 -> 5683022000000 | H15: =H10+H14 -> 7623910000000 | I15: =I10+I14 -> 7.501641e+12 | J15: =J10+J14 -> 7.402903e+12 | ... M15: =M10+M14 -> 7.2669353e+12
B16: LIABILITAS
A17: PB.AP | B17: Utang usaha (pihak ketiga + berelasi) | C17: =(BS!C30+BS!C31) -> 175206597303 | D17: =(BS!D30+BS!D31) -> 192301032210 | E17: =(BS!E30+BS!E31) -> 161991239794 | F17: =(BS!F30+BS!F31) -> 140702000000 | G17: =(BS!G30+BS!G31) -> 156194000000 | H17: =(BS!H30+BS!H31) -> 113840000000 | I17: =Schedules_Proj!I28 -> 1.2535339e+11 | J17: =Schedules_Proj!J28 -> 1.3689716e+11 | K17: =Schedules_Proj!K28 -> 1.4951599e+11 | L17: =Schedules_Proj!L28 -> 1.6331103e+11 | M17: =Schedules_Proj!M28 -> 1.7839304e+11
A18: PB.DEBT | B18: Utang berbunga (bank, non-bank, surat utang, pembiayaan) | C18: =(BS!C29+BS!C38+BS!C45+BS!C39+BS!C46+BS!C40+BS!C47+BS!C41+BS!C48) -> 1072251221694 | D18: =(BS!D29+BS!D38+BS!D45+BS!D39+BS!D46+BS!D40+BS!D47+BS!D41+BS!D48) -> 846194719314 | E18: =(BS!E29+BS!E38+BS!E45+BS!E39+BS!E46+BS!E40+BS!E47+BS!E41+BS!E48) -> 1725310890922 | F18: =(BS!F29+BS!F38+BS!F45+BS!F39+BS!F46+BS!F40+BS!F47+BS!F41+BS!F48) -> 1646343000000 | G18: =(BS!G29+BS!G38+BS!G45+BS!G39+BS!G46+BS!G40+BS!G47+BS!G41+BS!G48) -> 1665866000000 | H18: =(BS!H29+BS!H38+BS!H45+BS!H39+BS!H46+BS!H40+BS!H47+BS!H41+BS!H48) -> 4684415000000 | I18: =Schedules_Proj!I23 -> 4684415000000 | J18: =Schedules_Proj!J23 -> 4684415000000 | K18: =Schedules_Proj!K23 -> 4684415000000 | L18: =Schedules_Proj!L23 -> 4684415000000 | M18: =Schedules_Proj!M23 -> 4684415000000
